Workbook

Sheet RESUMEN
A1: 46104 | C1: =IFERROR(__xludf.DUMMYFUNCTION("unique(filter($C$68:$C1166,$C$68:$C1166<>""Proveedor"",$B$68:$B1166=C6,$C$68:$C1166<>""""))"),"Cafeteria") -> Cafeteria | D1: =IFERROR(__xludf.DUMMYFUNCTION("unique(filter($C$68:$C1166,$C$68:$C1166<>""Proveedor"",$B$68:$B1166=D6,$C$68:$C1166<>""""))"),"Cafeteria") -> Cafeteria | E1: =IFERROR(__xludf.DUMMYFUNCTION("unique(filter($C$68:$C1166,$C$68:$C1166<>""Proveedor"",$B$68:$B1166=E6,$C$68:$C1166<>""""))"),"Corporate Coffe") -> Corporate Coffe | F1: =IFERROR(__xludf.DUMMYFUNCTION("unique(filter($C$68:$C1166,$C$68:$C1166<>""Proveedor"",$B$68:$B1166=F6,$C$68:$C1166<>""""))"),"Cafeteria") -> Cafeteria | G1: =IFERROR(__xludf.DUMMYFUNCTION("unique(filter($C$68:$C1166,$C$68:$C1166<>""Proveedor"",$B$68:$B1166=#REF!,$C$68:$C1166<>""""))"),"#N/A") -> #N/A | H1: =IFERROR(__xludf.DUMMYFUNCTION("unique(filter($C$68:$C1166,$C$68:$C1166<>""Proveedor"",$B$68:$B1166=H6,$C$68:$C1166<>""""))"),"Cafeteria") -> Cafeteria | I1: =IFERROR(__xludf.DUMMYFUNCTION("unique(filter($C$68:$C1166,$C$68:$C1166<>""Proveedor"",$B$68:$B1166=#REF!,$C$68:$C1166<>""""))"),"#N/A") -> #N/A | J1: =IFERROR(__xludf.DUMMYFUNCTION("unique(filter($C$68:$C1166,$C$68:$C1166<>""Proveedor"",$B$68:$B1166=J6,$C$68:$C1166<>""""))"),"Cafeteria") -> Cafeteria | K1: =IFERROR(__xludf.DUMMYFUNCTION("unique(filter($C$68:$C1166,$C$68:$C1166<>""Proveedor"",$B$68:$B1166=K6,$C$68:$C1166<>""""))"),"Cafeteria") -> Cafeteria | L1: =IFERROR(__xludf.DUMMYFUNCTION("unique(filter($C$68:$C1166,$C$68:$C1166<>""Proveedor"",$B$68:$B1166=L6,$C$68:$C1166<>""""))"),"Cafeteria") -> Cafeteria | M1: =IFERROR(__xludf.DUMMYFUNCTION("unique(filter($C$68:$C1166,$C$68:$C1166<>""Proveedor"",$B$68:$B1166=M6,$C$68:$C1166<>""""))"),"Aseo") -> Aseo
A2: 46100 | C2: =IFERROR(__xludf.DUMMYFUNCTION("""COMPUTED_VALUE"""),"Aseo") -> Aseo | D2: =IFERROR(__xludf.DUMMYFUNCTION("""COMPUTED_VALUE"""),"Aseo") -> Aseo | E2: =IFERROR(__xludf.DUMMYFUNCTION("""COMPUTED_VALUE"""),"Cafeteria") -> Cafeteria | F2: =IFERROR(__xludf.DUMMYFUNCTION("""COMPUTED_VALUE"""),"Aseo") -> Aseo | H2: =IFERROR(__xludf.DUMMYFUNCTION("""COMPUTED_VALUE"""),"Aseo") -> Aseo | J2: =IFERROR(__xludf.DUMMYFUNCTION("""COMPUTED_VALUE"""),"Aseo") -> Aseo | K2: =IFERROR(__xludf.DUMMYFUNCTION("""COMPUTED_VALUE"""),"Aseo") -> Aseo | L2: =IFERROR(__xludf.DUMMYFUNCTION("""COMPUTED_VALUE"""),"Aseo") -> Aseo
E3: =IFERROR(__xludf.DUMMYFUNCTION("""COMPUTED_VALUE"""),"Papelería") -> Papelería
A4: Insumos | E4: =IFERROR(__xludf.DUMMYFUNCTION("""COMPUTED_VALUE"""),"Aseo") -> Aseo
A5: Cafe
C6: =IFERROR(__xludf.DUMMYFUNCTION("TRANSPOSE(unique(filter(B68:B1166,B68:B1166<>""Sede"",B68:B1166<>"""")))"),"Santa Lucia") -> Santa Lucia | D6: =IFERROR(__xludf.DUMMYFUNCTION("""COMPUTED_VALUE"""),"Plaza Egaña") -> Plaza Egaña | E6: =IFERROR(__xludf.DUMMYFUNCTION("""COMPUTED_VALUE"""),"Neohaus") -> Neohaus | F6: =IFERROR(__xludf.DUMMYFUNCTION("""COMPUTED_VALUE"""),"Florida Center") -> Florida Center | G6: =IFERROR(__xludf.DUMMYFUNCTION("""COMPUTED_VALUE"""),"Manuel Montt piso 2") -> Manuel Montt piso 2 | H6: =IFERROR(__xludf.DUMMYFUNCTION("""COMPUTED_VALUE"""),"Manuel Montt piso 5") -> Manuel Montt piso 5 | I6: =IFERROR(__xludf.DUMMYFUNCTION("""COMPUTED_VALUE"""),"Suecia piso 7") -> Suecia piso 7 | J6: =IFERROR(__xludf.DUMMYFUNCTION("""COMPUTED_VALUE"""),"Suecia piso 8") -> Suecia piso 8 | K6: =IFERROR(__xludf.DUMMYFUNCTION("""COMPUTED_VALUE"""),"Tobalaba 3") -> Tobalaba 3 | L6: =IFERROR(__xludf.DUMMYFUNCTION("""COMPUTED_VALUE"""),"Santa Rosa") -> Santa Rosa | M6: =IFERROR(__xludf.DUMMYFUNCTION("""COMPUTED_VALUE"""),"Santa Rosa ") -> Santa Rosa
B7: =IFERROR(__xludf.DUMMYFUNCTION("unique(filter(D68:D1166,D68:D1166<>""Producto"",D68:D1166<>""""))"),"Cafe Grano (KG)") -> Cafe Grano (KG) | C7: =IFERROR(INDEX($E$70:$BW$85,MATCH($B7,$D$70:$D$85,0),MATCH($A$2,$E$68:$BW$68,0))&" ---> "&INDEX($E$70:$BW$85,MATCH($B7,$D$70:$D$85,0),MATCH($A$1,$E$68:$BW$68,0)),"-") -> 20 ---> 17,5 | D7: =IFERROR(INDEX($E$89:$BQ$103,MATCH($B7,$D$89:$D$103,0),MATCH($A$2,$E$87:$BQ$87,0))&" ---> "&INDEX($E$89:$BQ$103,MATCH($B7,$D$89:$D$103,0),MATCH($A$1,$E$87:$BQ$87,0)),"-") -> 16 ---> 15 | E7: =IFERROR(INDEX($E$106:$BK$119,MATCH($B7,$D$106:$D$119,0),MATCH($A$2,$E$104:$BK$104,0))&" ---> "&INDEX($E$106:$BK$119,MATCH($B7,$D$106:$D$119,0),MATCH($A$1,$E$104:$BK$104,0)),"-") -> 2 kilos ---> 1 kilos | F7: =IFERROR(INDEX($E$123:$BO$158,MATCH($B7,$D$123:$D$158,0),MATCH($A$2,$E$121:$BO$121,0))&" ---> "&INDEX($E$123:$BO$158,MATCH($B7,$D$123:$D$158,0),MATCH($A$1,$E$121:$BO$121,0)),"-") -> 28 (bolsas de 500gr) ---> 27 (bolsas de 500gr) | G7: =IFERROR(INDEX($E$162:$AY$183,MATCH($B7&G$6,$A$162:$A$183,0),MATCH($A$2,$E$160:$AY$160,0))&" ---> "&INDEX($E$162:$AY$183,MATCH($B7&G$6,$A$162:$A$183,0),MATCH($A$1,$E$160:$AY$160,0)),"-") -> - | H7: =IFERROR(INDEX($E$162:$AY$183,MATCH($B7&H$6,$A$162:$A$183,0),MATCH($A$2,$E$160:$AY$160,0))&" ---> "&INDEX($E$162:$AY$183,MATCH($B7&H$6,$A$162:$A$183,0),MATCH($A$1,$E$160:$AY$160,0)),"-") -> - | I7: =IFERROR(INDEX($E$188:$BK$215,MATCH($B7&I$6,$A$188:$A$215,0),MATCH($A$2,$E$186:$BK$186,0))&" ---> "&INDEX($E$188:$BK$215,MATCH($B7&I$6,$A$188:$A$215,0),MATCH($A$1,$E$186:$BK$186,0)),"-") -> 3 ---> 3 | J7: =IFERROR(INDEX($E$188:$BK$215,MATCH($B7&J$6,$A$188:$A$215,0),MATCH($A$2,$E$186:$BK$186,0))&" ---> "&INDEX($E$188:$BK$215,MATCH($B7&J$6,$A$188:$A$215,0),MATCH($A$1,$E$186:$BK$186,0)),"-") -> 10 ---> 10 | K7: =IFERROR(INDEX($E$219:$BD$231,MATCH($B7&K$6,$A$219:$A$231,0),MATCH($A$2,$E$217:$BD$217,0))&" ---> "&INDEX($E$219:$BD$231,MATCH($B7&K$6,$A$219:$A$231,0),MATCH($A$1,$E$217:$BD$217,0)),"-") -> 12,5 ---> 8,5 | L7: =IFERROR(INDEX($E$219:$BD$231,MATCH($B7&L$6,$A$219:$A$231,0),MATCH($A$2,$E$217:$BD$217,0))&" ---> "&INDEX($E$219:$BD$231,MATCH($B7&L$6,$A$219:$A$231,0),MATCH($A$1,$E$217:$BD$217,0)),"-") -> - | M7: =IFERROR(INDEX($E$235:$AY$251,MATCH($B7,$D$235:$D$251,0),MATCH($A$2,$E$233:$AY$233,0))&" ---> "&INDEX($E$235:$AY$251,MATCH($B7,$D$234:$D$251,0),MATCH($A$1,$E$233:$AY$233,0)),"-") -> piso 5 (9) - piso 6 (9) ---> piso 3 (6)- piso 5 (6) - piso 6 (6)
B8: =IFERROR(__xludf.DUMMYFUNCTION("""COMPUTED_VALUE"""),"Toalla de Papel Jumbo (UN)") -> Toalla de Papel Jumbo (UN) | C8: =IFERROR(INDEX($E$70:$BW$85,MATCH($B8,$D$70:$D$85,0),MATCH($A$2,$E$68:$BW$68,0))&" ---> "&INDEX($E$70:$BW$85,MATCH($B8,$D$70:$D$85,0),MATCH($A$1,$E$68:$BW$68,0)),"-") -> 27 ---> 30 | D8: =IFERROR(INDEX($E$89:$BQ$103,MATCH($B8,$D$89:$D$103,0),MATCH($A$2,$E$87:$BQ$87,0))&" ---> "&INDEX($E$89:$BQ$103,MATCH($B8,$D$89:$D$103,0),MATCH($A$1,$E$87:$BQ$87,0)),"-") -> 1 ---> 0 | E8: =IFERROR(INDEX($E$106:$BK$119,MATCH($B8,$D$106:$D$119,0),MATCH($A$2,$E$104:$BK$104,0))&" ---> "&INDEX($E$106:$BK$119,MATCH($B8,$D$106:$D$119,0),MATCH($A$1,$E$104:$BK$104,0)),"-") -> sin stock ---> sin stock | F8: =IFERROR(INDEX($E$123:$BO$158,MATCH($B8,$D$123:$D$158,0),MATCH($A$2,$E$121:$BO$121,0))&" ---> "&INDEX($E$123:$BO$158,MATCH($B8,$D$123:$D$158,0),MATCH($A$1,$E$121:$BO$121,0)),"-") -> 8 ---> 7 | G8: =IFERROR(INDEX($E$162:$AY$183,MATCH($B8&G$6,$A$162:$A$183,0),MATCH($A$2,$E$160:$AY$160,0))&" ---> "&INDEX($E$162:$AY$183,MATCH($B8&G$6,$A$162:$A$183,0),MATCH($A$1,$E$160:$AY$160,0)),"-") -> - | H8: =IFERROR(INDEX($E$162:$AY$183,MATCH($B8&H$6,$A$162:$A$183,0),MATCH($A$2,$E$160:$AY$160,0))&" ---> "&INDEX($E$162:$AY$183,MATCH($B8&H$6,$A$162:$A$183,0),MATCH($A$1,$E$160:$AY$160,0)),"-") -> - | I8: =IFERROR(INDEX($E$188:$BK$215,MATCH($B8&I$6,$A$188:$A$215,0),MATCH($A$2,$E$186:$BK$186,0))&" ---> "&INDEX($E$188:$BK$215,MATCH($B8&I$6,$A$188:$A$215,0),MATCH($A$1,$E$186:$BK$186,0)),"-") -> 4 ---> 4 | J8: =IFERROR(INDEX($E$188:$BK$215,MATCH($B8&J$6,$A$188:$A$215,0),MATCH($A$2,$E$186:$BK$186,0))&" ---> "&INDEX($E$188:$BK$215,MATCH($B8&J$6,$A$188:$A$215,0),MATCH($A$1,$E$186:$BK$186,0)),"-") -> 24 ---> 24 | K8: =IFERROR(INDEX($E$219:$BD$231,MATCH($B8&K$6,$A$219:$A$231,0),MATCH($A$2,$E$217:$BD$217,0))&" ---> "&INDEX($E$219:$BD$231,MATCH($B8&K$6,$A$219:$A$231,0),MATCH($A$1,$E$217:$BD$217,0)),"-") -> 14 ---> 5 | L8: =IFERROR(INDEX($E$219:$BD$231,MATCH($B8&L$6,$A$219:$A$231,0),MATCH($A$2,$E$217:$BD$217,0))&" ---> "&INDEX($E$219:$BD$231,MATCH($B8&L$6,$A$219:$A$231,0),MATCH($A$1,$E$217:$BD$217,0)),"-") -> - | M8: =IFERROR(INDEX($E$235:$AY$251,MATCH($B8,$D$235:$D$251,0),MATCH($A$2,$E$233:$AY$233,0))&" ---> "&INDEX($E$235:$AY$251,MATCH($B8,$D$234:$D$251,0),MATCH($A$1,$E$233:$AY$233,0)),"-") -> 26 ---> 36
B9: =IFERROR(__xludf.DUMMYFUNCTION("""COMPUTED_VALUE"""),"Papel Higienico (UN)") -> Papel Higienico (UN) | C9: =IFERROR(INDEX($E$70:$BW$85,MATCH($B9,$D$70:$D$85,0),MATCH($A$2,$E$68:$BW$68,0))&" ---> "&INDEX($E$70:$BW$85,MATCH($B9,$D$70:$D$85,0),MATCH($A$1,$E$68:$BW$68,0)),"-") -> 20 ---> 9 | D9: =IFERROR(INDEX($E$89:$BQ$103,MATCH($B9,$D$89:$D$103,0),MATCH($A$2,$E$87:$BQ$87,0))&" ---> "&INDEX($E$89:$BQ$103,MATCH($B9,$D$89:$D$103,0),MATCH($A$1,$E$87:$BQ$87,0)),"-") -> 8 ---> 7 | E9: =IFERROR(INDEX($E$106:$BK$119,MATCH($B9,$D$106:$D$119,0),MATCH($A$2,$E$104:$BK$104,0))&" ---> "&INDEX($E$106:$BK$119,MATCH($B9,$D$106:$D$119,0),MATCH($A$1,$E$104:$BK$104,0)),"-") -> 6 paquetes ---> 4 paquetes | F9: =IFERROR(INDEX($E$123:$BO$158,MATCH($B9,$D$123:$D$158,0),MATCH($A$2,$E$121:$BO$121,0))&" ---> "&INDEX($E$123:$BO$158,MATCH($B9,$D$123:$D$158,0),MATCH($A$1,$E$121:$BO$121,0)),"-") -> - ---> - | G9: =IFERROR(INDEX($E$162:$AY$183,MATCH($B9&G$6,$A$162:$A$183,0),MATCH($A$2,$E$160:$AY$160,0))&" ---> "&INDEX($E$162:$AY$183,MATCH($B9&G$6,$A$162:$A$183,0),MATCH($A$1,$E$160:$AY$160,0)),"-") -> - | H9: =IFERROR(INDEX($E$162:$AY$183,MATCH($B9&H$6,$A$162:$A$183,0),MATCH($A$2,$E$160:$AY$160,0))&" ---> "&INDEX($E$162:$AY$183,MATCH($B9&H$6,$A$162:$A$183,0),MATCH($A$1,$E$160:$AY$160,0)),"-") -> - | I9: =IFERROR(INDEX($E$188:$BK$215,MATCH($B9&I$6,$A$188:$A$215,0),MATCH($A$2,$E$186:$BK$186,0))&" ---> "&INDEX($E$188:$BK$215,MATCH($B9&I$6,$A$188:$A$215,0),MATCH($A$1,$E$186:$BK$186,0)),"-") -> 25 ---> 25 | J9: =IFERROR(INDEX($E$188:$BK$215,MATCH($B9&J$6,$A$188:$A$215,0),MATCH($A$2,$E$186:$BK$186,0))&" ---> "&INDEX($E$188:$BK$215,MATCH($B9&J$6,$A$188:$A$215,0),MATCH($A$1,$E$186:$BK$186,0)),"-") -> 15 ---> 15 | K9: =IFERROR(INDEX($E$219:$BD$231,MATCH($B9&K$6,$A$219:$A$231,0),MATCH($A$2,$E$217:$BD$217,0))&" ---> "&INDEX($E$219:$BD$231,MATCH($B9&K$6,$A$219:$A$231,0),MATCH($A$1,$E$217:$BD$217,0)),"-") -> 24 ---> 20 | L9: =IFERROR(INDEX($E$219:$BD$231,MATCH($B9&L$6,$A$219:$A$231,0),MATCH($A$2,$E$217:$BD$217,0))&" ---> "&INDEX($E$219:$BD$231,MATCH($B9&L$6,$A$219:$A$231,0),MATCH($A$1,$E$217:$BD$217,0)),"-") -> - | M9: =IFERROR(INDEX($E$235:$AY$251,MATCH($B9,$D$235:$D$251,0),MATCH($A$2,$E$233:$AY$233,0))&" ---> "&INDEX($E$235:$AY$251,MATCH($B9,$D$234:$D$251,0),MATCH($A$1,$E$233:$AY$233,0)),"-") -> 40 ---> 6
B10: =IFERROR(__xludf.DUMMYFUNCTION("""COMPUTED_VALUE"""),"Resma Papel Fotocopia (UN)") -> Resma Papel Fotocopia (UN) | C10: =IFERROR(INDEX($E$70:$BW$85,MATCH($B10,$D$70:$D$85,0),MATCH($A$2,$E$68:$BW$68,0))&" ---> "&INDEX($E$70:$BW$85,MATCH($B10,$D$70:$D$85,0),MATCH($A$1,$E$68:$BW$68,0)),"-") -> 6 ---> 9 | D10: =IFERROR(INDEX($E$89:$BQ$103,MATCH($B10,$D$89:$D$103,0),MATCH($A$2,$E$87:$BQ$87,0))&" ---> "&INDEX($E$89:$BQ$103,MATCH($B10,$D$89:$D$103,0),MATCH($A$1,$E$87:$BQ$87,0)),"-") -> 7 ---> 7 | E10: =IFERROR(INDEX($E$106:$BK$119,MATCH($B10,$D$106:$D$119,0),MATCH($A$2,$E$104:$BK$104,0))&" ---> "&INDEX($E$106:$BK$119,MATCH($B10,$D$106:$D$119,0),MATCH($A$1,$E$104:$BK$104,0)),"-") -> 3 unidades ---> 2 unidades | F10: =IFERROR(INDEX($E$123:$BO$158,MATCH($B10,$D$123:$D$158,0),MATCH($A$2,$E$121:$BO$121,0))&" ---> "&INDEX($E$123:$BO$158,MATCH($B10,$D$123:$D$158,0),MATCH($A$1,$E$121:$BO$121,0)),"-") -> - | G10: =IFERROR(INDEX($E$162:$AY$183,MATCH($B10&G$6,$A$162:$A$183,0),MATCH($A$2,$E$160:$AY$160,0))&" ---> "&INDEX($E$162:$AY$183,MATCH($B10&G$6,$A$162:$A$183,0),MATCH($A$1,$E$160:$AY$160,0)),"-") -> - | H10: =IFERROR(INDEX($E$162:$AY$183,MATCH($B10&H$6,$A$162:$A$183,0),MATCH($A$2,$E$160:$AY$160,0))&" ---> "&INDEX($E$162:$AY$183,MATCH($B10&H$6,$A$162:$A$183,0),MATCH($A$1,$E$160:$AY$160,0)),"-") -> - | I10: =IFERROR(INDEX($E$188:$BK$215,MATCH($B10&I$6,$A$188:$A$215,0),MATCH($A$2,$E$186:$BK$186,0))&" ---> "&INDEX($E$188:$BK$215,MATCH($B10&I$6,$A$188:$A$215,0),MATCH($A$1,$E$186:$BK$186,0)),"-") -> 1 ---> 1 | J10: =IFERROR(INDEX($E$188:$BK$215,MATCH($B10&J$6,$A$188:$A$215,0),MATCH($A$2,$E$186:$BK$186,0))&" ---> "&INDEX($E$188:$BK$215,MATCH($B10&J$6,$A$188:$A$215,0),MATCH($A$1,$E$186:$BK$186,0)),"-") -> 5 ---> 5 | K10: =IFERROR(INDEX($E$219:$BD$231,MATCH($B10&K$6,$A$219:$A$231,0),MATCH($A$2,$E$217:$BD$217,0))&" ---> "&INDEX($E$219:$BD$231,MATCH($B10&K$6,$A$219:$A$231,0),MATCH($A$1,$E$217:$BD$217,0)),"-") -> 7 ---> 6 | L10: =IFERROR(INDEX($E$219:$BD$231,MATCH($B10&L$6,$A$219:$A$231,0),MATCH($A$2,$E$217:$BD$217,0))&" ---> "&INDEX($E$219:$BD$231,MATCH($B10&L$6,$A$219:$A$231,0),MATCH($A$1,$E$217:$BD$217,0)),"-") -> - | M10: =IFERROR(INDEX($E$235:$AY$251,MATCH($B10,$D$235:$D$251,0),MATCH($A$2,$E$233:$AY$233,0))&" ---> "&INDEX($E$235:$AY$251,MATCH($B10,$D$234:$D$251,0),MATCH($A$1,$E$233:$AY$233,0)),"-") -> 5 ---> 29
B11: =IFERROR(__xludf.DUMMYFUNCTION("""COMPUTED_VALUE"""),"Servilletas") -> Servilletas | C11: =IFERROR(INDEX($E$70:$BW$85,MATCH($B11,$D$70:$D$85,0),MATCH($A$2,$E$68:$BW$68,0))&" ---> "&INDEX($E$70:$BW$85,MATCH($B11,$D$70:$D$85,0),MATCH($A$1,$E$68:$BW$68,0)),"-") -> 6 ---> 3 | D11: =IFERROR(INDEX($E$89:$BQ$103,MATCH($B11,$D$89:$D$103,0),MATCH($A$2,$E$87:$BQ$87,0))&" ---> "&INDEX($E$89:$BQ$103,MATCH($B11,$D$89:$D$103,0),MATCH($A$1,$E$87:$BQ$87,0)),"-") -> 12 ---> 10 | E11: =IFERROR(INDEX($E$106:$BK$119,MATCH($B11,$D$106:$D$119,0),MATCH($A$2,$E$104:$BK$104,0))&" ---> "&INDEX($E$106:$BK$119,MATCH($B11,$D$106:$D$119,0),MATCH($A$1,$E$104:$BK$104,0)),"-") -> - | F11: =IFERROR(INDEX($E$123:$BO$158,MATCH($B11,$D$123:$D$158,0),MATCH($A$2,$E$121:$BO$121,0))&" ---> "&INDEX($E$123:$BO$158,MATCH($B11,$D$123:$D$158,0),MATCH($A$1,$E$121:$BO$121,0)),"-") -> 14 ---> 13 | G11: =IFERROR(INDEX($E$162:$AY$183,MATCH($B11&G$6,$A$162:$A$183,0),MATCH($A$2,$E$160:$AY$160,0))&" ---> "&INDEX($E$162:$AY$183,MATCH($B11&G$6,$A$162:$A$183,0),MATCH($A$1,$E$160:$AY$160,0)),"-") -> - | H11: =IFERROR(INDEX($E$162:$AY$183,MATCH($B11&H$6,$A$162:$A$183,0),MATCH($A$2,$E$160:$AY$160,0))&" ---> "&INDEX($E$162:$AY$183,MATCH($B11&H$6,$A$162:$A$183,0),MATCH($A$1,$E$160:$AY$160,0)),"-") -> - | I11: =IFERROR(INDEX($E$188:$BK$215,MATCH($B11&I$6,$A$188:$A$215,0),MATCH($A$2,$E$186:$BK$186,0))&" ---> "&INDEX($E$188:$BK$215,MATCH($B11&I$6,$A$188:$A$215,0),MATCH($A$1,$E$186:$BK$186,0)),"-") -> - | J11: =IFERROR(INDEX($E$188:$BK$215,MATCH($B11&J$6,$A$188:$A$215,0),MATCH($A$2,$E$186:$BK$186,0))&" ---> "&INDEX($E$188:$BK$215,MATCH($B11&J$6,$A$188:$A$215,0),MATCH($A$1,$E$186:$BK$186,0)),"-") -> - | K11: =IFERROR(INDEX($E$219:$BD$231,MATCH($B11&K$6,$A$219:$A$231,0),MATCH($A$2,$E$217:$BD$217,0))&" ---> "&INDEX($E$219:$BD$231,MATCH($B11&K$6,$A$219:$A$231,0),MATCH($A$1,$E$217:$BD$217,0)),"-") -> 15 ---> 4 | L11: =IFERROR(INDEX($E$219:$BD$231,MATCH($B11&L$6,$A$219:$A$231,0),MATCH($A$2,$E$217:$BD$217,0))&" ---> "&INDEX($E$219:$BD$231,MATCH($B11&L$6,$A$219:$A$231,0),MATCH($A$1,$E$217:$BD$217,0)),"-") -> - | M11: =IFERROR(INDEX($E$235:$AY$251,MATCH($B11,$D$235:$D$251,0),MATCH($A$2,$E$233:$AY$233,0))&" ---> "&INDEX($E$235:$AY$251,MATCH($B11,$D$234:$D$251,0),MATCH($A$1,$E$233:$AY$233,0)),"-") -> 29 ---> piso 3 (6)- piso 5 (6) - piso 6 (6)
B12: =IFERROR(__xludf.DUMMYFUNCTION("""COMPUTED_VALUE"""),"Leche Liquida") -> Leche Liquida | C12: =IFERROR(INDEX($E$70:$BW$85,MATCH($B12,$D$70:$D$85,0),MATCH($A$2,$E$68:$BW$68,0))&" ---> "&INDEX($E$70:$BW$85,MATCH($B12,$D$70:$D$85,0),MATCH($A$1,$E$68:$BW$68,0)),"-") -> 10 ---> 7 | D12: =IFERROR(INDEX($E$89:$BQ$103,MATCH($B12,$D$89:$D$103,0),MATCH($A$2,$E$87:$BQ$87,0))&" ---> "&INDEX($E$89:$BQ$103,MATCH($B12,$D$89:$D$103,0),MATCH($A$1,$E$87:$BQ$87,0)),"-") -> 11 ---> 8 | E12: =IFERROR(INDEX($E$106:$BK$119,MATCH($B12,$D$106:$D$119,0),MATCH($A$2,$E$104:$BK$104,0))&" ---> "&INDEX($E$106:$BK$119,MATCH($B12,$D$106:$D$119,0),MATCH($A$1,$E$104:$BK$104,0)),"-") -> - | F12: =IFERROR(INDEX($E$123:$BO$158,MATCH($B12,$D$123:$D$158,0),MATCH($A$2,$E$121:$BO$121,0))&" ---> "&INDEX($E$123:$BO$158,MATCH($B12,$D$123:$D$158,0),MATCH($A$1,$E$121:$BO$121,0)),"-") -> 20 ---> 19 | G12: =IFERROR(INDEX($E$162:$AY$183,MATCH($B12&G$6,$A$162:$A$183,0),MATCH($A$2,$E$160:$AY$160,0))&" ---> "&INDEX($E$162:$AY$183,MATCH($B12&G$6,$A$162:$A$183,0),MATCH($A$1,$E$160:$AY$160,0)),"-") -> - | H12: =IFERROR(INDEX($E$162:$AY$183,MATCH($B12&H$6,$A$162:$A$183,0),MATCH($A$2,$E$160:$AY$160,0))&" ---> "&INDEX($E$162:$AY$183,MATCH($B12&H$6,$A$162:$A$183,0),MATCH($A$1,$E$160:$AY$160,0)),"-") -> - | I12: =IFERROR(INDEX($E$188:$BK$215,MATCH($B12&I$6,$A$188:$A$215,0),MATCH($A$2,$E$186:$BK$186,0))&" ---> "&INDEX($E$188:$BK$215,MATCH($B12&I$6,$A$188:$A$215,0),MATCH($A$1,$E$186:$BK$186,0)),"-") -> 0 ---> 0 | J12: =IFERROR(INDEX($E$188:$BK$215,MATCH($B12&J$6,$A$188:$A$215,0),MATCH($A$2,$E$186:$BK$186,0))&" ---> "&INDEX($E$188:$BK$215,MATCH($B12&J$6,$A$188:$A$215,0),MATCH($A$1,$E$186:$BK$186,0)),"-") -> 23 ---> 23 | K12: =IFERROR(INDEX($E$219:$BD$231,MATCH($B12&K$6,$A$219:$A$231,0),MATCH($A$2,$E$217:$BD$217,0))&" ---> "&INDEX($E$219:$BD$231,MATCH($B12&K$6,$A$219:$A$231,0),MATCH($A$1,$E$217:$BD$217,0)),"-") -> 24 ---> 20 | L12: =IFERROR(INDEX($E$219:$BD$231,MATCH($B12&L$6,$A$219:$A$231,0),MATCH($A$2,$E$217:$BD$217,0))&" ---> "&INDEX($E$219:$BD$231,MATCH($B12&L$6,$A$219:$A$231,0),MATCH($A$1,$E$217:$BD$217,0)),"-") -> - | M12: =IFERROR(INDEX($E$235:$AY$251,MATCH($B12,$D$235:$D$251,0),MATCH($A$2,$E$233:$AY$233,0))&" ---> "&INDEX($E$235:$AY$251,MATCH($B12,$D$234:$D$251,0),MATCH($A$1,$E$233:$AY$233,0)),"-") -> -
B13: =IFERROR(__xludf.DUMMYFUNCTION("""COMPUTED_VALUE"""),"Cafe Granulado") -> Cafe Granulado | C13: =IFERROR(INDEX($E$70:$BW$85,MATCH($B13,$D$70:$D$85,0),MATCH($A$2,$E$68:$BW$68,0))&" ---> "&INDEX($E$70:$BW$85,MATCH($B13,$D$70:$D$85,0),MATCH($A$1,$E$68:$BW$68,0)),"-") -> 2 ---> 2 | D13: =IFERROR(INDEX($E$89:$BQ$103,MATCH($B13,$D$89:$D$103,0),MATCH($A$2,$E$87:$BQ$87,0))&" ---> "&INDEX($E$89:$BQ$103,MATCH($B13,$D$89:$D$103,0),MATCH($A$1,$E$87:$BQ$87,0)),"-") -> 1 ---> 1 | E13: =IFERROR(INDEX($E$106:$BK$119,MATCH($B13,$D$106:$D$119,0),MATCH($A$2,$E$104:$BK$104,0))&" ---> "&INDEX($E$106:$BK$119,MATCH($B13,$D$106:$D$119,0),MATCH($A$1,$E$104:$BK$104,0)),"-") -> 1 unidad ---> 1 unidad | F13: =IFERROR(INDEX($E$123:$BO$158,MATCH($B13,$D$123:$D$158,0),MATCH($A$2,$E$121:$BO$121,0))&" ---> "&INDEX($E$123:$BO$158,MATCH($B13,$D$123:$D$158,0),MATCH($A$1,$E$121:$BO$121,0)),"-") -> - | G13: =IFERROR(INDEX($E$162:$AY$183,MATCH($B13&G$6,$A$162:$A$183,0),MATCH($A$2,$E$160:$AY$160,0))&" ---> "&INDEX($E$162:$AY$183,MATCH($B13&G$6,$A$162:$A$183,0),MATCH($A$1,$E$160:$AY$160,0)),"-") -> - | H13: =IFERROR(INDEX($E$162:$AY$183,MATCH($B13&H$6,$A$162:$A$183,0),MATCH($A$2,$E$160:$AY$160,0))&" ---> "&INDEX($E$162:$AY$183,MATCH($B13&H$6,$A$162:$A$183,0),MATCH($A$1,$E$160:$AY$160,0)),"-") -> - | I13: =IFERROR(INDEX($E$188:$BK$215,MATCH($B13&I$6,$A$188:$A$215,0),MATCH($A$2,$E$186:$BK$186,0))&" ---> "&INDEX($E$188:$BK$215,MATCH($B13&I$6,$A$188:$A$215,0),MATCH($A$1,$E$186:$BK$186,0)),"-") -> 8 ---> 8 | J13: =IFERROR(INDEX($E$188:$BK$215,MATCH($B13&J$6,$A$188:$A$215,0),MATCH($A$2,$E$186:$BK$186,0))&" ---> "&INDEX($E$188:$BK$215,MATCH($B13&J$6,$A$188:$A$215,0),MATCH($A$1,$E$186:$BK$186,0)),"-") -> 4 ---> 4 | K13: =IFERROR(INDEX($E$219:$BD$231,MATCH($B13&K$6,$A$219:$A$231,0),MATCH($A$2,$E$217:$BD$217,0))&" ---> "&INDEX($E$219:$BD$231,MATCH($B13&K$6,$A$219:$A$231,0),MATCH($A$1,$E$217:$BD$217,0)),"-") -> - | L13: =IFERROR(INDEX($E$219:$BD$231,MATCH($B13&L$6,$A$219:$A$231,0),MATCH($A$2,$E$217:$BD$217,0))&" ---> "&INDEX($E$219:$BD$231,MATCH($B13&L$6,$A$219:$A$231,0),MATCH($A$1,$E$217:$BD$217,0)),"-") -> - | M13: =IFERROR(INDEX($E$235:$AY$251,MATCH($B13,$D$235:$D$251,0),MATCH($A$2,$E$233:$AY$233,0))&" ---> "&INDEX($E$235:$AY$251,MATCH($B13,$D$234:$D$251,0),MATCH($A$1,$E$233:$AY$233,0)),"-") -> 2 ---> 5
B14: =IFERROR(__xludf.DUMMYFUNCTION("""COMPUTED_VALUE"""),"Endulzante ") -> Endulzante | C14: =IFERROR(INDEX($E$70:$BW$85,MATCH($B14,$D$70:$D$85,0),MATCH($A$2,$E$68:$BW$68,0))&" ---> "&INDEX($E$70:$BW$85,MATCH($B14,$D$70:$D$85,0),MATCH($A$1,$E$68:$BW$68,0)),"-") -> 3 ---> 2 | D14: =IFERROR(INDEX($E$89:$BQ$103,MATCH($B14,$D$89:$D$103,0),MATCH($A$2,$E$87:$BQ$87,0))&" ---> "&INDEX($E$89:$BQ$103,MATCH($B14,$D$89:$D$103,0),MATCH($A$1,$E$87:$BQ$87,0)),"-") -> 0 ---> 0 | E14: =IFERROR(INDEX($E$106:$BK$119,MATCH($B14,$D$106:$D$119,0),MATCH($A$2,$E$104:$BK$104,0))&" ---> "&INDEX($E$106:$BK$119,MATCH($B14,$D$106:$D$119,0),MATCH($A$1,$E$104:$BK$104,0)),"-") -> 1 unidad ---> 1 unidad | F14: =IFERROR(INDEX($E$123:$BO$158,MATCH($B14,$D$123:$D$158,0),MATCH($A$2,$E$121:$BO$121,0))&" ---> "&INDEX($E$123:$BO$158,MATCH($B14,$D$123:$D$158,0),MATCH($A$1,$E$121:$BO$121,0)),"-") -> 4 ---> 4 | I14: =IFERROR(INDEX($E$188:$BK$215,MATCH($B14&I$6,$A$188:$A$215,0),MATCH($A$2,$E$186:$BK$186,0))&" ---> "&INDEX($E$188:$BK$215,MATCH($B14&I$6,$A$188:$A$215,0),MATCH($A$1,$E$186:$BK$186,0)),"-") -> 3 ---> 3 | J14: =IFERROR(INDEX($E$188:$BK$215,MATCH($B14&J$6,$A$188:$A$215,0),MATCH($A$2,$E$186:$BK$186,0))&" ---> "&INDEX($E$188:$BK$215,MATCH($B14&J$6,$A$188:$A$215,0),MATCH($A$1,$E$186:$BK$186,0)),"-") -> - | K14: =IFERROR(INDEX($E$219:$BD$231,MATCH($B14&K$6,$A$219:$A$231,0),MATCH($A$2,$E$217:$BD$217,0))&" ---> "&INDEX($E$219:$BD$231,MATCH($B14&K$6,$A$219:$A$231,0),MATCH($A$1,$E$217:$BD$217,0)),"-") -> 3 ---> 2 | L14: =IFERROR(INDEX($E$219:$BD$231,MATCH($B14&L$6,$A$219:$A$231,0),MATCH($A$2,$E$217:$BD$217,0))&" ---> "&INDEX($E$219:$BD$231,MATCH($B14&L$6,$A$219:$A$231,0),MATCH($A$1,$E$217:$BD$217,0)),"-") -> -
B15: =IFERROR(__xludf.DUMMYFUNCTION("""COMPUTED_VALUE"""),"Azucar kg") -> Azucar kg | C15: =IFERROR(INDEX($E$70:$BW$85,MATCH($B15,$D$70:$D$85,0),MATCH($A$2,$E$68:$BW$68,0))&" ---> "&INDEX($E$70:$BW$85,MATCH($B15,$D$70:$D$85,0),MATCH($A$1,$E$68:$BW$68,0)),"-") -> 0 ---> 0 | D15: =IFERROR(INDEX($E$89:$BQ$103,MATCH($B15,$D$89:$D$103,0),MATCH($A$2,$E$87:$BQ$87,0))&" ---> "&INDEX($E$89:$BQ$103,MATCH($B15,$D$89:$D$103,0),MATCH($A$1,$E$87:$BQ$87,0)),"-") -> - | E15: =IFERROR(INDEX($E$106:$BK$119,MATCH($B15,$D$106:$D$119,0),MATCH($A$2,$E$104:$BK$104,0))&" ---> "&INDEX($E$106:$BK$119,MATCH($B15,$D$106:$D$119,0),MATCH($A$1,$E$104:$BK$104,0)),"-") -> - | F15: =IFERROR(INDEX($E$123:$BO$158,MATCH($B15,$D$123:$D$158,0),MATCH($A$2,$E$121:$BO$121,0))&" ---> "&INDEX($E$123:$BO$158,MATCH($B15,$D$123:$D$158,0),MATCH($A$1,$E$121:$BO$121,0)),"-") -> - | I15: =IFERROR(INDEX($E$188:$BK$215,MATCH($B15&I$6,$A$188:$A$215,0),MATCH($A$2,$E$186:$BK$186,0))&" ---> "&INDEX($E$188:$BK$215,MATCH($B15&I$6,$A$188:$A$215,0),MATCH($A$1,$E$186:$BK$186,0)),"-") -> - | J15: =IFERROR(INDEX($E$188:$BK$215,MATCH($B15&J$6,$A$188:$A$215,0),MATCH($A$2,$E$186:$BK$186,0))&" ---> "&INDEX($E$188:$BK$215,MATCH($B15&J$6,$A$188:$A$215,0),MATCH($A$1,$E$186:$BK$186,0)),"-") -> - | K15: =IFERROR(INDEX($E$219:$BD$231,MATCH($B15&K$6,$A$219:$A$231,0),MATCH($A$2,$E$217:$BD$217,0))&" ---> "&INDEX($E$219:$BD$231,MATCH($B15&K$6,$A$219:$A$231,0),MATCH($A$1,$E$217:$BD$217,0)),"-") -> - | L15: =IFERROR(INDEX($E$219:$BD$231,MATCH($B15&L$6,$A$219:$A$231,0),MATCH($A$2,$E$217:$BD$217,0))&" ---> "&INDEX($E$219:$BD$231,MATCH($B15&L$6,$A$219:$A$231,0),MATCH($A$1,$E$217:$BD$217,0)),"-") -> -
B16: =IFERROR(__xludf.DUMMYFUNCTION("""COMPUTED_VALUE"""),"Cloro Gel ") -> Cloro Gel | C16: =IFERROR(INDEX($E$70:$BW$85,MATCH($B16,$D$70:$D$85,0),MATCH($A$2,$E$68:$BW$68,0))&" ---> "&INDEX($E$70:$BW$85,MATCH($B16,$D$70:$D$85,0),MATCH($A$1,$E$68:$BW$68,0)),"-") -> 0 ---> 0 | D16: =IFERROR(INDEX($E$89:$BQ$103,MATCH($B16,$D$89:$D$103,0),MATCH($A$2,$E$87:$BQ$87,0))&" ---> "&INDEX($E$89:$BQ$103,MATCH($B16,$D$89:$D$103,0),MATCH($A$1,$E$87:$BQ$87,0)),"-") -> 0 ---> 0 | E16: =IFERROR(INDEX($E$106:$BK$119,MATCH($B16,$D$106:$D$119,0),MATCH($A$2,$E$104:$BK$104,0))&" ---> "&INDEX($E$106:$BK$119,MATCH($B16,$D$106:$D$119,0),MATCH($A$1,$E$104:$BK$104,0)),"-") -> 1 bidón ---> 1 bidón | F16: =IFERROR(INDEX($E$123:$BO$158,MATCH($B16,$D$123:$D$158,0),MATCH($A$2,$E$121:$BO$121,0))&" ---> "&INDEX($E$123:$BO$158,MATCH($B16,$D$123:$D$158,0),MATCH($A$1,$E$121:$BO$121,0)),"-") -> - | G16: =IFERROR(INDEX($E$162:$AY$183,MATCH($B16&G$6,$A$162:$A$183,0),MATCH($A$2,$E$160:$AY$160,0))&" ---> "&INDEX($E$162:$AY$183,MATCH($B16&G$6,$A$162:$A$183,0),MATCH($A$1,$E$160:$AY$160,0)),"-") -> - | H16: =IFERROR(INDEX($E$162:$AY$183,MATCH($B16&H$6,$A$162:$A$183,0),MATCH($A$2,$E$160:$AY$160,0))&" ---> "&INDEX($E$162:$AY$183,MATCH($B16&H$6,$A$162:$A$183,0),MATCH($A$1,$E$160:$AY$160,0)),"-") -> - | I16: =IFERROR(INDEX($E$188:$BK$215,MATCH($B16&I$6,$A$188:$A$215,0),MATCH($A$2,$E$186:$BK$186,0))&" ---> "&INDEX($E$188:$BK$215,MATCH($B16&I$6,$A$188:$A$215,0),MATCH($A$1,$E$186:$BK$186,0)),"-") -> - | J16: =IFERROR(INDEX($E$188:$BK$215,MATCH($B16&J$6,$A$188:$A$215,0),MATCH($A$2,$E$186:$BK$186,0))&" ---> "&INDEX($E$188:$BK$215,MATCH($B16&J$6,$A$188:$A$215,0),MATCH($A$1,$E$186:$BK$186,0)),"-") -> - | K16: =IFERROR(INDEX($E$219:$BD$231,MATCH($B16&K$6,$A$219:$A$231,0),MATCH($A$2,$E$217:$BD$217,0))&" ---> "&INDEX($E$219:$BD$231,MATCH($B16&K$6,$A$219:$A$231,0),MATCH($A$1,$E$217:$BD$217,0)),"-") -> 1 ---> 1 | L16: =IFERROR(INDEX($E$219:$BD$231,MATCH($B16&L$6,$A$219:$A$231,0),MATCH($A$2,$E$217:$BD$217,0))&" ---> "&INDEX($E$219:$BD$231,MATCH($B16&L$6,$A$219:$A$231,0),MATCH($A$1,$E$217:$BD$217,0)),"-") -> - | M16: =IFERROR(INDEX($E$235:$AY$251,MATCH($B16,$D$235:$D$251,0),MATCH($A$2,$E$233:$AY$233,0))&" ---> "&INDEX($E$235:$AY$251,MATCH($B16,$D$234:$D$251,0),MATCH($A$1,$E$233:$AY$233,0)),"-") -> 1 ---> 3
B17: =IFERROR(__xludf.DUMMYFUNCTION("""COMPUTED_VALUE"""),"Limpia Piso ") -> Limpia Piso | C17: =IFERROR(INDEX($E$70:$BW$85,MATCH($B17,$D$70:$D$85,0),MATCH($A$2,$E$68:$BW$68,0))&" ---> "&INDEX($E$70:$BW$85,MATCH($B17,$D$70:$D$85,0),MATCH($A$1,$E$68:$BW$68,0)),"-") -> 1 ---> 0 | D17: =IFERROR(INDEX($E$89:$BQ$103,MATCH($B17,$D$89:$D$103,0),MATCH($A$2,$E$87:$BQ$87,0))&" ---> "&INDEX($E$89:$BQ$103,MATCH($B17,$D$89:$D$103,0),MATCH($A$1,$E$87:$BQ$87,0)),"-") -> 1 ---> 1 | E17: =IFERROR(INDEX($E$106:$BK$119,MATCH($B17,$D$106:$D$119,0),MATCH($A$2,$E$104:$BK$104,0))&" ---> "&INDEX($E$106:$BK$119,MATCH($B17,$D$106:$D$119,0),MATCH($A$1,$E$104:$BK$104,0)),"-") -> 1 bidón ---> 1 bidón | F17: =IFERROR(INDEX($E$123:$BO$158,MATCH($B17,$D$123:$D$158,0),MATCH($A$2,$E$121:$BO$121,0))&" ---> "&INDEX($E$123:$BO$158,MATCH($B17,$D$123:$D$158,0),MATCH($A$1,$E$121:$BO$121,0)),"-") -> - | G17: =IFERROR(INDEX($E$162:$AY$183,MATCH($B17&G$6,$A$162:$A$183,0),MATCH($A$2,$E$160:$AY$160,0))&" ---> "&INDEX($E$162:$AY$183,MATCH($B17&G$6,$A$162:$A$183,0),MATCH($A$1,$E$160:$AY$160,0)),"-") -> - | H17: =IFERROR(INDEX($E$162:$AY$183,MATCH($B17&H$6,$A$162:$A$183,0),MATCH($A$2,$E$160:$AY$160,0))&" ---> "&INDEX($E$162:$AY$183,MATCH($B17&H$6,$A$162:$A$183,0),MATCH($A$1,$E$160:$AY$160,0)),"-") -> - | I17: =IFERROR(INDEX($E$188:$BK$215,MATCH($B17&I$6,$A$188:$A$215,0),MATCH($A$2,$E$186:$BK$186,0))&" ---> "&INDEX($E$188:$BK$215,MATCH($B17&I$6,$A$188:$A$215,0),MATCH($A$1,$E$186:$BK$186,0)),"-") -> - | J17: =IFERROR(INDEX($E$188:$BK$215,MATCH($B17&J$6,$A$188:$A$215,0),MATCH($A$2,$E$186:$BK$186,0))&" ---> "&INDEX($E$188:$BK$215,MATCH($B17&J$6,$A$188:$A$215,0),MATCH($A$1,$E$186:$BK$186,0)),"-") -> - | K17: =IFERROR(INDEX($E$219:$BD$231,MATCH($B17&K$6,$A$219:$A$231,0),MATCH($A$2,$E$217:$BD$217,0))&" ---> "&INDEX($E$219:$BD$231,MATCH($B17&K$6,$A$219:$A$231,0),MATCH($A$1,$E$217:$BD$217,0)),"-") -> 3 ---> 2 | L17: =IFERROR(INDEX($E$219:$BD$231,MATCH($B17&L$6,$A$219:$A$231,0),MATCH($A$2,$E$217:$BD$217,0))&" ---> "&INDEX($E$219:$BD$231,MATCH($B17&L$6,$A$219:$A$231,0),MATCH($A$1,$E$217:$BD$217,0)),"-") -> - | M17: =IFERROR(INDEX($E$235:$AY$251,MATCH($B17,$D$235:$D$251,0),MATCH($A$2,$E$233:$AY$233,0))&" ---> "&INDEX($E$235:$AY$251,MATCH($B17,$D$234:$D$251,0),MATCH($A$1,$E$233:$AY$233,0)),"-") -> 1 ---> 26
B18: =IFERROR(__xludf.DUMMYFUNCTION("""COMPUTED_VALUE"""),"Bolsas Basura 50x70") -> Bolsas Basura 50x70 | C18: =IFERROR(INDEX($E$70:$BW$85,MATCH($B18,$D$70:$D$85,0),MATCH($A$2,$E$68:$BW$68,0))&" ---> "&INDEX($E$70:$BW$85,MATCH($B18,$D$70:$D$85,0),MATCH($A$1,$E$68:$BW$68,0)),"-") -> 0 ---> 0 | D18: =IFERROR(INDEX($E$89:$BQ$103,MATCH($B18,$D$89:$D$103,0),MATCH($A$2,$E$87:$BQ$87,0))&" ---> "&INDEX($E$89:$BQ$103,MATCH($B18,$D$89:$D$103,0),MATCH($A$1,$E$87:$BQ$87,0)),"-") -> 14 ---> 11 | E18: =IFERROR(INDEX($E$106:$BK$119,MATCH($B18,$D$106:$D$119,0),MATCH($A$2,$E$104:$BK$104,0))&" ---> "&INDEX($E$106:$BK$119,MATCH($B18,$D$106:$D$119,0),MATCH($A$1,$E$104:$BK$104,0)),"-") -> - | F18: =IFERROR(INDEX($E$123:$BO$158,MATCH($B18,$D$123:$D$158,0),MATCH($A$2,$E$121:$BO$121,0))&" ---> "&INDEX($E$123:$BO$158,MATCH($B18,$D$123:$D$158,0),MATCH($A$1,$E$121:$BO$121,0)),"-") -> 18 ---> 16 | G18: =IFERROR(INDEX($E$162:$AY$183,MATCH($B18&G$6,$A$162:$A$183,0),MATCH($A$2,$E$160:$AY$160,0))&" ---> "&INDEX($E$162:$AY$183,MATCH($B18&G$6,$A$162:$A$183,0),MATCH($A$1,$E$160:$AY$160,0)),"-") -> - | H18: =IFERROR(INDEX($E$162:$AY$183,MATCH($B18&H$6,$A$162:$A$183,0),MATCH($A$2,$E$160:$AY$160,0))&" ---> "&INDEX($E$162:$AY$183,MATCH($B18&H$6,$A$162:$A$183,0),MATCH($A$1,$E$160:$AY$160,0)),"-") -> - | I18: =IFERROR(INDEX($E$188:$BK$215,MATCH($B18&I$6,$A$188:$A$215,0),MATCH($A$2,$E$186:$BK$186,0))&" ---> "&INDEX($E$188:$BK$215,MATCH($B18&I$6,$A$188:$A$215,0),MATCH($A$1,$E$186:$BK$186,0)),"-") -> 4 ---> 4 | J18: =IFERROR(INDEX($E$188:$BK$215,MATCH($B18&J$6,$A$188:$A$215,0),MATCH($A$2,$E$186:$BK$186,0))&" ---> "&INDEX($E$188:$BK$215,MATCH($B18&J$6,$A$188:$A$215,0),MATCH($A$1,$E$186:$BK$186,0)),"-") -> 4 ---> 4 | K18: =IFERROR(INDEX($E$219:$BD$231,MATCH($B18&K$6,$A$219:$A$231,0),MATCH($A$2,$E$217:$BD$217,0))&" ---> "&INDEX($E$219:$BD$231,MATCH($B18&K$6,$A$219:$A$231,0),MATCH($A$1,$E$217:$BD$217,0)),"-") -> - | L18: =IFERROR(INDEX($E$219:$BD$231,MATCH($B18&L$6,$A$219:$A$231,0),MATCH($A$2,$E$217:$BD$217,0))&" ---> "&INDEX($E$219:$BD$231,MATCH($B18&L$6,$A$219:$A$231,0),MATCH($A$1,$E$217:$BD$217,0)),"-") -> - | M18: =IFERROR(INDEX($E$235:$AY$251,MATCH($B18,$D$235:$D$251,0),MATCH($A$2,$E$233:$AY$233,0))&" ---> "&INDEX($E$235:$AY$251,MATCH($B18,$D$234:$D$251,0),MATCH($A$1,$E$233:$AY$233,0)),"-") -> 4 ---> 4
B19: =IFERROR(__xludf.DUMMYFUNCTION("""COMPUTED_VALUE"""),"Bolsas Basura 70x90") -> Bolsas Basura 70x90 | C19: =IFERROR(INDEX($E$70:$BW$85,MATCH($B19,$D$70:$D$85,0),MATCH($A$2,$E$68:$BW$68,0))&" ---> "&INDEX($E$70:$BW$85,MATCH($B19,$D$70:$D$85,0),MATCH($A$1,$E$68:$BW$68,0)),"-") -> 2 ---> 1 | D19: =IFERROR(INDEX($E$89:$BQ$103,MATCH($B19,$D$89:$D$103,0),MATCH($A$2,$E$87:$BQ$87,0))&" ---> "&INDEX($E$89:$BQ$103,MATCH($B19,$D$89:$D$103,0),MATCH($A$1,$E$87:$BQ$87,0)),"-") -> 16 ---> 14 | E19: =IFERROR(INDEX($E$106:$BK$119,MATCH($B19,$D$106:$D$119,0),MATCH($A$2,$E$104:$BK$104,0))&" ---> "&INDEX($E$106:$BK$119,MATCH($B19,$D$106:$D$119,0),MATCH($A$1,$E$104:$BK$104,0)),"-") -> - | F19: =IFERROR(INDEX($E$123:$BO$158,MATCH($B19,$D$123:$D$158,0),MATCH($A$2,$E$121:$BO$121,0))&" ---> "&INDEX($E$123:$BO$158,MATCH($B19,$D$123:$D$158,0),MATCH($A$1,$E$121:$BO$121,0)),"-") -> 5 ---> 4 | G19: =IFERROR(INDEX($E$162:$AY$183,MATCH($B19&G$6,$A$162:$A$183,0),MATCH($A$2,$E$160:$AY$160,0))&" ---> "&INDEX($E$162:$AY$183,MATCH($B19&G$6,$A$162:$A$183,0),MATCH($A$1,$E$160:$AY$160,0)),"-") -> - | H19: =IFERROR(INDEX($E$162:$AY$183,MATCH($B19&H$6,$A$162:$A$183,0),MATCH($A$2,$E$160:$AY$160,0))&" ---> "&INDEX($E$162:$AY$183,MATCH($B19&H$6,$A$162:$A$183,0),MATCH($A$1,$E$160:$AY$160,0)),"-") -> - | I19: =IFERROR(INDEX($E$188:$BK$215,MATCH($B19&I$6,$A$188:$A$215,0),MATCH($A$2,$E$186:$BK$186,0))&" ---> "&INDEX($E$188:$BK$215,MATCH($B19&I$6,$A$188:$A$215,0),MATCH($A$1,$E$186:$BK$186,0)),"-") -> 5 ---> 5 | J19: =IFERROR(INDEX($E$188:$BK$215,MATCH($B19&J$6,$A$188:$A$215,0),MATCH($A$2,$E$186:$BK$186,0))&" ---> "&INDEX($E$188:$BK$215,MATCH($B19&J$6,$A$188:$A$215,0),MATCH($A$1,$E$186:$BK$186,0)),"-") -> 11 ---> 11 | K19: =IFERROR(INDEX($E$219:$BD$231,MATCH($B19&K$6,$A$219:$A$231,0),MATCH($A$2,$E$217:$BD$217,0))&" ---> "&INDEX($E$219:$BD$231,MATCH($B19&K$6,$A$219:$A$231,0),MATCH($A$1,$E$217:$BD$217,0)),"-") -> - | L19: =IFERROR(INDEX($E$219:$BD$231,MATCH($B19&L$6,$A$219:$A$231,0),MATCH($A$2,$E$217:$BD$217,0))&" ---> "&INDEX($E$219:$BD$231,MATCH($B19&L$6,$A$219:$A$231,0),MATCH($A$1,$E$217:$BD$217,0)),"-") -> - | M19: =IFERROR(INDEX($E$235:$AY$251,MATCH($B19,$D$235:$D$251,0),MATCH($A$2,$E$233:$AY$233,0))&" ---> "&INDEX($E$235:$AY$251,MATCH($B19,$D$234:$D$251,0),MATCH($A$1,$E$233:$AY$233,0)),"-") -> 21 ---> 13
B20: =IFERROR(__xludf.DUMMYFUNCTION("""COMPUTED_VALUE"""),"Bolsas Basura 80x110") -> Bolsas Basura 80x110 | C20: =IFERROR(INDEX($E$70:$BW$85,MATCH($B20,$D$70:$D$85,0),MATCH($A$2,$E$68:$BW$68,0))&" ---> "&INDEX($E$70:$BW$85,MATCH($B20,$D$70:$D$85,0),MATCH($A$1,$E$68:$BW$68,0)),"-") -> 2 ---> 2 | D20: =IFERROR(INDEX($E$89:$BQ$103,MATCH($B20,$D$89:$D$103,0),MATCH($A$2,$E$87:$BQ$87,0))&" ---> "&INDEX($E$89:$BQ$103,MATCH($B20,$D$89:$D$103,0),MATCH($A$1,$E$87:$BQ$87,0)),"-") -> 4 ---> 2 | E20: =IFERROR(INDEX($E$106:$BK$119,MATCH($B20,$D$106:$D$119,0),MATCH($A$2,$E$104:$BK$104,0))&" ---> "&INDEX($E$106:$BK$119,MATCH($B20,$D$106:$D$119,0),MATCH($A$1,$E$104:$BK$104,0)),"-") -> - | F20: =IFERROR(INDEX($E$123:$BO$158,MATCH($B20,$D$123:$D$158,0),MATCH($A$2,$E$121:$BO$121,0))&" ---> "&INDEX($E$123:$BO$158,MATCH($B20,$D$123:$D$158,0),MATCH($A$1,$E$121:$BO$121,0)),"-") -> 13 ---> 13 | G20: =IFERROR(INDEX($E$162:$AY$183,MATCH($B20&G$6,$A$162:$A$183,0),MATCH($A$2,$E$160:$AY$160,0))&" ---> "&INDEX($E$162:$AY$183,MATCH($B20&G$6,$A$162:$A$183,0),MATCH($A$1,$E$160:$AY$160,0)),"-") -> - | H20: =IFERROR(INDEX($E$162:$AY$183,MATCH($B20&H$6,$A$162:$A$183,0),MATCH($A$2,$E$160:$AY$160,0))&" ---> "&INDEX($E$162:$AY$183,MATCH($B20&H$6,$A$162:$A$183,0),MATCH($A$1,$E$160:$AY$160,0)),"-") -> - | I20: =IFERROR(INDEX($E$188:$BK$215,MATCH($B20&I$6,$A$188:$A$215,0),MATCH($A$2,$E$186:$BK$186,0))&" ---> "&INDEX($E$188:$BK$215,MATCH($B20&I$6,$A$188:$A$215,0),MATCH($A$1,$E$186:$BK$186,0)),"-") -> 11 ---> 11 | J20: =IFERROR(INDEX($E$188:$BK$215,MATCH($B20&J$6,$A$188:$A$215,0),MATCH($A$2,$E$186:$BK$186,0))&" ---> "&INDEX($E$188:$BK$215,MATCH($B20&J$6,$A$188:$A$215,0),MATCH($A$1,$E$186:$BK$186,0)),"-") -> 0 ---> 0 | K20: =IFERROR(INDEX($E$219:$BD$231,MATCH($B20&K$6,$A$219:$A$231,0),MATCH($A$2,$E$217:$BD$217,0))&" ---> "&INDEX($E$219:$BD$231,MATCH($B20&K$6,$A$219:$A$231,0),MATCH($A$1,$E$217:$BD$217,0)),"-") -> - | L20: =IFERROR(INDEX($E$219:$BD$231,MATCH($B20&L$6,$A$219:$A$231,0),MATCH($A$2,$E$217:$BD$217,0))&" ---> "&INDEX($E$219:$BD$231,MATCH($B20&L$6,$A$219:$A$231,0),MATCH($A$1,$E$217:$BD$217,0)),"-") -> - | M20: =IFERROR(INDEX($E$235:$AY$251,MATCH($B20,$D$235:$D$251,0),MATCH($A$2,$E$233:$AY$233,0))&" ---> "&INDEX($E$235:$AY$251,MATCH($B20,$D$234:$D$251,0),MATCH($A$1,$E$233:$AY$233,0)),"-") -> 28 ---> 13
B21: =IFERROR(__xludf.DUMMYFUNCTION("""COMPUTED_VALUE"""),"Esponja 4U ") -> Esponja 4U | C21: =IFERROR(INDEX($E$70:$BW$85,MATCH($B21,$D$70:$D$85,0),MATCH($A$2,$E$68:$BW$68,0))&" ---> "&INDEX($E$70:$BW$85,MATCH($B21,$D$70:$D$85,0),MATCH($A$1,$E$68:$BW$68,0)),"-") -> 16 ---> 12 | D21: =IFERROR(INDEX($E$89:$BQ$103,MATCH($B21,$D$89:$D$103,0),MATCH($A$2,$E$87:$BQ$87,0))&" ---> "&INDEX($E$89:$BQ$103,MATCH($B21,$D$89:$D$103,0),MATCH($A$1,$E$87:$BQ$87,0)),"-") -> 0 ---> 0 | E21: =IFERROR(INDEX($E$106:$BK$119,MATCH($B21,$D$106:$D$119,0),MATCH($A$2,$E$104:$BK$104,0))&" ---> "&INDEX($E$106:$BK$119,MATCH($B21,$D$106:$D$119,0),MATCH($A$1,$E$104:$BK$104,0)),"-") -> 1 paquete ---> 1 paquete | F21: =IFERROR(INDEX($E$123:$BO$158,MATCH($B21,$D$123:$D$158,0),MATCH($A$2,$E$121:$BO$121,0))&" ---> "&INDEX($E$123:$BO$158,MATCH($B21,$D$123:$D$158,0),MATCH($A$1,$E$121:$BO$121,0)),"-") -> - | G21: =IFERROR(INDEX($E$162:$AY$183,MATCH($B21&G$6,$A$162:$A$183,0),MATCH($A$2,$E$160:$AY$160,0))&" ---> "&INDEX($E$162:$AY$183,MATCH($B21&G$6,$A$162:$A$183,0),MATCH($A$1,$E$160:$AY$160,0)),"-") -> - | H21: =IFERROR(INDEX($E$162:$AY$183,MATCH($B21&H$6,$A$162:$A$183,0),MATCH($A$2,$E$160:$AY$160,0))&" ---> "&INDEX($E$162:$AY$183,MATCH($B21&H$6,$A$162:$A$183,0),MATCH($A$1,$E$160:$AY$160,0)),"-") -> - | I21: =IFERROR(INDEX($E$188:$BK$215,MATCH($B21&I$6,$A$188:$A$215,0),MATCH($A$2,$E$186:$BK$186,0))&" ---> "&INDEX($E$188:$BK$215,MATCH($B21&I$6,$A$188:$A$215,0),MATCH($A$1,$E$186:$BK$186,0)),"-") -> - | J21: =IFERROR(INDEX($E$188:$BK$215,MATCH($B21&J$6,$A$188:$A$215,0),MATCH($A$2,$E$186:$BK$186,0))&" ---> "&INDEX($E$188:$BK$215,MATCH($B21&J$6,$A$188:$A$215,0),MATCH($A$1,$E$186:$BK$186,0)),"-") -> - | K21: =IFERROR(INDEX($E$219:$BD$231,MATCH($B21&K$6,$A$219:$A$231,0),MATCH($A$2,$E$217:$BD$217,0))&" ---> "&INDEX($E$219:$BD$231,MATCH($B21&K$6,$A$219:$A$231,0),MATCH($A$1,$E$217:$BD$217,0)),"-") -> - | L21: =IFERROR(INDEX($E$219:$BD$231,MATCH($B21&L$6,$A$219:$A$231,0),MATCH($A$2,$E$217:$BD$217,0))&" ---> "&INDEX($E$219:$BD$231,MATCH($B21&L$6,$A$219:$A$231,0),MATCH($A$1,$E$217:$BD$217,0)),"-") -> - | M21: =IFERROR(INDEX($E$235:$AY$251,MATCH($B21,$D$235:$D$251,0),MATCH($A$2,$E$233:$AY$233,0))&" ---> "&INDEX($E$235:$AY$251,MATCH($B21,$D$234:$D$251,0),MATCH($A$1,$E$233:$AY$233,0)),"-") -> -
B22: =IFERROR(__xludf.DUMMYFUNCTION("""COMPUTED_VALUE"""),"Mopa Redonda ") -> Mopa Redonda | C22: =IFERROR(INDEX($E$70:$BW$85,MATCH($B22,$D$70:$D$85,0),MATCH($A$2,$E$68:$BW$68,0))&" ---> "&INDEX($E$70:$BW$85,MATCH($B22,$D$70:$D$85,0),MATCH($A$1,$E$68:$BW$68,0)),"-") -> 3 ---> 2 | D22: =IFERROR(INDEX($E$89:$BQ$103,MATCH($B22,$D$89:$D$103,0),MATCH($A$2,$E$87:$BQ$87,0))&" ---> "&INDEX($E$89:$BQ$103,MATCH($B22,$D$89:$D$103,0),MATCH($A$1,$E$87:$BQ$87,0)),"-") -> 5 ---> 4 | E22: =IFERROR(INDEX($E$106:$BK$119,MATCH($B22,$D$106:$D$119,0),MATCH($A$2,$E$104:$BK$104,0))&" ---> "&INDEX($E$106:$BK$119,MATCH($B22,$D$106:$D$119,0),MATCH($A$1,$E$104:$BK$104,0)),"-") -> 2 unidades ---> 2 unidades | F22: =IFERROR(INDEX($E$123:$BO$158,MATCH($B22,$D$123:$D$158,0),MATCH($A$2,$E$121:$BO$121,0))&" ---> "&INDEX($E$123:$BO$158,MATCH($B22,$D$123:$D$158,0),MATCH($A$1,$E$121:$BO$121,0)),"-") -> - | G22: =IFERROR(INDEX($E$162:$AY$183,MATCH($B22&G$6,$A$162:$A$183,0),MATCH($A$2,$E$160:$AY$160,0))&" ---> "&INDEX($E$162:$AY$183,MATCH($B22&G$6,$A$162:$A$183,0),MATCH($A$1,$E$160:$AY$160,0)),"-") -> - | H22: =IFERROR(INDEX($E$162:$AY$183,MATCH($B22&H$6,$A$162:$A$183,0),MATCH($A$2,$E$160:$AY$160,0))&" ---> "&INDEX($E$162:$AY$183,MATCH($B22&H$6,$A$162:$A$183,0),MATCH($A$1,$E$160:$AY$160,0)),"-") -> - | I22: =IFERROR(INDEX($E$188:$BK$215,MATCH($B22&I$6,$A$188:$A$215,0),MATCH($A$2,$E$186:$BK$186,0))&" ---> "&INDEX($E$188:$BK$215,MATCH($B22&I$6,$A$188:$A$215,0),MATCH($A$1,$E$186:$BK$186,0)),"-") -> - | J22: =IFERROR(INDEX($E$188:$BK$215,MATCH($B22&J$6,$A$188:$A$215,0),MATCH($A$2,$E$186:$BK$186,0))&" ---> "&INDEX($E$188:$BK$215,MATCH($B22&J$6,$A$188:$A$215,0),MATCH($A$1,$E$186:$BK$186,0)),"-") -> - | K22: =IFERROR(INDEX($E$219:$BD$231,MATCH($B22&K$6,$A$219:$A$231,0),MATCH($A$2,$E$217:$BD$217,0))&" ---> "&INDEX($E$219:$BD$231,MATCH($B22&K$6,$A$219:$A$231,0),MATCH($A$1,$E$217:$BD$217,0)),"-") -> - | L22: =IFERROR(INDEX($E$219:$BD$231,MATCH($B22&L$6,$A$219:$A$231,0),MATCH($A$2,$E$217:$BD$217,0))&" ---> "&INDEX($E$219:$BD$231,MATCH($B22&L$6,$A$219:$A$231,0),MATCH($A$1,$E$217:$BD$217,0)),"-") -> - | M22: =IFERROR(INDEX($E$235:$AY$251,MATCH($B22,$D$235:$D$251,0),MATCH($A$2,$E$233:$AY$233,0))&" ---> "&INDEX($E$235:$AY$251,MATCH($B22,$D$234:$D$251,0),MATCH($A$1,$E$233:$AY$233,0)),"-") -> -
B23: =IFERROR(__xludf.DUMMYFUNCTION("""COMPUTED_VALUE"""),"Vasos de cartón ") -> Vasos de cartón | C23: =IFERROR(INDEX($E$70:$BW$85,MATCH($B23,$D$70:$D$85,0),MATCH($A$2,$E$68:$BW$68,0))&" ---> "&INDEX($E$70:$BW$85,MATCH($B23,$D$70:$D$85,0),MATCH($A$1,$E$68:$BW$68,0)),"-") -> - | D23: =IFERROR(INDEX($E$89:$BQ$103,MATCH($B23,$D$89:$D$103,0),MATCH($A$2,$E$87:$BQ$87,0))&" ---> "&INDEX($E$89:$BQ$103,MATCH($B23,$D$89:$D$103,0),MATCH($A$1,$E$87:$BQ$87,0)),"-") -> - | E23: =IFERROR(INDEX($E$106:$BK$119,MATCH($B23,$D$106:$D$119,0),MATCH($A$2,$E$104:$BK$104,0))&" ---> "&INDEX($E$106:$BK$119,MATCH($B23,$D$106:$D$119,0),MATCH($A$1,$E$104:$BK$104,0)),"-") -> 3 paquetes ---> sin stock | F23: =IFERROR(INDEX($E$123:$BO$158,MATCH($B23,$D$123:$D$158,0),MATCH($A$2,$E$121:$BO$121,0))&" ---> "&INDEX($E$123:$BO$158,MATCH($B23,$D$123:$D$158,0),MATCH($A$1,$E$121:$BO$121,0)),"-") -> - | G23: =IFERROR(INDEX($E$162:$AY$183,MATCH($B23&G$6,$A$162:$A$183,0),MATCH($A$2,$E$160:$AY$160,0))&" ---> "&INDEX($E$162:$AY$183,MATCH($B23&G$6,$A$162:$A$183,0),MATCH($A$1,$E$160:$AY$160,0)),"-") -> - | H23: =IFERROR(INDEX($E$162:$AY$183,MATCH($B23&H$6,$A$162:$A$183,0),MATCH($A$2,$E$160:$AY$160,0))&" ---> "&INDEX($E$162:$AY$183,MATCH($B23&H$6,$A$162:$A$183,0),MATCH($A$1,$E$160:$AY$160,0)),"-") -> - | I23: =IFERROR(INDEX($E$188:$BK$215,MATCH($B23&I$6,$A$188:$A$215,0),MATCH($A$2,$E$186:$BK$186,0))&" ---> "&INDEX($E$188:$BK$215,MATCH($B23&I$6,$A$188:$A$215,0),MATCH($A$1,$E$186:$BK$186,0)),"-") -> - | J23: =IFERROR(INDEX($E$188:$BK$215,MATCH($B23&J$6,$A$188:$A$215,0),MATCH($A$2,$E$186:$BK$186,0))&" ---> "&INDEX($E$188:$BK$215,MATCH($B23&J$6,$A$188:$A$215,0),MATCH($A$1,$E$186:$BK$186,0)),"-") -> - | K23: =IFERROR(INDEX($E$219:$BD$231,MATCH($B23&K$6,$A$219:$A$231,0),MATCH($A$2,$E$217:$BD$217,0))&" ---> "&INDEX($E$219:$BD$231,MATCH($B23&K$6,$A$219:$A$231,0),MATCH($A$1,$E$217:$BD$217,0)),"-") -> - | L23: =IFERROR(INDEX($E$219:$BD$231,MATCH($B23&L$6,$A$219:$A$231,0),MATCH($A$2,$E$217:$BD$217,0))&" ---> "&INDEX($E$219:$BD$231,MATCH($B23&L$6,$A$219:$A$231,0),MATCH($A$1,$E$217:$BD$217,0)),"-") -> - | M23: =IFERROR(INDEX($E$235:$AY$251,MATCH($B23,$D$235:$D$251,0),MATCH($A$2,$E$233:$AY$233,0))&" ---> "&INDEX($E$235:$AY$251,MATCH($B23,$D$234:$D$251,0),MATCH($A$1,$E$233:$AY$233,0)),"-") -> -
B24: =IFERROR(__xludf.DUMMYFUNCTION("""COMPUTED_VALUE"""),"Aceite de oliva ") -> Aceite de oliva | C24: =IFERROR(INDEX($E$70:$BW$85,MATCH($B24,$D$70:$D$85,0),MATCH($A$2,$E$68:$BW$68,0))&" ---> "&INDEX($E$70:$BW$85,MATCH($B24,$D$70:$D$85,0),MATCH($A$1,$E$68:$BW$68,0)),"-") -> - | D24: =IFERROR(INDEX($E$89:$BQ$103,MATCH($B24,$D$89:$D$103,0),MATCH($A$2,$E$87:$BQ$87,0))&" ---> "&INDEX($E$89:$BQ$103,MATCH($B24,$D$89:$D$103,0),MATCH($A$1,$E$87:$BQ$87,0)),"-") -> - | E24: =IFERROR(INDEX($E$106:$BK$119,MATCH($B24,$D$106:$D$119,0),MATCH($A$2,$E$104:$BK$104,0))&" ---> "&INDEX($E$106:$BK$119,MATCH($B24,$D$106:$D$119,0),MATCH($A$1,$E$104:$BK$104,0)),"-") -> 3 unidades ---> 2 unidades | F24: =IFERROR(INDEX($E$123:$BO$158,MATCH($B24,$D$123:$D$158,0),MATCH($A$2,$E$121:$BO$121,0))&" ---> "&INDEX($E$123:$BO$158,MATCH($B24,$D$123:$D$158,0),MATCH($A$1,$E$121:$BO$121,0)),"-") -> - | G24: =IFERROR(INDEX($E$162:$AY$183,MATCH($B24&G$6,$A$162:$A$183,0),MATCH($A$2,$E$160:$AY$160,0))&" ---> "&INDEX($E$162:$AY$183,MATCH($B24&G$6,$A$162:$A$183,0),MATCH($A$1,$E$160:$AY$160,0)),"-") -> - | H24: =IFERROR(INDEX($E$162:$AY$183,MATCH($B24&H$6,$A$162:$A$183,0),MATCH($A$2,$E$160:$AY$160,0))&" ---> "&INDEX($E$162:$AY$183,MATCH($B24&H$6,$A$162:$A$183,0),MATCH($A$1,$E$160:$AY$160,0)),"-") -> - | I24: =IFERROR(INDEX($E$188:$BK$215,MATCH($B24&I$6,$A$188:$A$215,0),MATCH($A$2,$E$186:$BK$186,0))&" ---> "&INDEX($E$188:$BK$215,MATCH($B24&I$6,$A$188:$A$215,0),MATCH($A$1,$E$186:$BK$186,0)),"-") -> - | J24: =IFERROR(INDEX($E$188:$BK$215,MATCH($B24&J$6,$A$188:$A$215,0),MATCH($A$2,$E$186:$BK$186,0))&" ---> "&INDEX($E$188:$BK$215,MATCH($B24&J$6,$A$188:$A$215,0),MATCH($A$1,$E$186:$BK$186,0)),"-") -> - | K24: =IFERROR(INDEX($E$219:$BD$231,MATCH($B24&K$6,$A$219:$A$231,0),MATCH($A$2,$E$217:$BD$217,0))&" ---> "&INDEX($E$219:$BD$231,MATCH($B24&K$6,$A$219:$A$231,0),MATCH($A$1,$E$217:$BD$217,0)),"-") -> - | L24: =IFERROR(INDEX($E$219:$BD$231,MATCH($B24&L$6,$A$219:$A$231,0),MATCH($A$2,$E$217:$BD$217,0))&" ---> "&INDEX($E$219:$BD$231,MATCH($B24&L$6,$A$219:$A$231,0),MATCH($A$1,$E$217:$BD$217,0)),"-") -> - | M24: =IFERROR(INDEX($E$235:$AY$251,MATCH($B24,$D$235:$D$251,0),MATCH($A$2,$E$233:$AY$233,0))&" ---> "&INDEX($E$235:$AY$251,MATCH($B24,$D$234:$D$251,0),MATCH($A$1,$E$233:$AY$233,0)),"-") -> -
B25: =IFERROR(__xludf.DUMMYFUNCTION("""COMPUTED_VALUE"""),"Bolsas Basura ") -> Bolsas Basura | C25: =IFERROR(INDEX($E$70:$BW$85,MATCH($B25,$D$70:$D$85,0),MATCH($A$2,$E$68:$BW$68,0))&" ---> "&INDEX($E$70:$BW$85,MATCH($B25,$D$70:$D$85,0),MATCH($A$1,$E$68:$BW$68,0)),"-") -> - | D25: =IFERROR(INDEX($E$89:$BQ$103,MATCH($B25,$D$89:$D$103,0),MATCH($A$2,$E$87:$BQ$87,0))&" ---> "&INDEX($E$89:$BQ$103,MATCH($B25,$D$89:$D$103,0),MATCH($A$1,$E$87:$BQ$87,0)),"-") -> - | E25: =IFERROR(INDEX($E$106:$BK$119,MATCH($B25,$D$106:$D$119,0),MATCH($A$2,$E$104:$BK$104,0))&" ---> "&INDEX($E$106:$BK$119,MATCH($B25,$D$106:$D$119,0),MATCH($A$1,$E$104:$BK$104,0)),"-") -> 6 paquetes pequeñas, 7 paquetes medianas, 7 paquetes grandes. ---> 6 paquetes pequeñas, 7 paquetes medianas, 7 paquetes grandes. | F25: =IFERROR(INDEX($E$123:$BO$158,MATCH($B25,$D$123:$D$158,0),MATCH($A$2,$E$121:$BO$121,0))&" ---> "&INDEX($E$123:$BO$158,MATCH($B25,$D$123:$D$158,0),MATCH($A$1,$E$121:$BO$121,0)),"-") -> - | G25: =IFERROR(INDEX($E$162:$AY$183,MATCH($B25&G$6,$A$162:$A$183,0),MATCH($A$2,$E$160:$AY$160,0))&" ---> "&INDEX($E$162:$AY$183,MATCH($B25&G$6,$A$162:$A$183,0),MATCH($A$1,$E$160:$AY$160,0)),"-") -> - | H25: =IFERROR(INDEX($E$162:$AY$183,MATCH($B25&H$6,$A$162:$A$183,0),MATCH($A$2,$E$160:$AY$160,0))&" ---> "&INDEX($E$162:$AY$183,MATCH($B25&H$6,$A$162:$A$183,0),MATCH($A$1,$E$160:$AY$160,0)),"-") -> - | I25: =IFERROR(INDEX($E$188:$BK$215,MATCH($B25&I$6,$A$188:$A$215,0),MATCH($A$2,$E$186:$BK$186,0))&" ---> "&INDEX($E$188:$BK$215,MATCH($B25&I$6,$A$188:$A$215,0),MATCH($A$1,$E$186:$BK$186,0)),"-") -> - | J25: =IFERROR(INDEX($E$188:$BK$215,MATCH($B25&J$6,$A$188:$A$215,0),MATCH($A$2,$E$186:$BK$186,0))&" ---> "&INDEX($E$188:$BK$215,MATCH($B25&J$6,$A$188:$A$215,0),MATCH($A$1,$E$186:$BK$186,0)),"-") -> - | K25: =IFERROR(INDEX($E$219:$BD$231,MATCH($B25&K$6,$A$219:$A$231,0),MATCH($A$2,$E$217:$BD$217,0))&" ---> "&INDEX($E$219:$BD$231,MATCH($B25&K$6,$A$219:$A$231,0),MATCH($A$1,$E$217:$BD$217,0)),"-") -> - | L25: =IFERROR(INDEX($E$219:$BD$231,MATCH($B25&L$6,$A$219:$A$231,0),MATCH($A$2,$E$217:$BD$217,0))&" ---> "&INDEX($E$219:$BD$231,MATCH($B25&L$6,$A$219:$A$231,0),MATCH($A$1,$E$217:$BD$217,0)),"-") -> - | M25: =IFERROR(INDEX($E$235:$AY$251,MATCH($B25,$D$235:$D$251,0),MATCH($A$2,$E$233:$AY$233,0))&" ---> "&INDEX($E$235:$AY$251,MATCH($B25,$D$234:$D$251,0),MATCH($A$1,$E$233:$AY$233,0)),"-") -> -
B26: =IFERROR(__xludf.DUMMYFUNCTION("""COMPUTED_VALUE"""),"Papel interfoliado") -> Papel interfoliado | C26: =IFERROR(INDEX($E$70:$BW$85,MATCH($B26,$D$70:$D$85,0),MATCH($A$2,$E$68:$BW$68,0))&" ---> "&INDEX($E$70:$BW$85,MATCH($B26,$D$70:$D$85,0),MATCH($A$1,$E$68:$BW$68,0)),"-") -> - | D26: =IFERROR(INDEX($E$89:$BQ$103,MATCH($B26,$D$89:$D$103,0),MATCH($A$2,$E$87:$BQ$87,0))&" ---> "&INDEX($E$89:$BQ$103,MATCH($B26,$D$89:$D$103,0),MATCH($A$1,$E$87:$BQ$87,0)),"-") -> - | E26: =IFERROR(INDEX($E$106:$BK$119,MATCH($B26,$D$106:$D$119,0),MATCH($A$2,$E$104:$BK$104,0))&" ---> "&INDEX($E$106:$BK$119,MATCH($B26,$D$106:$D$119,0),MATCH($A$1,$E$104:$BK$104,0)),"-") -> sin stock ---> sin stock | F26: =IFERROR(INDEX($E$123:$BO$158,MATCH($B26,$D$123:$D$158,0),MATCH($A$2,$E$121:$BO$121,0))&" ---> "&INDEX($E$123:$BO$158,MATCH($B26,$D$123:$D$158,0),MATCH($A$1,$E$121:$BO$121,0)),"-") -> - | G26: =IFERROR(INDEX($E$162:$AY$183,MATCH($B26&G$6,$A$162:$A$183,0),MATCH($A$2,$E$160:$AY$160,0))&" ---> "&INDEX($E$162:$AY$183,MATCH($B26&G$6,$A$162:$A$183,0),MATCH($A$1,$E$160:$AY$160,0)),"-") -> - | H26: =IFERROR(INDEX($E$162:$AY$183,MATCH($B26&H$6,$A$162:$A$183,0),MATCH($A$2,$E$160:$AY$160,0))&" ---> "&INDEX($E$162:$AY$183,MATCH($B26&H$6,$A$162:$A$183,0),MATCH($A$1,$E$160:$AY$160,0)),"-") -> - | I26: =IFERROR(INDEX($E$188:$BK$215,MATCH($B26&I$6,$A$188:$A$215,0),MATCH($A$2,$E$186:$BK$186,0))&" ---> "&INDEX($E$188:$BK$215,MATCH($B26&I$6,$A$188:$A$215,0),MATCH($A$1,$E$186:$BK$186,0)),"-") -> - | J26: =IFERROR(INDEX($E$188:$BK$215,MATCH($B26&J$6,$A$188:$A$215,0),MATCH($A$2,$E$186:$BK$186,0))&" ---> "&INDEX($E$188:$BK$215,MATCH($B26&J$6,$A$188:$A$215,0),MATCH($A$1,$E$186:$BK$186,0)),"-") -> - | K26: =IFERROR(INDEX($E$219:$BD$231,MATCH($B26&K$6,$A$219:$A$231,0),MATCH($A$2,$E$217:$BD$217,0))&" ---> "&INDEX($E$219:$BD$231,MATCH($B26&K$6,$A$219:$A$231,0),MATCH($A$1,$E$217:$BD$217,0)),"-") -> - | L26: =IFERROR(INDEX($E$219:$BD$231,MATCH($B26&L$6,$A$219:$A$231,0),MATCH($A$2,$E$217:$BD$217,0))&" ---> "&INDEX($E$219:$BD$231,MATCH($B26&L$6,$A$219:$A$231,0),MATCH($A$1,$E$217:$BD$217,0)),"-") -> - | M26: =IFERROR(INDEX($E$235:$AY$251,MATCH($B26,$D$235:$D$251,0),MATCH($A$2,$E$233:$AY$233,0))&" ---> "&INDEX($E$235:$AY$251,MATCH($B26,$D$234:$D$251,0),MATCH($A$1,$E$233:$AY$233,0)),"-") -> -
B27: =IFERROR(__xludf.DUMMYFUNCTION("""COMPUTED_VALUE"""),"Café soluble") -> Café soluble | C27: =IFERROR(INDEX($E$70:$BW$85,MATCH($B27,$D$70:$D$85,0),MATCH($A$2,$E$68:$BW$68,0))&" ---> "&INDEX($E$70:$BW$85,MATCH($B27,$D$70:$D$85,0),MATCH($A$1,$E$68:$BW$68,0)),"-") -> - | D27: =IFERROR(INDEX($E$89:$BQ$103,MATCH($B27,$D$89:$D$103,0),MATCH($A$2,$E$87:$BQ$87,0))&" ---> "&INDEX($E$89:$BQ$103,MATCH($B27,$D$89:$D$103,0),MATCH($A$1,$E$87:$BQ$87,0)),"-") -> - | E27: =IFERROR(INDEX($E$106:$BK$119,MATCH($B27,$D$106:$D$119,0),MATCH($A$2,$E$104:$BK$104,0))&" ---> "&INDEX($E$106:$BK$119,MATCH($B27,$D$106:$D$119,0),MATCH($A$1,$E$104:$BK$104,0)),"-") -> - | F27: =IFERROR(INDEX($E$123:$BO$158,MATCH($B27,$D$123:$D$158,0),MATCH($A$2,$E$121:$BO$121,0))&" ---> "&INDEX($E$123:$BO$158,MATCH($B27,$D$123:$D$158,0),MATCH($A$1,$E$121:$BO$121,0)),"-") -> 2 ---> 2 | G27: =IFERROR(INDEX($E$162:$AY$183,MATCH($B27&G$6,$A$162:$A$183,0),MATCH($A$2,$E$160:$AY$160,0))&" ---> "&INDEX($E$162:$AY$183,MATCH($B27&G$6,$A$162:$A$183,0),MATCH($A$1,$E$160:$AY$160,0)),"-") -> - | H27: =IFERROR(INDEX($E$162:$AY$183,MATCH($B27&H$6,$A$162:$A$183,0),MATCH($A$2,$E$160:$AY$160,0))&" ---> "&INDEX($E$162:$AY$183,MATCH($B27&H$6,$A$162:$A$183,0),MATCH($A$1,$E$160:$AY$160,0)),"-") -> - | I27: =IFERROR(INDEX($E$188:$BK$215,MATCH($B27&I$6,$A$188:$A$215,0),MATCH($A$2,$E$186:$BK$186,0))&" ---> "&INDEX($E$188:$BK$215,MATCH($B27&I$6,$A$188:$A$215,0),MATCH($A$1,$E$186:$BK$186,0)),"-") -> - | J27: =IFERROR(INDEX($E$188:$BK$215,MATCH($B27&J$6,$A$188:$A$215,0),MATCH($A$2,$E$186:$BK$186,0))&" ---> "&INDEX($E$188:$BK$215,MATCH($B27&J$6,$A$188:$A$215,0),MATCH($A$1,$E$186:$BK$186,0)),"-") -> - | K27: =IFERROR(INDEX($E$219:$BD$231,MATCH($B27&K$6,$A$219:$A$231,0),MATCH($A$2,$E$217:$BD$217,0))&" ---> "&INDEX($E$219:$BD$231,MATCH($B27&K$6,$A$219:$A$231,0),MATCH($A$1,$E$217:$BD$217,0)),"-") -> - | L27: =IFERROR(INDEX($E$219:$BD$231,MATCH($B27&L$6,$A$219:$A$231,0),MATCH($A$2,$E$217:$BD$217,0))&" ---> "&INDEX($E$219:$BD$231,MATCH($B27&L$6,$A$219:$A$231,0),MATCH($A$1,$E$217:$BD$217,0)),"-") -> - | M27: =IFERROR(INDEX($E$235:$AY$251,MATCH($B27,$D$235:$D$251,0),MATCH($A$2,$E$233:$AY$233,0))&" ---> "&INDEX($E$235:$AY$251,MATCH($B27,$D$234:$D$251,0),MATCH($A$1,$E$233:$AY$233,0)),"-") -> -
B28: =IFERROR(__xludf.DUMMYFUNCTION("""COMPUTED_VALUE"""),"Té Negro") -> Té Negro | C28: =IFERROR(INDEX($E$70:$BW$85,MATCH($B28,$D$70:$D$85,0),MATCH($A$2,$E$68:$BW$68,0))&" ---> "&INDEX($E$70:$BW$85,MATCH($B28,$D$70:$D$85,0),MATCH($A$1,$E$68:$BW$68,0)),"-") -> - | D28: =IFERROR(INDEX($E$89:$BQ$103,MATCH($B28,$D$89:$D$103,0),MATCH($A$2,$E$87:$BQ$87,0))&" ---> "&INDEX($E$89:$BQ$103,MATCH($B28,$D$89:$D$103,0),MATCH($A$1,$E$87:$BQ$87,0)),"-") -> - | E28: =IFERROR(INDEX($E$106:$BK$119,MATCH($B28,$D$106:$D$119,0),MATCH($A$2,$E$104:$BK$104,0))&" ---> "&INDEX($E$106:$BK$119,MATCH($B28,$D$106:$D$119,0),MATCH($A$1,$E$104:$BK$104,0)),"-") -> - | F28: =IFERROR(INDEX($E$123:$BO$158,MATCH($B28,$D$123:$D$158,0),MATCH($A$2,$E$121:$BO$121,0))&" ---> "&INDEX($E$123:$BO$158,MATCH($B28,$D$123:$D$158,0),MATCH($A$1,$E$121:$BO$121,0)),"-") -> 4 ---> 4 | G28: =IFERROR(INDEX($E$162:$AY$183,MATCH($B28&G$6,$A$162:$A$183,0),MATCH($A$2,$E$160:$AY$160,0))&" ---> "&INDEX($E$162:$AY$183,MATCH($B28&G$6,$A$162:$A$183,0),MATCH($A$1,$E$160:$AY$160,0)),"-") -> - | H28: =IFERROR(INDEX($E$162:$AY$183,MATCH($B28&H$6,$A$162:$A$183,0),MATCH($A$2,$E$160:$AY$160,0))&" ---> "&INDEX($E$162:$AY$183,MATCH($B28&H$6,$A$162:$A$183,0),MATCH($A$1,$E$160:$AY$160,0)),"-") -> - | I28: =IFERROR(INDEX($E$188:$BK$215,MATCH($B28&I$6,$A$188:$A$215,0),MATCH($A$2,$E$186:$BK$186,0))&" ---> "&INDEX($E$188:$BK$215,MATCH($B28&I$6,$A$188:$A$215,0),MATCH($A$1,$E$186:$BK$186,0)),"-") -> - | J28: =IFERROR(INDEX($E$188:$BK$215,MATCH($B28&J$6,$A$188:$A$215,0),MATCH($A$2,$E$186:$BK$186,0))&" ---> "&INDEX($E$188:$BK$215,MATCH($B28&J$6,$A$188:$A$215,0),MATCH($A$1,$E$186:$BK$186,0)),"-") -> - | K28: =IFERROR(INDEX($E$219:$BD$231,MATCH($B28&K$6,$A$219:$A$231,0),MATCH($A$2,$E$217:$BD$217,0))&" ---> "&INDEX($E$219:$BD$231,MATCH($B28&K$6,$A$219:$A$231,0),MATCH($A$1,$E$217:$BD$217,0)),"-") -> - | L28: =IFERROR(INDEX($E$219:$BD$231,MATCH($B28&L$6,$A$219:$A$231,0),MATCH($A$2,$E$217:$BD$217,0))&" ---> "&INDEX($E$219:$BD$231,MATCH($B28&L$6,$A$219:$A$231,0),MATCH($A$1,$E$217:$BD$217,0)),"-") -> - | M28: =IFERROR(INDEX($E$235:$AY$251,MATCH($B28,$D$235:$D$251,0),MATCH($A$2,$E$233:$AY$233,0))&" ---> "&INDEX($E$235:$AY$251,MATCH($B28,$D$234:$D$251,0),MATCH($A$1,$E$233:$AY$233,0)),"-") -> -
B29: =IFERROR(__xludf.DUMMYFUNCTION("""COMPUTED_VALUE"""),"Té Premium") -> Té Premium | C29: =IFERROR(INDEX($E$70:$BW$85,MATCH($B29,$D$70:$D$85,0),MATCH($A$2,$E$68:$BW$68,0))&" ---> "&INDEX($E$70:$BW$85,MATCH($B29,$D$70:$D$85,0),MATCH($A$1,$E$68:$BW$68,0)),"-") -> - | D29: =IFERROR(INDEX($E$89:$BQ$103,MATCH($B29,$D$89:$D$103,0),MATCH($A$2,$E$87:$BQ$87,0))&" ---> "&INDEX($E$89:$BQ$103,MATCH($B29,$D$89:$D$103,0),MATCH($A$1,$E$87:$BQ$87,0)),"-") -> - | E29: =IFERROR(INDEX($E$106:$BK$119,MATCH($B29,$D$106:$D$119,0),MATCH($A$2,$E$104:$BK$104,0))&" ---> "&INDEX($E$106:$BK$119,MATCH($B29,$D$106:$D$119,0),MATCH($A$1,$E$104:$BK$104,0)),"-") -> - | F29: =IFERROR(INDEX($E$123:$BO$158,MATCH($B29,$D$123:$D$158,0),MATCH($A$2,$E$121:$BO$121,0))&" ---> "&INDEX($E$123:$BO$158,MATCH($B29,$D$123:$D$158,0),MATCH($A$1,$E$121:$BO$121,0)),"-") -> 2 ---> 2 | G29: =IFERROR(INDEX($E$162:$AY$183,MATCH($B29&G$6,$A$162:$A$183,0),MATCH($A$2,$E$160:$AY$160,0))&" ---> "&INDEX($E$162:$AY$183,MATCH($B29&G$6,$A$162:$A$183,0),MATCH($A$1,$E$160:$AY$160,0)),"-") -> - | H29: =IFERROR(INDEX($E$162:$AY$183,MATCH($B29&H$6,$A$162:$A$183,0),MATCH($A$2,$E$160:$AY$160,0))&" ---> "&INDEX($E$162:$AY$183,MATCH($B29&H$6,$A$162:$A$183,0),MATCH($A$1,$E$160:$AY$160,0)),"-") -> - | I29: =IFERROR(INDEX($E$188:$BK$215,MATCH($B29&I$6,$A$188:$A$215,0),MATCH($A$2,$E$186:$BK$186,0))&" ---> "&INDEX($E$188:$BK$215,MATCH($B29&I$6,$A$188:$A$215,0),MATCH($A$1,$E$186:$BK$186,0)),"-") -> - | J29: =IFERROR(INDEX($E$188:$BK$215,MATCH($B29&J$6,$A$188:$A$215,0),MATCH($A$2,$E$186:$BK$186,0))&" ---> "&INDEX($E$188:$BK$215,MATCH($B29&J$6,$A$188:$A$215,0),MATCH($A$1,$E$186:$BK$186,0)),"-") -> - | K29: =IFERROR(INDEX($E$219:$BD$231,MATCH($B29&K$6,$A$219:$A$231,0),MATCH($A$2,$E$217:$BD$217,0))&" ---> "&INDEX($E$219:$BD$231,MATCH($B29&K$6,$A$219:$A$231,0),MATCH($A$1,$E$217:$BD$217,0)),"-") -> - | L29: =IFERROR(INDEX($E$219:$BD$231,MATCH($B29&L$6,$A$219:$A$231,0),MATCH($A$2,$E$217:$BD$217,0))&" ---> "&INDEX($E$219:$BD$231,MATCH($B29&L$6,$A$219:$A$231,0),MATCH($A$1,$E$217:$BD$217,0)),"-") -> - | M29: =IFERROR(INDEX($E$235:$AY$251,MATCH($B29,$D$235:$D$251,0),MATCH($A$2,$E$233:$AY$233,0))&" ---> "&INDEX($E$235:$AY$251,MATCH($B29,$D$234:$D$251,0),MATCH($A$1,$E$233:$AY$233,0)),"-") -> -
B30: =IFERROR(__xludf.DUMMYFUNCTION("""COMPUTED_VALUE"""),"Supremo de Hierbas") -> Supremo de Hierbas | C30: =IFERROR(INDEX($E$70:$BW$85,MATCH($B30,$D$70:$D$85,0),MATCH($A$2,$E$68:$BW$68,0))&" ---> "&INDEX($E$70:$BW$85,MATCH($B30,$D$70:$D$85,0),MATCH($A$1,$E$68:$BW$68,0)),"-") -> - | D30: =IFERROR(INDEX($E$89:$BQ$103,MATCH($B30,$D$89:$D$103,0),MATCH($A$2,$E$87:$BQ$87,0))&" ---> "&INDEX($E$89:$BQ$103,MATCH($B30,$D$89:$D$103,0),MATCH($A$1,$E$87:$BQ$87,0)),"-") -> - | E30: =IFERROR(INDEX($E$106:$BK$119,MATCH($B30,$D$106:$D$119,0),MATCH($A$2,$E$104:$BK$104,0))&" ---> "&INDEX($E$106:$BK$119,MATCH($B30,$D$106:$D$119,0),MATCH($A$1,$E$104:$BK$104,0)),"-") -> - | F30: =IFERROR(INDEX($E$123:$BO$158,MATCH($B30,$D$123:$D$158,0),MATCH($A$2,$E$121:$BO$121,0))&" ---> "&INDEX($E$123:$BO$158,MATCH($B30,$D$123:$D$158,0),MATCH($A$1,$E$121:$BO$121,0)),"-") -> 3 ---> 3 | G30: =IFERROR(INDEX($E$162:$AY$183,MATCH($B30&G$6,$A$162:$A$183,0),MATCH($A$2,$E$160:$AY$160,0))&" ---> "&INDEX($E$162:$AY$183,MATCH($B30&G$6,$A$162:$A$183,0),MATCH($A$1,$E$160:$AY$160,0)),"-") -> - | H30: =IFERROR(INDEX($E$162:$AY$183,MATCH($B30&H$6,$A$162:$A$183,0),MATCH($A$2,$E$160:$AY$160,0))&" ---> "&INDEX($E$162:$AY$183,MATCH($B30&H$6,$A$162:$A$183,0),MATCH($A$1,$E$160:$AY$160,0)),"-") -> - | I30: =IFERROR(INDEX($E$188:$BK$215,MATCH($B30&I$6,$A$188:$A$215,0),MATCH($A$2,$E$186:$BK$186,0))&" ---> "&INDEX($E$188:$BK$215,MATCH($B30&I$6,$A$188:$A$215,0),MATCH($A$1,$E$186:$BK$186,0)),"-") -> - | J30: =IFERROR(INDEX($E$188:$BK$215,MATCH($B30&J$6,$A$188:$A$215,0),MATCH($A$2,$E$186:$BK$186,0))&" ---> "&INDEX($E$188:$BK$215,MATCH($B30&J$6,$A$188:$A$215,0),MATCH($A$1,$E$186:$BK$186,0)),"-") -> - | K30: =IFERROR(INDEX($E$219:$BD$231,MATCH($B30&K$6,$A$219:$A$231,0),MATCH($A$2,$E$217:$BD$217,0))&" ---> "&INDEX($E$219:$BD$231,MATCH($B30&K$6,$A$219:$A$231,0),MATCH($A$1,$E$217:$BD$217,0)),"-") -> - | L30: =IFERROR(INDEX($E$219:$BD$231,MATCH($B30&L$6,$A$219:$A$231,0),MATCH($A$2,$E$217:$BD$217,0))&" ---> "&INDEX($E$219:$BD$231,MATCH($B30&L$6,$A$219:$A$231,0),MATCH($A$1,$E$217:$BD$217,0)),"-") -> - | M30: =IFERROR(INDEX($E$235:$AY$251,MATCH($B30,$D$235:$D$251,0),MATCH($A$2,$E$233:$AY$233,0))&" ---> "&INDEX($E$235:$AY$251,MATCH($B30,$D$234:$D$251,0),MATCH($A$1,$E$233:$AY$233,0)),"-") -> -
B31: =IFERROR(__xludf.DUMMYFUNCTION("""COMPUTED_VALUE"""),"Azucar") -> Azucar | C31: =IFERROR(INDEX($E$70:$BW$85,MATCH($B31,$D$70:$D$85,0),MATCH($A$2,$E$68:$BW$68,0))&" ---> "&INDEX($E$70:$BW$85,MATCH($B31,$D$70:$D$85,0),MATCH($A$1,$E$68:$BW$68,0)),"-") -> - | D31: =IFERROR(INDEX($E$89:$BQ$103,MATCH($B31,$D$89:$D$103,0),MATCH($A$2,$E$87:$BQ$87,0))&" ---> "&INDEX($E$89:$BQ$103,MATCH($B31,$D$89:$D$103,0),MATCH($A$1,$E$87:$BQ$87,0)),"-") -> - | E31: =IFERROR(INDEX($E$106:$BK$119,MATCH($B31,$D$106:$D$119,0),MATCH($A$2,$E$104:$BK$104,0))&" ---> "&INDEX($E$106:$BK$119,MATCH($B31,$D$106:$D$119,0),MATCH($A$1,$E$104:$BK$104,0)),"-") -> - | F31: =IFERROR(INDEX($E$123:$BO$158,MATCH($B31,$D$123:$D$158,0),MATCH($A$2,$E$121:$BO$121,0))&" ---> "&INDEX($E$123:$BO$158,MATCH($B31,$D$123:$D$158,0),MATCH($A$1,$E$121:$BO$121,0)),"-") -> 0 ---> 0 | G31: =IFERROR(INDEX($E$162:$AY$183,MATCH($B31&G$6,$A$162:$A$183,0),MATCH($A$2,$E$160:$AY$160,0))&" ---> "&INDEX($E$162:$AY$183,MATCH($B31&G$6,$A$162:$A$183,0),MATCH($A$1,$E$160:$AY$160,0)),"-") -> - | H31: =IFERROR(INDEX($E$162:$AY$183,MATCH($B31&H$6,$A$162:$A$183,0),MATCH($A$2,$E$160:$AY$160,0))&" ---> "&INDEX($E$162:$AY$183,MATCH($B31&H$6,$A$162:$A$183,0),MATCH($A$1,$E$160:$AY$160,0)),"-") -> - | I31: =IFERROR(INDEX($E$188:$BK$215,MATCH($B31&I$6,$A$188:$A$215,0),MATCH($A$2,$E$186:$BK$186,0))&" ---> "&INDEX($E$188:$BK$215,MATCH($B31&I$6,$A$188:$A$215,0),MATCH($A$1,$E$186:$BK$186,0)),"-") -> - | J31: =IFERROR(INDEX($E$188:$BK$215,MATCH($B31&J$6,$A$188:$A$215,0),MATCH($A$2,$E$186:$BK$186,0))&" ---> "&INDEX($E$188:$BK$215,MATCH($B31&J$6,$A$188:$A$215,0),MATCH($A$1,$E$186:$BK$186,0)),"-") -> - | K31: =IFERROR(INDEX($E$219:$BD$231,MATCH($B31&K$6,$A$219:$A$231,0),MATCH($A$2,$E$217:$BD$217,0))&" ---> "&INDEX($E$219:$BD$231,MATCH($B31&K$6,$A$219:$A$231,0),MATCH($A$1,$E$217:$BD$217,0)),"-") -> - | L31: =IFERROR(INDEX($E$219:$BD$231,MATCH($B31&L$6,$A$219:$A$231,0),MATCH($A$2,$E$217:$BD$217,0))&" ---> "&INDEX($E$219:$BD$231,MATCH($B31&L$6,$A$219:$A$231,0),MATCH($A$1,$E$217:$BD$217,0)),"-") -> - | M31: =IFERROR(INDEX($E$235:$AY$251,MATCH($B31,$D$235:$D$251,0),MATCH($A$2,$E$233:$AY$233,0))&" ---> "&INDEX($E$235:$AY$251,MATCH($B31,$D$234:$D$251,0),MATCH($A$1,$E$233:$AY$233,0)),"-") -> -
