Workbook

Sheet RESUMEN
A1: 46104 | C1: =IFERROR(__xludf.DUMMYFUNCTION("unique(filter($C$81:$C1195,$C$81:$C1195<>""Proveedor"",$B$81:$B1195=C5,$C$81:$C1195<>""""))"),"Coporate Coffe") -> Coporate Coffe | D1: =IFERROR(__xludf.DUMMYFUNCTION("unique(filter($C$81:$C1195,$C$81:$C1195<>""Proveedor"",$B$81:$B1195=D5,$C$81:$C1195<>""""))"),"Cafe Caribe") -> Cafe Caribe | E1: =IFERROR(__xludf.DUMMYFUNCTION("unique(filter($C$81:$C1195,$C$81:$C1195<>""Proveedor"",$B$81:$B1195=E5,$C$81:$C1195<>""""))"),"Cafe Caribe") -> Cafe Caribe | F1: =IFERROR(__xludf.DUMMYFUNCTION("unique(filter($C$81:$C1195,$C$81:$C1195<>""Proveedor"",$B$81:$B1195=F5,$C$81:$C1195<>""""))"),"Coporate Coffe") -> Coporate Coffe | G1: =IFERROR(__xludf.DUMMYFUNCTION("unique(filter($C$81:$C1195,$C$81:$C1195<>""Proveedor"",$B$81:$B1195=G5,$C$81:$C1195<>""""))"),"Cafe Caribe") -> Cafe Caribe | H1: =IFERROR(__xludf.DUMMYFUNCTION("unique(filter($C$81:$C1195,$C$81:$C1195<>""Proveedor"",$B$81:$B1195=H5,$C$81:$C1195<>""""))"),"Cafe Caribe") -> Cafe Caribe | I1: =IFERROR(__xludf.DUMMYFUNCTION("unique(filter($C$81:$C1195,$C$81:$C1195<>""Proveedor"",$B$81:$B1195=I5,$C$81:$C1195<>""""))"),"Cafeteria") -> Cafeteria | J1: =IFERROR(__xludf.DUMMYFUNCTION("unique(filter($C$81:$C1195,$C$81:$C1195<>""Proveedor"",$B$81:$B1195=J5,$C$81:$C1195<>""""))"),"Cafe Caribe") -> Cafe Caribe | K1: =IFERROR(__xludf.DUMMYFUNCTION("unique(filter($C$81:$C1195,$C$81:$C1195<>""Proveedor"",$B$81:$B1195=K5,$C$81:$C1195<>""""))"),"Cafe Caribe") -> Cafe Caribe | L1: =IFERROR(__xludf.DUMMYFUNCTION("unique(filter($C$81:$C1195,$C$81:$C1195<>""Proveedor"",$B$81:$B1195=L5,$C$81:$C1195<>""""))"),"Corporate Coffe") -> Corporate Coffe
A2: 46100 | C2: =IFERROR(__xludf.DUMMYFUNCTION("""COMPUTED_VALUE"""),"Cafeteria") -> Cafeteria | D2: =IFERROR(__xludf.DUMMYFUNCTION("""COMPUTED_VALUE"""),"Cafeteria") -> Cafeteria | E2: =IFERROR(__xludf.DUMMYFUNCTION("""COMPUTED_VALUE"""),"Cafeteria") -> Cafeteria | F2: =IFERROR(__xludf.DUMMYFUNCTION("""COMPUTED_VALUE"""),"Cafeteria") -> Cafeteria | G2: =IFERROR(__xludf.DUMMYFUNCTION("""COMPUTED_VALUE"""),"Cafeteria") -> Cafeteria | H2: =IFERROR(__xludf.DUMMYFUNCTION("""COMPUTED_VALUE"""),"Cafeteria") -> Cafeteria | I2: =IFERROR(__xludf.DUMMYFUNCTION("""COMPUTED_VALUE"""),"Cafe Caribe") -> Cafe Caribe | J2: =IFERROR(__xludf.DUMMYFUNCTION("""COMPUTED_VALUE"""),"Cafeteria") -> Cafeteria | K2: =IFERROR(__xludf.DUMMYFUNCTION("""COMPUTED_VALUE"""),"Cafeteria") -> Cafeteria | L2: =IFERROR(__xludf.DUMMYFUNCTION("""COMPUTED_VALUE"""),"Cafeteria") -> Cafeteria
C3: =IFERROR(__xludf.DUMMYFUNCTION("""COMPUTED_VALUE"""),"Aseo") -> Aseo | D3: =IFERROR(__xludf.DUMMYFUNCTION("""COMPUTED_VALUE"""),"Aseo") -> Aseo | E3: =IFERROR(__xludf.DUMMYFUNCTION("""COMPUTED_VALUE"""),"Aseo") -> Aseo | F3: =IFERROR(__xludf.DUMMYFUNCTION("""COMPUTED_VALUE"""),"Aseo") -> Aseo | G3: =IFERROR(__xludf.DUMMYFUNCTION("""COMPUTED_VALUE"""),"Aseo") -> Aseo | H3: =IFERROR(__xludf.DUMMYFUNCTION("""COMPUTED_VALUE"""),"Cocina") -> Cocina | I3: =IFERROR(__xludf.DUMMYFUNCTION("""COMPUTED_VALUE"""),"Aseo") -> Aseo | J3: =IFERROR(__xludf.DUMMYFUNCTION("""COMPUTED_VALUE"""),"Aseo") -> Aseo | K3: =IFERROR(__xludf.DUMMYFUNCTION("""COMPUTED_VALUE"""),"Aseo") -> Aseo | L3: =IFERROR(__xludf.DUMMYFUNCTION("""COMPUTED_VALUE"""),"Aseo") -> Aseo
H4: =IFERROR(__xludf.DUMMYFUNCTION("""COMPUTED_VALUE"""),"Aseo") -> Aseo
C5: =IFERROR(__xludf.DUMMYFUNCTION("TRANSPOSE(unique(filter(B80:B1195,B80:B1195<>""Sede"",B80:B1195<>"""")))"),"Abedules ") -> Abedules | D5: =IFERROR(__xludf.DUMMYFUNCTION("""COMPUTED_VALUE"""),"Alto el Golf") -> Alto el Golf | E5: =IFERROR(__xludf.DUMMYFUNCTION("""COMPUTED_VALUE"""),"Apoquindo") -> Apoquindo | F5: =IFERROR(__xludf.DUMMYFUNCTION("""COMPUTED_VALUE"""),"Los Militares") -> Los Militares | G5: =IFERROR(__xludf.DUMMYFUNCTION("""COMPUTED_VALUE"""),"Monjitas") -> Monjitas | H5: =IFERROR(__xludf.DUMMYFUNCTION("""COMPUTED_VALUE"""),"Isidora") -> Isidora | I5: =IFERROR(__xludf.DUMMYFUNCTION("""COMPUTED_VALUE"""),"Vespucio") -> Vespucio | J5: =IFERROR(__xludf.DUMMYFUNCTION("""COMPUTED_VALUE"""),"Kennedy") -> Kennedy | K5: =IFERROR(__xludf.DUMMYFUNCTION("""COMPUTED_VALUE"""),"Nueva Las Condes") -> Nueva Las Condes | L5: =IFERROR(__xludf.DUMMYFUNCTION("""COMPUTED_VALUE"""),"Cerro el Plomo") -> Cerro el Plomo
B6: =IFERROR(__xludf.DUMMYFUNCTION("unique(filter(D80:D1195,D80:D1195<>""Producto"",D80:D1195<>""""))"),"Cafe Grano (KG)") -> Cafe Grano (KG) | C6: =IFERROR(INDEX($E$82:$CY$96,MATCH($B6,$D$82:$D$96,0),MATCH($A$2,$E$80:$CY$80,0))&" ---> "&INDEX($E$82:$CY$96,MATCH($B6,$D$82:$D$96,0),MATCH($A$1,$E$80:$CY$80,0)),"-") -> 0 ---> 0 | D6: =IFERROR(INDEX($E$100:$CY$113,MATCH($B6,$D$100:$D$113,0),MATCH($A$2,$E$98:$CY$98,0))&" ---> "&INDEX($E$100:$CY$113,MATCH($B6,$D$100:$D$113,0),MATCH($A$1,$E$98:$CY$98,0)),"-") -> 14 ---> 12 | E6: =IFERROR(INDEX($E$117:$CY$130,MATCH($B6,$D$117:$D$130,0),MATCH($A$2,$E$115:$CY$115,0))&" ---> "&INDEX($E$117:$CY$130,MATCH($B6,$D$117:$D$130,0),MATCH($A$1,$E$115:$CY$115,0)),"-") -> 13,5 kl ---> 11 kl | F6: =IFERROR(INDEX($E$134:$CY$147,MATCH($B6,$D$134:$D$147,0),MATCH($A$2,$E$132:$CY$132,0))&" ---> "&INDEX($E$134:$CY$147,MATCH($B6,$D$134:$D$147,0),MATCH($A$1,$E$132:$CY$132,0)),"-") -> 7 ---> 6 | G6: =IFERROR(INDEX($E$151:$CY$164,MATCH($B6,$D$151:$D$164,0),MATCH($A$2,$E$149:$CY$149,0))&" ---> "&INDEX($E$151:$CY$164,MATCH($B6,$D$151:$D$164,0),MATCH($A$1,$E$149:$CY$149,0)),"-") -> 13,5 kg ---> 11 kg | H6: =IFERROR(INDEX($E$169:$CY$182,MATCH($B6,$D$169:$D$182,0),MATCH($A$2,$E$167:$CY$167,0))&" ---> "&INDEX($E$169:$CY$182,MATCH($B6,$D$169:$D$182,0),MATCH($A$1,$E$167:$CY$167,0)),"-") -> 14.5kg ---> 13 kg | I6: =IFERROR(INDEX($E$186:$CY$224,MATCH($B6,$D$186:$D$224,0),MATCH($A$2,$E$184:$CY$184,0))&" ---> "&INDEX($E$186:$CY$224,MATCH($B6,$D$186:$D$224,0),MATCH($A$1,$E$184:$CY$184,0)),"-") -> 15 1/2 ---> 13 | J6: =IFERROR(INDEX($E$228:$BK$243,MATCH($B6,$D$228:$D$243,0),MATCH($A$2,$E$226:$BK$226,0))&" ---> "&INDEX($E$228:$BK$243,MATCH($B6,$D$228:$D$243,0),MATCH($A$1,$E$226:$BK$226,0)),"-") -> 20 kg ---> 10 Kg | K6: =IFERROR(INDEX($E$246:$CY$260,MATCH($B6,$D$246:$D$260,0),MATCH($A$2,$E$244:$CY$244,0))&" ---> "&INDEX($E$246:$CY$260,MATCH($B6,$D$246:$D$260,0),MATCH($A$1,$E$244:$CY$244,0)),"-") -> 9,5 ---> 8 | L6: {=IFERROR(INDEX($E$268:$CY$302,MATCH($B6,$D$268:$D$302,0),MATCH($A$2,$E$266:$CY$266,0))&" ---> "&INDEX($E$268:$CY$302,MATCH($B6,$D$268:$D$302,0),MATCH($A$1,$E$266:$CY$266,0)),"-")} -> 12 ---> 12
B7: =IFERROR(__xludf.DUMMYFUNCTION("""COMPUTED_VALUE"""),"Toalla de Papel Jumbo (UN)") -> Toalla de Papel Jumbo (UN) | C7: =IFERROR(INDEX($E$82:$CY$96,MATCH($B7,$D$82:$D$96,0),MATCH($A$2,$E$80:$CY$80,0))&" ---> "&INDEX($E$82:$CY$96,MATCH($B7,$D$82:$D$96,0),MATCH($A$1,$E$80:$CY$80,0)),"-") -> 2 ---> 3 | D7: =IFERROR(INDEX($E$100:$CY$113,MATCH($B7,$D$100:$D$113,0),MATCH($A$2,$E$98:$CY$98,0))&" ---> "&INDEX($E$100:$CY$113,MATCH($B7,$D$100:$D$113,0),MATCH($A$1,$E$98:$CY$98,0)),"-") -> 5 ---> 4 | E7: =IFERROR(INDEX($E$117:$CY$130,MATCH($B7,$D$117:$D$130,0),MATCH($A$2,$E$115:$CY$115,0))&" ---> "&INDEX($E$117:$CY$130,MATCH($B7,$D$117:$D$130,0),MATCH($A$1,$E$115:$CY$115,0)),"-") -> 2 und ---> 0 | F7: =IFERROR(INDEX($E$134:$CY$147,MATCH($B7,$D$134:$D$147,0),MATCH($A$2,$E$132:$CY$132,0))&" ---> "&INDEX($E$134:$CY$147,MATCH($B7,$D$134:$D$147,0),MATCH($A$1,$E$132:$CY$132,0)),"-") -> 7 paquetes ---> 4 paquetes | G7: =IFERROR(INDEX($E$151:$CY$164,MATCH($B7,$D$151:$D$164,0),MATCH($A$2,$E$149:$CY$149,0))&" ---> "&INDEX($E$151:$CY$164,MATCH($B7,$D$151:$D$164,0),MATCH($A$1,$E$149:$CY$149,0)),"-") -> 4 und ---> 4 und | H7: =IFERROR(INDEX($E$169:$CY$182,MATCH($B7,$D$169:$D$182,0),MATCH($A$2,$E$167:$CY$167,0))&" ---> "&INDEX($E$169:$CY$182,MATCH($B7,$D$169:$D$182,0),MATCH($A$1,$E$167:$CY$167,0)),"-") -> 8 ---> 7 | I7: =IFERROR(INDEX($E$186:$CY$224,MATCH($B7,$D$186:$D$224,0),MATCH($A$2,$E$184:$CY$184,0))&" ---> "&INDEX($E$186:$CY$224,MATCH($B7,$D$186:$D$224,0),MATCH($A$1,$E$184:$CY$184,0)),"-") -> 13 ---> 4 | J7: =IFERROR(INDEX($E$228:$BK$243,MATCH($B7,$D$228:$D$243,0),MATCH($A$2,$E$226:$BK$226,0))&" ---> "&INDEX($E$228:$BK$243,MATCH($B7,$D$228:$D$243,0),MATCH($A$1,$E$226:$BK$226,0)),"-") -> 4 ---> 30 | K7: =IFERROR(INDEX($E$246:$CY$260,MATCH($B7,$D$246:$D$260,0),MATCH($A$2,$E$244:$CY$244,0))&" ---> "&INDEX($E$246:$CY$260,MATCH($B7,$D$246:$D$260,0),MATCH($A$1,$E$244:$CY$244,0)),"-") -> 3 ---> 1 | L7: =IFERROR(INDEX($E$268:$CY$293,MATCH($B7,$D$268:$D$293,0),MATCH($A$2,$E$266:$CY$266,0))&" ---> "&INDEX($E$268:$CY$293,MATCH($B7,$D$268:$D$293,0),MATCH($A$1,$E$266:$CY$266,0)),"-") -> 0 ---> 0
B8: =IFERROR(__xludf.DUMMYFUNCTION("""COMPUTED_VALUE"""),"Papel Higienico (UN)") -> Papel Higienico (UN) | C8: =IFERROR(INDEX($E$82:$CY$96,MATCH($B8,$D$82:$D$96,0),MATCH($A$2,$E$80:$CY$80,0))&" ---> "&INDEX($E$82:$CY$96,MATCH($B8,$D$82:$D$96,0),MATCH($A$1,$E$80:$CY$80,0)),"-") -> 5 ---> 6 | D8: =IFERROR(INDEX($E$100:$CY$113,MATCH($B8,$D$100:$D$113,0),MATCH($A$2,$E$98:$CY$98,0))&" ---> "&INDEX($E$100:$CY$113,MATCH($B8,$D$100:$D$113,0),MATCH($A$1,$E$98:$CY$98,0)),"-") -> 16 ---> 16 | E8: =IFERROR(INDEX($E$117:$CY$130,MATCH($B8,$D$117:$D$130,0),MATCH($A$2,$E$115:$CY$115,0))&" ---> "&INDEX($E$117:$CY$130,MATCH($B8,$D$117:$D$130,0),MATCH($A$1,$E$115:$CY$115,0)),"-") -> 2 und ---> 0 | F8: =IFERROR(INDEX($E$134:$CY$147,MATCH($B8,$D$134:$D$147,0),MATCH($A$2,$E$132:$CY$132,0))&" ---> "&INDEX($E$134:$CY$147,MATCH($B8,$D$134:$D$147,0),MATCH($A$1,$E$132:$CY$132,0)),"-") -> 7 paquetes ---> 4 paquetes | G8: =IFERROR(INDEX($E$151:$CY$164,MATCH($B8,$D$151:$D$164,0),MATCH($A$2,$E$149:$CY$149,0))&" ---> "&INDEX($E$151:$CY$164,MATCH($B8,$D$151:$D$164,0),MATCH($A$1,$E$149:$CY$149,0)),"-") -> 44 und ---> 40 und | H8: =IFERROR(INDEX($E$169:$CY$182,MATCH($B8,$D$169:$D$182,0),MATCH($A$2,$E$167:$CY$167,0))&" ---> "&INDEX($E$169:$CY$182,MATCH($B8,$D$169:$D$182,0),MATCH($A$1,$E$167:$CY$167,0)),"-") -> 10 ---> 9 | I8: =IFERROR(INDEX($E$186:$CY$224,MATCH($B8,$D$186:$D$224,0),MATCH($A$2,$E$184:$CY$184,0))&" ---> "&INDEX($E$186:$CY$224,MATCH($B8,$D$186:$D$224,0),MATCH($A$1,$E$184:$CY$184,0)),"-") -> 32 ---> 26 | J8: =IFERROR(INDEX($E$228:$BK$243,MATCH($B8,$D$228:$D$243,0),MATCH($A$2,$E$226:$BK$226,0))&" ---> "&INDEX($E$228:$BK$243,MATCH($B8,$D$228:$D$243,0),MATCH($A$1,$E$226:$BK$226,0)),"-") -> 5 ---> 36 | K8: =IFERROR(INDEX($E$246:$CY$260,MATCH($B8,$D$246:$D$260,0),MATCH($A$2,$E$244:$CY$244,0))&" ---> "&INDEX($E$246:$CY$260,MATCH($B8,$D$246:$D$260,0),MATCH($A$1,$E$244:$CY$244,0)),"-") -> 4 ---> 3 | L8: =IFERROR(INDEX($E$268:$CY$293,MATCH($B8,$D$268:$D$293,0),MATCH($A$2,$E$266:$CY$266,0))&" ---> "&INDEX($E$268:$CY$293,MATCH($B8,$D$268:$D$293,0),MATCH($A$1,$E$266:$CY$266,0)),"-") -> 12 ---> 8
B9: =IFERROR(__xludf.DUMMYFUNCTION("""COMPUTED_VALUE"""),"Resma Papel Fotocopia (UN)") -> Resma Papel Fotocopia (UN) | C9: =IFERROR(INDEX($E$82:$CY$96,MATCH($B9,$D$82:$D$96,0),MATCH($A$2,$E$80:$CY$80,0))&" ---> "&INDEX($E$82:$CY$96,MATCH($B9,$D$82:$D$96,0),MATCH($A$1,$E$80:$CY$80,0)),"-") -> 0 ---> 0 | D9: =IFERROR(INDEX($E$100:$CY$113,MATCH($B9,$D$100:$D$113,0),MATCH($A$2,$E$98:$CY$98,0))&" ---> "&INDEX($E$100:$CY$113,MATCH($B9,$D$100:$D$113,0),MATCH($A$1,$E$98:$CY$98,0)),"-") -> 5 ---> 5 | E9: =IFERROR(INDEX($E$117:$CY$130,MATCH($B9,$D$117:$D$130,0),MATCH($A$2,$E$115:$CY$115,0))&" ---> "&INDEX($E$117:$CY$130,MATCH($B9,$D$117:$D$130,0),MATCH($A$1,$E$115:$CY$115,0)),"-") -> 6 ---> 4 | F9: =IFERROR(INDEX($E$134:$CY$147,MATCH($B9,$D$134:$D$147,0),MATCH($A$2,$E$132:$CY$132,0))&" ---> "&INDEX($E$134:$CY$147,MATCH($B9,$D$134:$D$147,0),MATCH($A$1,$E$132:$CY$132,0)),"-") -> 10 resmas ---> 10 resmas | G9: =IFERROR(INDEX($E$151:$CY$164,MATCH($B9,$D$151:$D$164,0),MATCH($A$2,$E$149:$CY$149,0))&" ---> "&INDEX($E$151:$CY$164,MATCH($B9,$D$151:$D$164,0),MATCH($A$1,$E$149:$CY$149,0)),"-") -> 7 ---> 6 und | H9: =IFERROR(INDEX($E$169:$CY$182,MATCH($B9,$D$169:$D$182,0),MATCH($A$2,$E$167:$CY$167,0))&" ---> "&INDEX($E$169:$CY$182,MATCH($B9,$D$169:$D$182,0),MATCH($A$1,$E$167:$CY$167,0)),"-") -> 14 ---> 14 | I9: =IFERROR(INDEX($E$186:$CY$224,MATCH($B9,$D$186:$D$224,0),MATCH($A$2,$E$184:$CY$184,0))&" ---> "&INDEX($E$186:$CY$224,MATCH($B9,$D$186:$D$224,0),MATCH($A$1,$E$184:$CY$184,0)),"-") -> - | J9: =IFERROR(INDEX($E$228:$BK$243,MATCH($B9,$D$228:$D$243,0),MATCH($A$2,$E$226:$BK$226,0))&" ---> "&INDEX($E$228:$BK$243,MATCH($B9,$D$228:$D$243,0),MATCH($A$1,$E$226:$BK$226,0)),"-") -> carta: 4 oficio:29 A3 75: 8 ---> carta: 6 oficio:29 A3 75: 8 | K9: =IFERROR(INDEX($E$246:$CY$260,MATCH($B9,$D$246:$D$260,0),MATCH($A$2,$E$244:$CY$244,0))&" ---> "&INDEX($E$246:$CY$260,MATCH($B9,$D$246:$D$260,0),MATCH($A$1,$E$244:$CY$244,0)),"-") -> 6 ---> 6 | L9: =IFERROR(INDEX($E$268:$CY$293,MATCH($B9,$D$268:$D$293,0),MATCH($A$2,$E$266:$CY$266,0))&" ---> "&INDEX($E$268:$CY$293,MATCH($B9,$D$268:$D$293,0),MATCH($A$1,$E$266:$CY$266,0)),"-") -> 4 ---> 4
B10: =IFERROR(__xludf.DUMMYFUNCTION("""COMPUTED_VALUE"""),"Cafe Granulado") -> Cafe Granulado | C10: =IFERROR(INDEX($E$82:$CY$96,MATCH($B10,$D$82:$D$96,0),MATCH($A$2,$E$80:$CY$80,0))&" ---> "&INDEX($E$82:$CY$96,MATCH($B10,$D$82:$D$96,0),MATCH($A$1,$E$80:$CY$80,0)),"-") -> ---> 0 | D10: =IFERROR(INDEX($E$100:$CY$113,MATCH($B10,$D$100:$D$113,0),MATCH($A$2,$E$98:$CY$98,0))&" ---> "&INDEX($E$100:$CY$113,MATCH($B10,$D$100:$D$113,0),MATCH($A$1,$E$98:$CY$98,0)),"-") -> - | E10: =IFERROR(INDEX($E$117:$CY$130,MATCH($B10,$D$117:$D$130,0),MATCH($A$2,$E$115:$CY$115,0))&" ---> "&INDEX($E$117:$CY$130,MATCH($B10,$D$117:$D$130,0),MATCH($A$1,$E$115:$CY$115,0)),"-") -> - | F10: =IFERROR(INDEX($E$134:$CY$147,MATCH($B10,$D$134:$D$147,0),MATCH($A$2,$E$132:$CY$132,0))&" ---> "&INDEX($E$134:$CY$147,MATCH($B10,$D$134:$D$147,0),MATCH($A$1,$E$132:$CY$132,0)),"-") -> - | G10: =IFERROR(INDEX($E$151:$CY$164,MATCH($B10,$D$151:$D$164,0),MATCH($A$2,$E$149:$CY$149,0))&" ---> "&INDEX($E$151:$CY$164,MATCH($B10,$D$151:$D$164,0),MATCH($A$1,$E$149:$CY$149,0)),"-") -> - | H10: =IFERROR(INDEX($E$169:$CY$182,MATCH($B10,$D$169:$D$182,0),MATCH($A$2,$E$167:$CY$167,0))&" ---> "&INDEX($E$169:$CY$182,MATCH($B10,$D$169:$D$182,0),MATCH($A$1,$E$167:$CY$167,0)),"-") -> ---> | I10: =IFERROR(INDEX($E$186:$CY$224,MATCH($B10,$D$186:$D$224,0),MATCH($A$2,$E$184:$CY$184,0))&" ---> "&INDEX($E$186:$CY$224,MATCH($B10,$D$186:$D$224,0),MATCH($A$1,$E$184:$CY$184,0)),"-") -> 3 ---> 3 | J10: =IFERROR(INDEX($E$228:$BK$243,MATCH($B10,$D$228:$D$243,0),MATCH($A$2,$E$226:$BK$226,0))&" ---> "&INDEX($E$228:$BK$243,MATCH($B10,$D$228:$D$243,0),MATCH($A$1,$E$226:$BK$226,0)),"-") -> - | K10: =IFERROR(INDEX($E$246:$CY$260,MATCH($B10,$D$246:$D$260,0),MATCH($A$2,$E$244:$CY$244,0))&" ---> "&INDEX($E$246:$CY$260,MATCH($B10,$D$246:$D$260,0),MATCH($A$1,$E$244:$CY$244,0)),"-") -> 0 ---> 0 | L10: =IFERROR(INDEX($E$268:$CY$293,MATCH($B10,$D$268:$D$293,0),MATCH($A$2,$E$266:$CY$266,0))&" ---> "&INDEX($E$268:$CY$293,MATCH($B10,$D$268:$D$293,0),MATCH($A$1,$E$266:$CY$266,0)),"-") -> -
B11: =IFERROR(__xludf.DUMMYFUNCTION("""COMPUTED_VALUE"""),"Papel interfoliado ") -> Papel interfoliado | C11: =IFERROR(INDEX($E$82:$CY$96,MATCH($B11,$D$82:$D$96,0),MATCH($A$2,$E$80:$CY$80,0))&" ---> "&INDEX($E$82:$CY$96,MATCH($B11,$D$82:$D$96,0),MATCH($A$1,$E$80:$CY$80,0)),"-") -> ---> 0 | D11: =IFERROR(INDEX($E$100:$CY$113,MATCH($B11,$D$100:$D$113,0),MATCH($A$2,$E$98:$CY$98,0))&" ---> "&INDEX($E$100:$CY$113,MATCH($B11,$D$100:$D$113,0),MATCH($A$1,$E$98:$CY$98,0)),"-") -> - | E11: =IFERROR(INDEX($E$117:$CY$130,MATCH($B11,$D$117:$D$130,0),MATCH($A$2,$E$115:$CY$115,0))&" ---> "&INDEX($E$117:$CY$130,MATCH($B11,$D$117:$D$130,0),MATCH($A$1,$E$115:$CY$115,0)),"-") -> - | F11: =IFERROR(INDEX($E$134:$CY$147,MATCH($B11,$D$134:$D$147,0),MATCH($A$2,$E$132:$CY$132,0))&" ---> "&INDEX($E$134:$CY$147,MATCH($B11,$D$134:$D$147,0),MATCH($A$1,$E$132:$CY$132,0)),"-") -> - | G11: =IFERROR(INDEX($E$151:$CY$164,MATCH($B11,$D$151:$D$164,0),MATCH($A$2,$E$149:$CY$149,0))&" ---> "&INDEX($E$151:$CY$164,MATCH($B11,$D$151:$D$164,0),MATCH($A$1,$E$149:$CY$149,0)),"-") -> - | H11: =IFERROR(INDEX($E$169:$CY$182,MATCH($B11,$D$169:$D$182,0),MATCH($A$2,$E$167:$CY$167,0))&" ---> "&INDEX($E$169:$CY$182,MATCH($B11,$D$169:$D$182,0),MATCH($A$1,$E$167:$CY$167,0)),"-") -> - | I11: =IFERROR(INDEX($E$186:$CY$224,MATCH($B11,$D$186:$D$224,0),MATCH($A$2,$E$184:$CY$184,0))&" ---> "&INDEX($E$186:$CY$224,MATCH($B11,$D$186:$D$224,0),MATCH($A$1,$E$184:$CY$184,0)),"-") -> - | J11: =IFERROR(INDEX($E$228:$BK$243,MATCH($B11,$D$228:$D$243,0),MATCH($A$2,$E$226:$BK$226,0))&" ---> "&INDEX($E$228:$BK$243,MATCH($B11,$D$228:$D$243,0),MATCH($A$1,$E$226:$BK$226,0)),"-") -> - | K11: =IFERROR(INDEX($E$246:$CY$260,MATCH($B11,$D$246:$D$260,0),MATCH($A$2,$E$244:$CY$244,0))&" ---> "&INDEX($E$246:$CY$260,MATCH($B11,$D$246:$D$260,0),MATCH($A$1,$E$244:$CY$244,0)),"-") -> - | L11: =IFERROR(INDEX($E$268:$CY$293,MATCH($B11,$D$268:$D$293,0),MATCH($A$2,$E$266:$CY$266,0))&" ---> "&INDEX($E$268:$CY$293,MATCH($B11,$D$268:$D$293,0),MATCH($A$1,$E$266:$CY$266,0)),"-") -> -
B12: =IFERROR(__xludf.DUMMYFUNCTION("""COMPUTED_VALUE"""),"Leche liquida") -> Leche liquida | C12: =IFERROR(INDEX($E$82:$CY$96,MATCH($B12,$D$82:$D$96,0),MATCH($A$2,$E$80:$CY$80,0))&" ---> "&INDEX($E$82:$CY$96,MATCH($B12,$D$82:$D$96,0),MATCH($A$1,$E$80:$CY$80,0)),"-") -> 0 ---> 0 | D12: =IFERROR(INDEX($E$100:$CY$113,MATCH($B12,$D$100:$D$113,0),MATCH($A$2,$E$98:$CY$98,0))&" ---> "&INDEX($E$100:$CY$113,MATCH($B12,$D$100:$D$113,0),MATCH($A$1,$E$98:$CY$98,0)),"-") -> 4 ---> 1 | E12: =IFERROR(INDEX($E$117:$CY$130,MATCH($B12,$D$117:$D$130,0),MATCH($A$2,$E$115:$CY$115,0))&" ---> "&INDEX($E$117:$CY$130,MATCH($B12,$D$117:$D$130,0),MATCH($A$1,$E$115:$CY$115,0)),"-") -> 10 lt ---> 6 lt | F12: =IFERROR(INDEX($E$134:$CY$147,MATCH($B12,$D$134:$D$147,0),MATCH($A$2,$E$132:$CY$132,0))&" ---> "&INDEX($E$134:$CY$147,MATCH($B12,$D$134:$D$147,0),MATCH($A$1,$E$132:$CY$132,0)),"-") -> 11 unidades ---> 11 unidades | G12: =IFERROR(INDEX($E$151:$CY$164,MATCH($B12,$D$151:$D$164,0),MATCH($A$2,$E$149:$CY$149,0))&" ---> "&INDEX($E$151:$CY$164,MATCH($B12,$D$151:$D$164,0),MATCH($A$1,$E$149:$CY$149,0)),"-") -> 26 lts ---> 19 lts | H12: =IFERROR(INDEX($E$169:$CY$182,MATCH($B12,$D$169:$D$182,0),MATCH($A$2,$E$167:$CY$167,0))&" ---> "&INDEX($E$169:$CY$182,MATCH($B12,$D$169:$D$182,0),MATCH($A$1,$E$167:$CY$167,0)),"-") -> 19 L ---> 16L | I12: =IFERROR(INDEX($E$186:$CY$224,MATCH($B12,$D$186:$D$224,0),MATCH($A$2,$E$184:$CY$184,0))&" ---> "&INDEX($E$186:$CY$224,MATCH($B12,$D$186:$D$224,0),MATCH($A$1,$E$184:$CY$184,0)),"-") -> 20 ---> 14 | J12: =IFERROR(INDEX($E$228:$BK$243,MATCH($B12,$D$228:$D$243,0),MATCH($A$2,$E$226:$BK$226,0))&" ---> "&INDEX($E$228:$BK$243,MATCH($B12,$D$228:$D$243,0),MATCH($A$1,$E$226:$BK$226,0)),"-") -> 15 ---> 0 | K12: =IFERROR(INDEX($E$246:$CY$260,MATCH($B12,$D$246:$D$260,0),MATCH($A$2,$E$244:$CY$244,0))&" ---> "&INDEX($E$246:$CY$260,MATCH($B12,$D$246:$D$260,0),MATCH($A$1,$E$244:$CY$244,0)),"-") -> 17 ---> 16 | L12: =IFERROR(INDEX($E$268:$CY$293,MATCH($B12,$D$268:$D$293,0),MATCH($A$2,$E$266:$CY$266,0))&" ---> "&INDEX($E$268:$CY$293,MATCH($B12,$D$268:$D$293,0),MATCH($A$1,$E$266:$CY$266,0)),"-") -> 20 ---> 18
B13: =IFERROR(__xludf.DUMMYFUNCTION("""COMPUTED_VALUE"""),"Leche en polvo") -> Leche en polvo | C13: =IFERROR(INDEX($E$82:$CY$96,MATCH($B13,$D$82:$D$96,0),MATCH($A$2,$E$80:$CY$80,0))&" ---> "&INDEX($E$82:$CY$96,MATCH($B13,$D$82:$D$96,0),MATCH($A$1,$E$80:$CY$80,0)),"-") -> 2 ---> 3 | D13: =IFERROR(INDEX($E$100:$CY$113,MATCH($B13,$D$100:$D$113,0),MATCH($A$2,$E$98:$CY$98,0))&" ---> "&INDEX($E$100:$CY$113,MATCH($B13,$D$100:$D$113,0),MATCH($A$1,$E$98:$CY$98,0)),"-") -> - | E13: =IFERROR(INDEX($E$117:$CY$130,MATCH($B13,$D$117:$D$130,0),MATCH($A$2,$E$115:$CY$115,0))&" ---> "&INDEX($E$117:$CY$130,MATCH($B13,$D$117:$D$130,0),MATCH($A$1,$E$115:$CY$115,0)),"-") -> - | F13: =IFERROR(INDEX($E$134:$CY$147,MATCH($B13,$D$134:$D$147,0),MATCH($A$2,$E$132:$CY$132,0))&" ---> "&INDEX($E$134:$CY$147,MATCH($B13,$D$134:$D$147,0),MATCH($A$1,$E$132:$CY$132,0)),"-") -> - | G13: =IFERROR(INDEX($E$151:$CY$164,MATCH($B13,$D$151:$D$164,0),MATCH($A$2,$E$149:$CY$149,0))&" ---> "&INDEX($E$151:$CY$164,MATCH($B13,$D$151:$D$164,0),MATCH($A$1,$E$149:$CY$149,0)),"-") -> - | H13: =IFERROR(INDEX($E$169:$CY$182,MATCH($B13,$D$169:$D$182,0),MATCH($A$2,$E$167:$CY$167,0))&" ---> "&INDEX($E$169:$CY$182,MATCH($B13,$D$169:$D$182,0),MATCH($A$1,$E$167:$CY$167,0)),"-") -> - | I13: =IFERROR(INDEX($E$186:$CY$224,MATCH($B13,$D$186:$D$224,0),MATCH($A$2,$E$184:$CY$184,0))&" ---> "&INDEX($E$186:$CY$224,MATCH($B13,$D$186:$D$224,0),MATCH($A$1,$E$184:$CY$184,0)),"-") -> - | J13: =IFERROR(INDEX($E$228:$BK$243,MATCH($B13,$D$228:$D$243,0),MATCH($A$2,$E$226:$BK$226,0))&" ---> "&INDEX($E$228:$BK$243,MATCH($B13,$D$228:$D$243,0),MATCH($A$1,$E$226:$BK$226,0)),"-") -> - | K13: =IFERROR(INDEX($E$246:$CY$260,MATCH($B13,$D$246:$D$260,0),MATCH($A$2,$E$244:$CY$244,0))&" ---> "&INDEX($E$246:$CY$260,MATCH($B13,$D$246:$D$260,0),MATCH($A$1,$E$244:$CY$244,0)),"-") -> - | L13: =IFERROR(INDEX($E$268:$CY$293,MATCH($B13,$D$268:$D$293,0),MATCH($A$2,$E$266:$CY$266,0))&" ---> "&INDEX($E$268:$CY$293,MATCH($B13,$D$268:$D$293,0),MATCH($A$1,$E$266:$CY$266,0)),"-") -> -
B14: =IFERROR(__xludf.DUMMYFUNCTION("""COMPUTED_VALUE"""),"Vainilla") -> Vainilla | C14: =IFERROR(INDEX($E$82:$CY$96,MATCH($B14,$D$82:$D$96,0),MATCH($A$2,$E$80:$CY$80,0))&" ---> "&INDEX($E$82:$CY$96,MATCH($B14,$D$82:$D$96,0),MATCH($A$1,$E$80:$CY$80,0)),"-") -> 3 ---> 6 | D14: =IFERROR(INDEX($E$100:$CY$113,MATCH($B14,$D$100:$D$113,0),MATCH($A$2,$E$98:$CY$98,0))&" ---> "&INDEX($E$100:$CY$113,MATCH($B14,$D$100:$D$113,0),MATCH($A$1,$E$98:$CY$98,0)),"-") -> - | E14: =IFERROR(INDEX($E$117:$CY$130,MATCH($B14,$D$117:$D$130,0),MATCH($A$2,$E$115:$CY$115,0))&" ---> "&INDEX($E$117:$CY$130,MATCH($B14,$D$117:$D$130,0),MATCH($A$1,$E$115:$CY$115,0)),"-") -> - | F14: =IFERROR(INDEX($E$134:$CY$147,MATCH($B14,$D$134:$D$147,0),MATCH($A$2,$E$132:$CY$132,0))&" ---> "&INDEX($E$134:$CY$147,MATCH($B14,$D$134:$D$147,0),MATCH($A$1,$E$132:$CY$132,0)),"-") -> - | G14: =IFERROR(INDEX($E$151:$CY$164,MATCH($B14,$D$151:$D$164,0),MATCH($A$2,$E$149:$CY$149,0))&" ---> "&INDEX($E$151:$CY$164,MATCH($B14,$D$151:$D$164,0),MATCH($A$1,$E$149:$CY$149,0)),"-") -> - | H14: =IFERROR(INDEX($E$169:$CY$182,MATCH($B14,$D$169:$D$182,0),MATCH($A$2,$E$167:$CY$167,0))&" ---> "&INDEX($E$169:$CY$182,MATCH($B14,$D$169:$D$182,0),MATCH($A$1,$E$167:$CY$167,0)),"-") -> - | I14: =IFERROR(INDEX($E$186:$CY$224,MATCH($B14,$D$186:$D$224,0),MATCH($A$2,$E$184:$CY$184,0))&" ---> "&INDEX($E$186:$CY$224,MATCH($B14,$D$186:$D$224,0),MATCH($A$1,$E$184:$CY$184,0)),"-") -> - | J14: =IFERROR(INDEX($E$228:$BK$243,MATCH($B14,$D$228:$D$243,0),MATCH($A$2,$E$226:$BK$226,0))&" ---> "&INDEX($E$228:$BK$243,MATCH($B14,$D$228:$D$243,0),MATCH($A$1,$E$226:$BK$226,0)),"-") -> - | K14: =IFERROR(INDEX($E$246:$CY$260,MATCH($B14,$D$246:$D$260,0),MATCH($A$2,$E$244:$CY$244,0))&" ---> "&INDEX($E$246:$CY$260,MATCH($B14,$D$246:$D$260,0),MATCH($A$1,$E$244:$CY$244,0)),"-") -> - | L14: =IFERROR(INDEX($E$268:$CY$293,MATCH($B14,$D$268:$D$293,0),MATCH($A$2,$E$266:$CY$266,0))&" ---> "&INDEX($E$268:$CY$293,MATCH($B14,$D$268:$D$293,0),MATCH($A$1,$E$266:$CY$266,0)),"-") -> -
B15: =IFERROR(__xludf.DUMMYFUNCTION("""COMPUTED_VALUE"""),"Endulzante") -> Endulzante | C15: =IFERROR(INDEX($E$82:$CY$96,MATCH($B15,$D$82:$D$96,0),MATCH($A$2,$E$80:$CY$80,0))&" ---> "&INDEX($E$82:$CY$96,MATCH($B15,$D$82:$D$96,0),MATCH($A$1,$E$80:$CY$80,0)),"-") -> 5 ---> 3 | D15: =IFERROR(INDEX($E$100:$CY$113,MATCH($B15,$D$100:$D$113,0),MATCH($A$2,$E$98:$CY$98,0))&" ---> "&INDEX($E$100:$CY$113,MATCH($B15,$D$100:$D$113,0),MATCH($A$1,$E$98:$CY$98,0)),"-") -> 0 ---> 0 | E15: =IFERROR(INDEX($E$117:$CY$130,MATCH($B15,$D$117:$D$130,0),MATCH($A$2,$E$115:$CY$115,0))&" ---> "&INDEX($E$117:$CY$130,MATCH($B15,$D$117:$D$130,0),MATCH($A$1,$E$115:$CY$115,0)),"-") -> 1 ---> 1 | F15: =IFERROR(INDEX($E$134:$CY$147,MATCH($B15,$D$134:$D$147,0),MATCH($A$2,$E$132:$CY$132,0))&" ---> "&INDEX($E$134:$CY$147,MATCH($B15,$D$134:$D$147,0),MATCH($A$1,$E$132:$CY$132,0)),"-") -> 2 unidades ---> 1 unidad | G15: =IFERROR(INDEX($E$151:$CY$164,MATCH($B15,$D$151:$D$164,0),MATCH($A$2,$E$149:$CY$149,0))&" ---> "&INDEX($E$151:$CY$164,MATCH($B15,$D$151:$D$164,0),MATCH($A$1,$E$149:$CY$149,0)),"-") -> 3 und ---> 3 und | H15: =IFERROR(INDEX($E$169:$CY$182,MATCH($B15,$D$169:$D$182,0),MATCH($A$2,$E$167:$CY$167,0))&" ---> "&INDEX($E$169:$CY$182,MATCH($B15,$D$169:$D$182,0),MATCH($A$1,$E$167:$CY$167,0)),"-") -> 1(450ml) ---> 1(450ml) | I15: =IFERROR(INDEX($E$186:$CY$224,MATCH($B15,$D$186:$D$224,0),MATCH($A$2,$E$184:$CY$184,0))&" ---> "&INDEX($E$186:$CY$224,MATCH($B15,$D$186:$D$224,0),MATCH($A$1,$E$184:$CY$184,0)),"-") -> 6 ---> 6 | J15: =IFERROR(INDEX($E$228:$BK$243,MATCH($B15,$D$228:$D$243,0),MATCH($A$2,$E$226:$BK$226,0))&" ---> "&INDEX($E$228:$BK$243,MATCH($B15,$D$228:$D$243,0),MATCH($A$1,$E$226:$BK$226,0)),"-") -> ---> | K15: =IFERROR(INDEX($E$246:$CY$260,MATCH($B15,$D$246:$D$260,0),MATCH($A$2,$E$244:$CY$244,0))&" ---> "&INDEX($E$246:$CY$260,MATCH($B15,$D$246:$D$260,0),MATCH($A$1,$E$244:$CY$244,0)),"-") -> 2 ---> 2 | L15: =IFERROR(INDEX($E$268:$CY$293,MATCH($B15,$D$268:$D$293,0),MATCH($A$2,$E$266:$CY$266,0))&" ---> "&INDEX($E$268:$CY$293,MATCH($B15,$D$268:$D$293,0),MATCH($A$1,$E$266:$CY$266,0)),"-") -> 2 ---> 2
B16: =IFERROR(__xludf.DUMMYFUNCTION("""COMPUTED_VALUE"""),"Servilletas") -> Servilletas | C16: =IFERROR(INDEX($E$82:$CY$96,MATCH($B16,$D$82:$D$96,0),MATCH($A$2,$E$80:$CY$80,0))&" ---> "&INDEX($E$82:$CY$96,MATCH($B16,$D$82:$D$96,0),MATCH($A$1,$E$80:$CY$80,0)),"-") -> 14 ---> 16 | D16: =IFERROR(INDEX($E$100:$CY$113,MATCH($B16,$D$100:$D$113,0),MATCH($A$2,$E$98:$CY$98,0))&" ---> "&INDEX($E$100:$CY$113,MATCH($B16,$D$100:$D$113,0),MATCH($A$1,$E$98:$CY$98,0)),"-") -> 14 ---> 12 | E16: =IFERROR(INDEX($E$117:$CY$130,MATCH($B16,$D$117:$D$130,0),MATCH($A$2,$E$115:$CY$115,0))&" ---> "&INDEX($E$117:$CY$130,MATCH($B16,$D$117:$D$130,0),MATCH($A$1,$E$115:$CY$115,0)),"-") -> 0 ---> 0 | F16: =IFERROR(INDEX($E$134:$CY$147,MATCH($B16,$D$134:$D$147,0),MATCH($A$2,$E$132:$CY$132,0))&" ---> "&INDEX($E$134:$CY$147,MATCH($B16,$D$134:$D$147,0),MATCH($A$1,$E$132:$CY$132,0)),"-") -> 10 paquetes ---> 12 paquetes | G16: =IFERROR(INDEX($E$151:$CY$164,MATCH($B16,$D$151:$D$164,0),MATCH($A$2,$E$149:$CY$149,0))&" ---> "&INDEX($E$151:$CY$164,MATCH($B16,$D$151:$D$164,0),MATCH($A$1,$E$149:$CY$149,0)),"-") -> 7 cajas ---> 7 cajas | H16: =IFERROR(INDEX($E$169:$CY$182,MATCH($B16,$D$169:$D$182,0),MATCH($A$2,$E$167:$CY$167,0))&" ---> "&INDEX($E$169:$CY$182,MATCH($B16,$D$169:$D$182,0),MATCH($A$1,$E$167:$CY$167,0)),"-") -> 4 ---> 3 | I16: =IFERROR(INDEX($E$186:$CY$224,MATCH($B16,$D$186:$D$224,0),MATCH($A$2,$E$184:$CY$184,0))&" ---> "&INDEX($E$186:$CY$224,MATCH($B16,$D$186:$D$224,0),MATCH($A$1,$E$184:$CY$184,0)),"-") -> - | J16: =IFERROR(INDEX($E$228:$BK$243,MATCH($B16,$D$228:$D$243,0),MATCH($A$2,$E$226:$BK$226,0))&" ---> "&INDEX($E$228:$BK$243,MATCH($B16,$D$228:$D$243,0),MATCH($A$1,$E$226:$BK$226,0)),"-") -> 6 ---> 1 | K16: =IFERROR(INDEX($E$246:$CY$260,MATCH($B16,$D$246:$D$260,0),MATCH($A$2,$E$244:$CY$244,0))&" ---> "&INDEX($E$246:$CY$260,MATCH($B16,$D$246:$D$260,0),MATCH($A$1,$E$244:$CY$244,0)),"-") -> 15 ---> 13 | L16: =IFERROR(INDEX($E$268:$CY$293,MATCH($B16,$D$268:$D$293,0),MATCH($A$2,$E$266:$CY$266,0))&" ---> "&INDEX($E$268:$CY$293,MATCH($B16,$D$268:$D$293,0),MATCH($A$1,$E$266:$CY$266,0)),"-") -> 21 ---> 20
B17: =IFERROR(__xludf.DUMMYFUNCTION("""COMPUTED_VALUE"""),"Cloro Gel") -> Cloro Gel | C17: =IFERROR(INDEX($E$82:$CY$96,MATCH($B17,$D$82:$D$96,0),MATCH($A$2,$E$80:$CY$80,0))&" ---> "&INDEX($E$82:$CY$96,MATCH($B17,$D$82:$D$96,0),MATCH($A$1,$E$80:$CY$80,0)),"-") -> 4 ---> 3 | D17: =IFERROR(INDEX($E$100:$CY$113,MATCH($B17,$D$100:$D$113,0),MATCH($A$2,$E$98:$CY$98,0))&" ---> "&INDEX($E$100:$CY$113,MATCH($B17,$D$100:$D$113,0),MATCH($A$1,$E$98:$CY$98,0)),"-") -> 1 ---> 1 | E17: =IFERROR(INDEX($E$117:$CY$130,MATCH($B17,$D$117:$D$130,0),MATCH($A$2,$E$115:$CY$115,0))&" ---> "&INDEX($E$117:$CY$130,MATCH($B17,$D$117:$D$130,0),MATCH($A$1,$E$115:$CY$115,0)),"-") -> 9 ---> 2 paquetes | F17: =IFERROR(INDEX($E$134:$CY$147,MATCH($B17,$D$134:$D$147,0),MATCH($A$2,$E$132:$CY$132,0))&" ---> "&INDEX($E$134:$CY$147,MATCH($B17,$D$134:$D$147,0),MATCH($A$1,$E$132:$CY$132,0)),"-") -> 1 ---> 0 | G17: =IFERROR(INDEX($E$151:$CY$164,MATCH($B17,$D$151:$D$164,0),MATCH($A$2,$E$149:$CY$149,0))&" ---> "&INDEX($E$151:$CY$164,MATCH($B17,$D$151:$D$164,0),MATCH($A$1,$E$149:$CY$149,0)),"-") -> 5 cajas ---> 5 cajas | H17: =IFERROR(INDEX($E$169:$CY$182,MATCH($B17,$D$169:$D$182,0),MATCH($A$2,$E$167:$CY$167,0))&" ---> "&INDEX($E$169:$CY$182,MATCH($B17,$D$169:$D$182,0),MATCH($A$1,$E$167:$CY$167,0)),"-") -> 1 ---> 1 | I17: =IFERROR(INDEX($E$186:$CY$224,MATCH($B17,$D$186:$D$224,0),MATCH($A$2,$E$184:$CY$184,0))&" ---> "&INDEX($E$186:$CY$224,MATCH($B17,$D$186:$D$224,0),MATCH($A$1,$E$184:$CY$184,0)),"-") -> 3 ---> 3 | J17: =IFERROR(INDEX($E$228:$BK$243,MATCH($B17,$D$228:$D$243,0),MATCH($A$2,$E$226:$BK$226,0))&" ---> "&INDEX($E$228:$BK$243,MATCH($B17,$D$228:$D$243,0),MATCH($A$1,$E$226:$BK$226,0)),"-") -> 4 ---> 0 | K17: =IFERROR(INDEX($E$246:$CY$260,MATCH($B17,$D$246:$D$260,0),MATCH($A$2,$E$244:$CY$244,0))&" ---> "&INDEX($E$246:$CY$260,MATCH($B17,$D$246:$D$260,0),MATCH($A$1,$E$244:$CY$244,0)),"-") -> 0 ---> 0 | L17: =IFERROR(INDEX($E$268:$CY$293,MATCH($B17,$D$268:$D$293,0),MATCH($A$2,$E$266:$CY$266,0))&" ---> "&INDEX($E$268:$CY$293,MATCH($B17,$D$268:$D$293,0),MATCH($A$1,$E$266:$CY$266,0)),"-") -> 2 ---> 2
B18: =IFERROR(__xludf.DUMMYFUNCTION("""COMPUTED_VALUE"""),"Limpia Piso") -> Limpia Piso | C18: =IFERROR(INDEX($E$82:$CY$96,MATCH($B18,$D$82:$D$96,0),MATCH($A$2,$E$80:$CY$80,0))&" ---> "&INDEX($E$82:$CY$96,MATCH($B18,$D$82:$D$96,0),MATCH($A$1,$E$80:$CY$80,0)),"-") -> 4 ---> 0 | D18: =IFERROR(INDEX($E$100:$CY$113,MATCH($B18,$D$100:$D$113,0),MATCH($A$2,$E$98:$CY$98,0))&" ---> "&INDEX($E$100:$CY$113,MATCH($B18,$D$100:$D$113,0),MATCH($A$1,$E$98:$CY$98,0)),"-") -> 1 ---> 1 | E18: =IFERROR(INDEX($E$117:$CY$130,MATCH($B18,$D$117:$D$130,0),MATCH($A$2,$E$115:$CY$115,0))&" ---> "&INDEX($E$117:$CY$130,MATCH($B18,$D$117:$D$130,0),MATCH($A$1,$E$115:$CY$115,0)),"-") -> 1 ---> 0 | F18: =IFERROR(INDEX($E$134:$CY$147,MATCH($B18,$D$134:$D$147,0),MATCH($A$2,$E$132:$CY$132,0))&" ---> "&INDEX($E$134:$CY$147,MATCH($B18,$D$134:$D$147,0),MATCH($A$1,$E$132:$CY$132,0)),"-") -> 0 ---> 0 | G18: =IFERROR(INDEX($E$151:$CY$164,MATCH($B18,$D$151:$D$164,0),MATCH($A$2,$E$149:$CY$149,0))&" ---> "&INDEX($E$151:$CY$164,MATCH($B18,$D$151:$D$164,0),MATCH($A$1,$E$149:$CY$149,0)),"-") -> 3 cajas ---> 3 cajas | H18: =IFERROR(INDEX($E$169:$CY$182,MATCH($B18,$D$169:$D$182,0),MATCH($A$2,$E$167:$CY$167,0))&" ---> "&INDEX($E$169:$CY$182,MATCH($B18,$D$169:$D$182,0),MATCH($A$1,$E$167:$CY$167,0)),"-") -> 1 ---> 3(lts) | I18: =IFERROR(INDEX($E$186:$CY$224,MATCH($B18,$D$186:$D$224,0),MATCH($A$2,$E$184:$CY$184,0))&" ---> "&INDEX($E$186:$CY$224,MATCH($B18,$D$186:$D$224,0),MATCH($A$1,$E$184:$CY$184,0)),"-") -> 2 ---> 2 | J18: =IFERROR(INDEX($E$228:$BK$243,MATCH($B18,$D$228:$D$243,0),MATCH($A$2,$E$226:$BK$226,0))&" ---> "&INDEX($E$228:$BK$243,MATCH($B18,$D$228:$D$243,0),MATCH($A$1,$E$226:$BK$226,0)),"-") -> 4 ---> 3 | K18: =IFERROR(INDEX($E$246:$CY$260,MATCH($B18,$D$246:$D$260,0),MATCH($A$2,$E$244:$CY$244,0))&" ---> "&INDEX($E$246:$CY$260,MATCH($B18,$D$246:$D$260,0),MATCH($A$1,$E$244:$CY$244,0)),"-") -> 0 ---> 0 | L18: =IFERROR(INDEX($E$268:$CY$293,MATCH($B18,$D$268:$D$293,0),MATCH($A$2,$E$266:$CY$266,0))&" ---> "&INDEX($E$268:$CY$293,MATCH($B18,$D$268:$D$293,0),MATCH($A$1,$E$266:$CY$266,0)),"-") -> 2 ---> 2
B19: =IFERROR(__xludf.DUMMYFUNCTION("""COMPUTED_VALUE"""),"Esponja 4U") -> Esponja 4U | C19: =IFERROR(INDEX($E$82:$CY$96,MATCH($B19,$D$82:$D$96,0),MATCH($A$2,$E$80:$CY$80,0))&" ---> "&INDEX($E$82:$CY$96,MATCH($B19,$D$82:$D$96,0),MATCH($A$1,$E$80:$CY$80,0)),"-") -> 3 ---> 1 | D19: =IFERROR(INDEX($E$100:$CY$113,MATCH($B19,$D$100:$D$113,0),MATCH($A$2,$E$98:$CY$98,0))&" ---> "&INDEX($E$100:$CY$113,MATCH($B19,$D$100:$D$113,0),MATCH($A$1,$E$98:$CY$98,0)),"-") -> 3 ---> 3 | E19: =IFERROR(INDEX($E$117:$CY$130,MATCH($B19,$D$117:$D$130,0),MATCH($A$2,$E$115:$CY$115,0))&" ---> "&INDEX($E$117:$CY$130,MATCH($B19,$D$117:$D$130,0),MATCH($A$1,$E$115:$CY$115,0)),"-") -> 4 ---> 2 | F19: =IFERROR(INDEX($E$134:$CY$147,MATCH($B19,$D$134:$D$147,0),MATCH($A$2,$E$132:$CY$132,0))&" ---> "&INDEX($E$134:$CY$147,MATCH($B19,$D$134:$D$147,0),MATCH($A$1,$E$132:$CY$132,0)),"-") -> 3 paquetes ---> 3 paquetes | G19: =IFERROR(INDEX($E$151:$CY$164,MATCH($B19,$D$151:$D$164,0),MATCH($A$2,$E$149:$CY$149,0))&" ---> "&INDEX($E$151:$CY$164,MATCH($B19,$D$151:$D$164,0),MATCH($A$1,$E$149:$CY$149,0)),"-") -> 2 lts ---> 3 lts | H19: =IFERROR(INDEX($E$169:$CY$182,MATCH($B19,$D$169:$D$182,0),MATCH($A$2,$E$167:$CY$167,0))&" ---> "&INDEX($E$169:$CY$182,MATCH($B19,$D$169:$D$182,0),MATCH($A$1,$E$167:$CY$167,0)),"-") -> 4 ---> 4 | I19: =IFERROR(INDEX($E$186:$CY$224,MATCH($B19,$D$186:$D$224,0),MATCH($A$2,$E$184:$CY$184,0))&" ---> "&INDEX($E$186:$CY$224,MATCH($B19,$D$186:$D$224,0),MATCH($A$1,$E$184:$CY$184,0)),"-") -> 3 ---> 2 1/2 | J19: =IFERROR(INDEX($E$228:$BK$243,MATCH($B19,$D$228:$D$243,0),MATCH($A$2,$E$226:$BK$226,0))&" ---> "&INDEX($E$228:$BK$243,MATCH($B19,$D$228:$D$243,0),MATCH($A$1,$E$226:$BK$226,0)),"-") -> 2 ---> 0 | K19: =IFERROR(INDEX($E$246:$CY$260,MATCH($B19,$D$246:$D$260,0),MATCH($A$2,$E$244:$CY$244,0))&" ---> "&INDEX($E$246:$CY$260,MATCH($B19,$D$246:$D$260,0),MATCH($A$1,$E$244:$CY$244,0)),"-") -> - | L19: =IFERROR(INDEX($E$268:$CY$293,MATCH($B19,$D$268:$D$293,0),MATCH($A$2,$E$266:$CY$266,0))&" ---> "&INDEX($E$268:$CY$293,MATCH($B19,$D$268:$D$293,0),MATCH($A$1,$E$266:$CY$266,0)),"-") -> -
B20: =IFERROR(__xludf.DUMMYFUNCTION("""COMPUTED_VALUE"""),"Mopa Redonda") -> Mopa Redonda | C20: =IFERROR(INDEX($E$82:$CY$96,MATCH($B20,$D$82:$D$96,0),MATCH($A$2,$E$80:$CY$80,0))&" ---> "&INDEX($E$82:$CY$96,MATCH($B20,$D$82:$D$96,0),MATCH($A$1,$E$80:$CY$80,0)),"-") -> 5 ---> 3 | D20: =IFERROR(INDEX($E$100:$CY$113,MATCH($B20,$D$100:$D$113,0),MATCH($A$2,$E$98:$CY$98,0))&" ---> "&INDEX($E$100:$CY$113,MATCH($B20,$D$100:$D$113,0),MATCH($A$1,$E$98:$CY$98,0)),"-") -> 3 ---> 3 | E20: =IFERROR(INDEX($E$117:$CY$130,MATCH($B20,$D$117:$D$130,0),MATCH($A$2,$E$115:$CY$115,0))&" ---> "&INDEX($E$117:$CY$130,MATCH($B20,$D$117:$D$130,0),MATCH($A$1,$E$115:$CY$115,0)),"-") -> 1 ---> 4 und | F20: =IFERROR(INDEX($E$134:$CY$147,MATCH($B20,$D$134:$D$147,0),MATCH($A$2,$E$132:$CY$132,0))&" ---> "&INDEX($E$134:$CY$147,MATCH($B20,$D$134:$D$147,0),MATCH($A$1,$E$132:$CY$132,0)),"-") -> 5 unidades ---> 3 unidades | G20: =IFERROR(INDEX($E$151:$CY$164,MATCH($B20,$D$151:$D$164,0),MATCH($A$2,$E$149:$CY$149,0))&" ---> "&INDEX($E$151:$CY$164,MATCH($B20,$D$151:$D$164,0),MATCH($A$1,$E$149:$CY$149,0)),"-") -> 1 kg ---> 1 kg | H20: =IFERROR(INDEX($E$169:$CY$182,MATCH($B20,$D$169:$D$182,0),MATCH($A$2,$E$167:$CY$167,0))&" ---> "&INDEX($E$169:$CY$182,MATCH($B20,$D$169:$D$182,0),MATCH($A$1,$E$167:$CY$167,0)),"-") -> - | I20: =IFERROR(INDEX($E$186:$CY$224,MATCH($B20,$D$186:$D$224,0),MATCH($A$2,$E$184:$CY$184,0))&" ---> "&INDEX($E$186:$CY$224,MATCH($B20,$D$186:$D$224,0),MATCH($A$1,$E$184:$CY$184,0)),"-") -> 0 ---> 4 | J20: =IFERROR(INDEX($E$228:$BK$243,MATCH($B20,$D$228:$D$243,0),MATCH($A$2,$E$226:$BK$226,0))&" ---> "&INDEX($E$228:$BK$243,MATCH($B20,$D$228:$D$243,0),MATCH($A$1,$E$226:$BK$226,0)),"-") -> 5 ---> 1 | K20: =IFERROR(INDEX($E$246:$CY$260,MATCH($B20,$D$246:$D$260,0),MATCH($A$2,$E$244:$CY$244,0))&" ---> "&INDEX($E$246:$CY$260,MATCH($B20,$D$246:$D$260,0),MATCH($A$1,$E$244:$CY$244,0)),"-") -> - | L20: =IFERROR(INDEX($E$268:$CY$293,MATCH($B20,$D$268:$D$293,0),MATCH($A$2,$E$266:$CY$266,0))&" ---> "&INDEX($E$268:$CY$293,MATCH($B20,$D$268:$D$293,0),MATCH($A$1,$E$266:$CY$266,0)),"-") -> -
B21: =IFERROR(__xludf.DUMMYFUNCTION("""COMPUTED_VALUE"""),"Bolsas Basura 50x70") -> Bolsas Basura 50x70 | C21: =IFERROR(INDEX($E$82:$CY$96,MATCH($B21,$D$82:$D$96,0),MATCH($A$2,$E$80:$CY$80,0))&" ---> "&INDEX($E$82:$CY$96,MATCH($B21,$D$82:$D$96,0),MATCH($A$1,$E$80:$CY$80,0)),"-") -> - | D21: =IFERROR(INDEX($E$100:$CY$113,MATCH($B21,$D$100:$D$113,0),MATCH($A$2,$E$98:$CY$98,0))&" ---> "&INDEX($E$100:$CY$113,MATCH($B21,$D$100:$D$113,0),MATCH($A$1,$E$98:$CY$98,0)),"-") -> 17 ---> 15 | E21: =IFERROR(INDEX($E$117:$CY$130,MATCH($B21,$D$117:$D$130,0),MATCH($A$2,$E$115:$CY$115,0))&" ---> "&INDEX($E$117:$CY$130,MATCH($B21,$D$117:$D$130,0),MATCH($A$1,$E$115:$CY$115,0)),"-") -> 0 ---> 0 | F21: =IFERROR(INDEX($E$134:$CY$147,MATCH($B21,$D$134:$D$147,0),MATCH($A$2,$E$132:$CY$132,0))&" ---> "&INDEX($E$134:$CY$147,MATCH($B21,$D$134:$D$147,0),MATCH($A$1,$E$132:$CY$132,0)),"-") -> 0 ---> 0 | G21: =IFERROR(INDEX($E$151:$CY$164,MATCH($B21,$D$151:$D$164,0),MATCH($A$2,$E$149:$CY$149,0))&" ---> "&INDEX($E$151:$CY$164,MATCH($B21,$D$151:$D$164,0),MATCH($A$1,$E$149:$CY$149,0)),"-") -> 4 lts ---> 4 lts | H21: =IFERROR(INDEX($E$169:$CY$182,MATCH($B21,$D$169:$D$182,0),MATCH($A$2,$E$167:$CY$167,0))&" ---> "&INDEX($E$169:$CY$182,MATCH($B21,$D$169:$D$182,0),MATCH($A$1,$E$167:$CY$167,0)),"-") -> 25 ---> 23 | I21: =IFERROR(INDEX($E$186:$CY$224,MATCH($B21,$D$186:$D$224,0),MATCH($A$2,$E$184:$CY$184,0))&" ---> "&INDEX($E$186:$CY$224,MATCH($B21,$D$186:$D$224,0),MATCH($A$1,$E$184:$CY$184,0)),"-") -> 2 ---> 3 | J21: =IFERROR(INDEX($E$228:$BK$243,MATCH($B21,$D$228:$D$243,0),MATCH($A$2,$E$226:$BK$226,0))&" ---> "&INDEX($E$228:$BK$243,MATCH($B21,$D$228:$D$243,0),MATCH($A$1,$E$226:$BK$226,0)),"-") -> 4 ---> 2 | K21: =IFERROR(INDEX($E$246:$CY$260,MATCH($B21,$D$246:$D$260,0),MATCH($A$2,$E$244:$CY$244,0))&" ---> "&INDEX($E$246:$CY$260,MATCH($B21,$D$246:$D$260,0),MATCH($A$1,$E$244:$CY$244,0)),"-") -> 6 ---> 4 | L21: =IFERROR(INDEX($E$268:$CY$293,MATCH($B21,$D$268:$D$293,0),MATCH($A$2,$E$266:$CY$266,0))&" ---> "&INDEX($E$268:$CY$293,MATCH($B21,$D$268:$D$293,0),MATCH($A$1,$E$266:$CY$266,0)),"-") -> 14 ---> 14
B22: =IFERROR(__xludf.DUMMYFUNCTION("""COMPUTED_VALUE"""),"Bolsas Basura 70x90") -> Bolsas Basura 70x90 | C22: =IFERROR(INDEX($E$82:$CY$96,MATCH($B22,$D$82:$D$96,0),MATCH($A$2,$E$80:$CY$80,0))&" ---> "&INDEX($E$82:$CY$96,MATCH($B22,$D$82:$D$96,0),MATCH($A$1,$E$80:$CY$80,0)),"-") -> - | D22: =IFERROR(INDEX($E$100:$CY$113,MATCH($B22,$D$100:$D$113,0),MATCH($A$2,$E$98:$CY$98,0))&" ---> "&INDEX($E$100:$CY$113,MATCH($B22,$D$100:$D$113,0),MATCH($A$1,$E$98:$CY$98,0)),"-") -> 1 ---> 0 | E22: =IFERROR(INDEX($E$117:$CY$130,MATCH($B22,$D$117:$D$130,0),MATCH($A$2,$E$115:$CY$115,0))&" ---> "&INDEX($E$117:$CY$130,MATCH($B22,$D$117:$D$130,0),MATCH($A$1,$E$115:$CY$115,0)),"-") -> 9 ---> 3 | F22: =IFERROR(INDEX($E$134:$CY$147,MATCH($B22,$D$134:$D$147,0),MATCH($A$2,$E$132:$CY$132,0))&" ---> "&INDEX($E$134:$CY$147,MATCH($B22,$D$134:$D$147,0),MATCH($A$1,$E$132:$CY$132,0)),"-") -> 4 paquetes ---> 2 paquetes | G22: =IFERROR(INDEX($E$151:$CY$164,MATCH($B22,$D$151:$D$164,0),MATCH($A$2,$E$149:$CY$149,0))&" ---> "&INDEX($E$151:$CY$164,MATCH($B22,$D$151:$D$164,0),MATCH($A$1,$E$149:$CY$149,0)),"-") -> 1 lt ---> 1 lt | H22: =IFERROR(INDEX($E$169:$CY$182,MATCH($B22,$D$169:$D$182,0),MATCH($A$2,$E$167:$CY$167,0))&" ---> "&INDEX($E$169:$CY$182,MATCH($B22,$D$169:$D$182,0),MATCH($A$1,$E$167:$CY$167,0)),"-") -> 21 ---> 19 | I22: =IFERROR(INDEX($E$186:$CY$224,MATCH($B22,$D$186:$D$224,0),MATCH($A$2,$E$184:$CY$184,0))&" ---> "&INDEX($E$186:$CY$224,MATCH($B22,$D$186:$D$224,0),MATCH($A$1,$E$184:$CY$184,0)),"-") -> 8 ---> 9 | J22: =IFERROR(INDEX($E$228:$BK$243,MATCH($B22,$D$228:$D$243,0),MATCH($A$2,$E$226:$BK$226,0))&" ---> "&INDEX($E$228:$BK$243,MATCH($B22,$D$228:$D$243,0),MATCH($A$1,$E$226:$BK$226,0)),"-") -> 17 ---> 0 | K22: =IFERROR(INDEX($E$246:$CY$260,MATCH($B22,$D$246:$D$260,0),MATCH($A$2,$E$244:$CY$244,0))&" ---> "&INDEX($E$246:$CY$260,MATCH($B22,$D$246:$D$260,0),MATCH($A$1,$E$244:$CY$244,0)),"-") -> 0 ---> 0 | L22: =IFERROR(INDEX($E$268:$CY$293,MATCH($B22,$D$268:$D$293,0),MATCH($A$2,$E$266:$CY$266,0))&" ---> "&INDEX($E$268:$CY$293,MATCH($B22,$D$268:$D$293,0),MATCH($A$1,$E$266:$CY$266,0)),"-") -> -
B23: =IFERROR(__xludf.DUMMYFUNCTION("""COMPUTED_VALUE"""),"Bolsas Basura 80x110") -> Bolsas Basura 80x110 | C23: =IFERROR(INDEX($E$82:$CY$96,MATCH($B23,$D$82:$D$96,0),MATCH($A$2,$E$80:$CY$80,0))&" ---> "&INDEX($E$82:$CY$96,MATCH($B23,$D$82:$D$96,0),MATCH($A$1,$E$80:$CY$80,0)),"-") -> - | D23: =IFERROR(INDEX($E$100:$CY$113,MATCH($B23,$D$100:$D$113,0),MATCH($A$2,$E$98:$CY$98,0))&" ---> "&INDEX($E$100:$CY$113,MATCH($B23,$D$100:$D$113,0),MATCH($A$1,$E$98:$CY$98,0)),"-") -> 12 ---> 10 | E23: =IFERROR(INDEX($E$117:$CY$130,MATCH($B23,$D$117:$D$130,0),MATCH($A$2,$E$115:$CY$115,0))&" ---> "&INDEX($E$117:$CY$130,MATCH($B23,$D$117:$D$130,0),MATCH($A$1,$E$115:$CY$115,0)),"-") -> 4 ---> 3 | F23: =IFERROR(INDEX($E$134:$CY$147,MATCH($B23,$D$134:$D$147,0),MATCH($A$2,$E$132:$CY$132,0))&" ---> "&INDEX($E$134:$CY$147,MATCH($B23,$D$134:$D$147,0),MATCH($A$1,$E$132:$CY$132,0)),"-") -> 5 paquetes ---> 1 paquete | G23: =IFERROR(INDEX($E$151:$CY$165,MATCH($B23,$D$151:$D$165,0),MATCH($A$2,$E$149:$CY$149,0))&" ---> "&INDEX($E$151:$CY$165,MATCH($B23,$D$151:$D$165,0),MATCH($A$1,$E$149:$CY$149,0)),"-") -> 2 lts ---> 2 lts | H23: =IFERROR(INDEX($E$169:$CY$182,MATCH($B23,$D$169:$D$182,0),MATCH($A$2,$E$167:$CY$167,0))&" ---> "&INDEX($E$169:$CY$182,MATCH($B23,$D$169:$D$182,0),MATCH($A$1,$E$167:$CY$167,0)),"-") -> 15 ---> 13 | I23: =IFERROR(INDEX($E$186:$CY$224,MATCH($B23,$D$186:$D$224,0),MATCH($A$2,$E$184:$CY$184,0))&" ---> "&INDEX($E$186:$CY$224,MATCH($B23,$D$186:$D$224,0),MATCH($A$1,$E$184:$CY$184,0)),"-") -> 5 ---> 11 | J23: =IFERROR(INDEX($E$228:$BK$243,MATCH($B23,$D$228:$D$243,0),MATCH($A$2,$E$226:$BK$226,0))&" ---> "&INDEX($E$228:$BK$243,MATCH($B23,$D$228:$D$243,0),MATCH($A$1,$E$226:$BK$226,0)),"-") -> 0 ---> 0 | K23: =IFERROR(INDEX($E$246:$CY$260,MATCH($B23,$D$246:$D$260,0),MATCH($A$2,$E$244:$CY$244,0))&" ---> "&INDEX($E$246:$CY$260,MATCH($B23,$D$246:$D$260,0),MATCH($A$1,$E$244:$CY$244,0)),"-") -> 1 ---> 1 | L23: =IFERROR(INDEX($E$268:$CY$293,MATCH($B23,$D$268:$D$293,0),MATCH($A$2,$E$266:$CY$266,0))&" ---> "&INDEX($E$268:$CY$293,MATCH($B23,$D$268:$D$293,0),MATCH($A$1,$E$266:$CY$266,0)),"-") -> -
B24: =IFERROR(__xludf.DUMMYFUNCTION("""COMPUTED_VALUE"""),"Repuesto Jabon") -> Repuesto Jabon | C24: =IFERROR(INDEX($E$82:$CY$96,MATCH($B24,$D$82:$D$96,0),MATCH($A$2,$E$80:$CY$80,0))&" ---> "&INDEX($E$82:$CY$96,MATCH($B24,$D$82:$D$96,0),MATCH($A$1,$E$80:$CY$80,0)),"-") -> - | D24: =IFERROR(INDEX($E$100:$CY$113,MATCH($B24,$D$100:$D$113,0),MATCH($A$2,$E$98:$CY$98,0))&" ---> "&INDEX($E$100:$CY$113,MATCH($B24,$D$100:$D$113,0),MATCH($A$1,$E$98:$CY$98,0)),"-") -> - | E24: =IFERROR(INDEX($E$117:$CY$130,MATCH($B24,$D$117:$D$130,0),MATCH($A$2,$E$115:$CY$115,0))&" ---> "&INDEX($E$117:$CY$130,MATCH($B24,$D$117:$D$130,0),MATCH($A$1,$E$115:$CY$115,0)),"-") -> - | F24: =IFERROR(INDEX($E$134:$CY$147,MATCH($B24,$D$134:$D$147,0),MATCH($A$2,$E$132:$CY$132,0))&" ---> "&INDEX($E$134:$CY$147,MATCH($B24,$D$134:$D$147,0),MATCH($A$1,$E$132:$CY$132,0)),"-") -> - | G24: =IFERROR(INDEX($E$151:$CY$165,MATCH($B24,$D$151:$D$165,0),MATCH($A$2,$E$149:$CY$149,0))&" ---> "&INDEX($E$151:$CY$165,MATCH($B24,$D$151:$D$165,0),MATCH($A$1,$E$149:$CY$149,0)),"-") -> ---> | H24: =IFERROR(INDEX($E$169:$CY$182,MATCH($B24,$D$169:$D$182,0),MATCH($A$2,$E$167:$CY$167,0))&" ---> "&INDEX($E$169:$CY$182,MATCH($B24,$D$169:$D$182,0),MATCH($A$1,$E$167:$CY$167,0)),"-") -> - | I24: =IFERROR(INDEX($E$186:$CY$224,MATCH($B24,$D$186:$D$224,0),MATCH($A$2,$E$184:$CY$184,0))&" ---> "&INDEX($E$186:$CY$224,MATCH($B24,$D$186:$D$224,0),MATCH($A$1,$E$184:$CY$184,0)),"-") -> - | J24: =IFERROR(INDEX($E$228:$BK$243,MATCH($B24,$D$228:$D$243,0),MATCH($A$2,$E$226:$BK$226,0))&" ---> "&INDEX($E$228:$BK$243,MATCH($B24,$D$228:$D$243,0),MATCH($A$1,$E$226:$BK$226,0)),"-") -> - | K24: =IFERROR(INDEX($E$246:$CY$260,MATCH($B24,$D$246:$D$260,0),MATCH($A$2,$E$244:$CY$244,0))&" ---> "&INDEX($E$246:$CY$260,MATCH($B24,$D$246:$D$260,0),MATCH($A$1,$E$244:$CY$244,0)),"-") -> - | L24: =IFERROR(INDEX($E$268:$CY$293,MATCH($B24,$D$268:$D$293,0),MATCH($A$2,$E$266:$CY$266,0))&" ---> "&INDEX($E$268:$CY$293,MATCH($B24,$D$268:$D$293,0),MATCH($A$1,$E$266:$CY$266,0)),"-") -> -
B25: =IFERROR(__xludf.DUMMYFUNCTION("""COMPUTED_VALUE"""),"Aceite de oliva ") -> Aceite de oliva | C25: =IFERROR(INDEX($E$82:$CY$96,MATCH($B25,$D$82:$D$96,0),MATCH($A$2,$E$80:$CY$80,0))&" ---> "&INDEX($E$82:$CY$96,MATCH($B25,$D$82:$D$96,0),MATCH($A$1,$E$80:$CY$80,0)),"-") -> - | D25: =IFERROR(INDEX($E$100:$CY$113,MATCH($B25,$D$100:$D$113,0),MATCH($A$2,$E$98:$CY$98,0))&" ---> "&INDEX($E$100:$CY$113,MATCH($B25,$D$100:$D$113,0),MATCH($A$1,$E$98:$CY$98,0)),"-") -> - | E25: =IFERROR(INDEX($E$117:$CY$130,MATCH($B25,$D$117:$D$130,0),MATCH($A$2,$E$115:$CY$115,0))&" ---> "&INDEX($E$117:$CY$130,MATCH($B25,$D$117:$D$130,0),MATCH($A$1,$E$115:$CY$115,0)),"-") -> - | F25: =IFERROR(INDEX($E$134:$CY$147,MATCH($B25,$D$134:$D$147,0),MATCH($A$2,$E$132:$CY$132,0))&" ---> "&INDEX($E$134:$CY$147,MATCH($B25,$D$134:$D$147,0),MATCH($A$1,$E$132:$CY$132,0)),"-") -> - | G25: =IFERROR(INDEX($E$151:$CY$165,MATCH($B25,$D$151:$D$165,0),MATCH($A$2,$E$149:$CY$149,0))&" ---> "&INDEX($E$151:$CY$165,MATCH($B25,$D$151:$D$165,0),MATCH($A$1,$E$149:$CY$149,0)),"-") -> - | H25: =IFERROR(INDEX($E$169:$CY$182,MATCH($B25,$D$169:$D$182,0),MATCH($A$2,$E$167:$CY$167,0))&" ---> "&INDEX($E$169:$CY$182,MATCH($B25,$D$169:$D$182,0),MATCH($A$1,$E$167:$CY$167,0)),"-") -> - | I25: =IFERROR(INDEX($E$186:$CY$224,MATCH($B25,$D$186:$D$224,0),MATCH($A$2,$E$184:$CY$184,0))&" ---> "&INDEX($E$186:$CY$224,MATCH($B25,$D$186:$D$224,0),MATCH($A$1,$E$184:$CY$184,0)),"-") -> 2 ---> 1 | J25: =IFERROR(INDEX($E$228:$BK$243,MATCH($B25,$D$228:$D$243,0),MATCH($A$2,$E$226:$BK$226,0))&" ---> "&INDEX($E$228:$BK$243,MATCH($B25,$D$228:$D$243,0),MATCH($A$1,$E$226:$BK$226,0)),"-") -> - | K25: =IFERROR(INDEX($E$246:$CY$260,MATCH($B25,$D$246:$D$260,0),MATCH($A$2,$E$244:$CY$244,0))&" ---> "&INDEX($E$246:$CY$260,MATCH($B25,$D$246:$D$260,0),MATCH($A$1,$E$244:$CY$244,0)),"-") -> 1 ---> 1 | L25: =IFERROR(INDEX($E$268:$CY$293,MATCH($B25,$D$268:$D$293,0),MATCH($A$2,$E$266:$CY$266,0))&" ---> "&INDEX($E$268:$CY$293,MATCH($B25,$D$268:$D$293,0),MATCH($A$1,$E$266:$CY$266,0)),"-") -> 4 ---> 4
B26: =IFERROR(__xludf.DUMMYFUNCTION("""COMPUTED_VALUE"""),"Aceto Balsamico ") -> Aceto Balsamico | C26: =IFERROR(INDEX($E$82:$CY$96,MATCH($B26,$D$82:$D$96,0),MATCH($A$2,$E$80:$CY$80,0))&" ---> "&INDEX($E$82:$CY$96,MATCH($B26,$D$82:$D$96,0),MATCH($A$1,$E$80:$CY$80,0)),"-") -> - | D26: =IFERROR(INDEX($E$100:$CY$113,MATCH($B26,$D$100:$D$113,0),MATCH($A$2,$E$98:$CY$98,0))&" ---> "&INDEX($E$100:$CY$113,MATCH($B26,$D$100:$D$113,0),MATCH($A$1,$E$98:$CY$98,0)),"-") -> - | E26: =IFERROR(INDEX($E$117:$CY$130,MATCH($B26,$D$117:$D$130,0),MATCH($A$2,$E$115:$CY$115,0))&" ---> "&INDEX($E$117:$CY$130,MATCH($B26,$D$117:$D$130,0),MATCH($A$1,$E$115:$CY$115,0)),"-") -> - | F26: =IFERROR(INDEX($E$134:$CY$147,MATCH($B26,$D$134:$D$147,0),MATCH($A$2,$E$132:$CY$132,0))&" ---> "&INDEX($E$134:$CY$147,MATCH($B26,$D$134:$D$147,0),MATCH($A$1,$E$132:$CY$132,0)),"-") -> - | G26: =IFERROR(INDEX($E$151:$CY$165,MATCH($B26,$D$151:$D$165,0),MATCH($A$2,$E$149:$CY$149,0))&" ---> "&INDEX($E$151:$CY$165,MATCH($B26,$D$151:$D$165,0),MATCH($A$1,$E$149:$CY$149,0)),"-") -> - | H26: =IFERROR(INDEX($E$169:$CY$182,MATCH($B26,$D$169:$D$182,0),MATCH($A$2,$E$167:$CY$167,0))&" ---> "&INDEX($E$169:$CY$182,MATCH($B26,$D$169:$D$182,0),MATCH($A$1,$E$167:$CY$167,0)),"-") -> - | I26: =IFERROR(INDEX($E$186:$CY$224,MATCH($B26,$D$186:$D$224,0),MATCH($A$2,$E$184:$CY$184,0))&" ---> "&INDEX($E$186:$CY$224,MATCH($B26,$D$186:$D$224,0),MATCH($A$1,$E$184:$CY$184,0)),"-") -> 2 ---> 1 | J26: =IFERROR(INDEX($E$228:$BK$243,MATCH($B26,$D$228:$D$243,0),MATCH($A$2,$E$226:$BK$226,0))&" ---> "&INDEX($E$228:$BK$243,MATCH($B26,$D$228:$D$243,0),MATCH($A$1,$E$226:$BK$226,0)),"-") -> - | K26: =IFERROR(INDEX($E$246:$CY$260,MATCH($B26,$D$246:$D$260,0),MATCH($A$2,$E$244:$CY$244,0))&" ---> "&INDEX($E$246:$CY$260,MATCH($B26,$D$246:$D$260,0),MATCH($A$1,$E$244:$CY$244,0)),"-") -> - | L26: =IFERROR(INDEX($E$268:$CY$293,MATCH($B26,$D$268:$D$293,0),MATCH($A$2,$E$266:$CY$266,0))&" ---> "&INDEX($E$268:$CY$293,MATCH($B26,$D$268:$D$293,0),MATCH($A$1,$E$266:$CY$266,0)),"-") -> -
B27: =IFERROR(__xludf.DUMMYFUNCTION("""COMPUTED_VALUE"""),"Jugo de Limon ") -> Jugo de Limon | C27: =IFERROR(INDEX($E$82:$CY$96,MATCH($B27,$D$82:$D$96,0),MATCH($A$2,$E$80:$CY$80,0))&" ---> "&INDEX($E$82:$CY$96,MATCH($B27,$D$82:$D$96,0),MATCH($A$1,$E$80:$CY$80,0)),"-") -> - | D27: =IFERROR(INDEX($E$100:$CY$113,MATCH($B27,$D$100:$D$113,0),MATCH($A$2,$E$98:$CY$98,0))&" ---> "&INDEX($E$100:$CY$113,MATCH($B27,$D$100:$D$113,0),MATCH($A$1,$E$98:$CY$98,0)),"-") -> - | E27: =IFERROR(INDEX($E$117:$CY$130,MATCH($B27,$D$117:$D$130,0),MATCH($A$2,$E$115:$CY$115,0))&" ---> "&INDEX($E$117:$CY$130,MATCH($B27,$D$117:$D$130,0),MATCH($A$1,$E$115:$CY$115,0)),"-") -> - | F27: =IFERROR(INDEX($E$134:$CY$147,MATCH($B27,$D$134:$D$147,0),MATCH($A$2,$E$132:$CY$132,0))&" ---> "&INDEX($E$134:$CY$147,MATCH($B27,$D$134:$D$147,0),MATCH($A$1,$E$132:$CY$132,0)),"-") -> - | G27: =IFERROR(INDEX($E$151:$CY$165,MATCH($B27,$D$151:$D$165,0),MATCH($A$2,$E$149:$CY$149,0))&" ---> "&INDEX($E$151:$CY$165,MATCH($B27,$D$151:$D$165,0),MATCH($A$1,$E$149:$CY$149,0)),"-") -> - | H27: =IFERROR(INDEX($E$169:$CY$182,MATCH($B27,$D$169:$D$182,0),MATCH($A$2,$E$167:$CY$167,0))&" ---> "&INDEX($E$169:$CY$182,MATCH($B27,$D$169:$D$182,0),MATCH($A$1,$E$167:$CY$167,0)),"-") -> - | I27: =IFERROR(INDEX($E$186:$CY$224,MATCH($B27,$D$186:$D$224,0),MATCH($A$2,$E$184:$CY$184,0))&" ---> "&INDEX($E$186:$CY$224,MATCH($B27,$D$186:$D$224,0),MATCH($A$1,$E$184:$CY$184,0)),"-") -> 5 ---> 5 | J27: =IFERROR(INDEX($E$228:$BK$243,MATCH($B27,$D$228:$D$243,0),MATCH($A$2,$E$226:$BK$226,0))&" ---> "&INDEX($E$228:$BK$243,MATCH($B27,$D$228:$D$243,0),MATCH($A$1,$E$226:$BK$226,0)),"-") -> - | K27: =IFERROR(INDEX($E$246:$CY$260,MATCH($B27,$D$246:$D$260,0),MATCH($A$2,$E$244:$CY$244,0))&" ---> "&INDEX($E$246:$CY$260,MATCH($B27,$D$246:$D$260,0),MATCH($A$1,$E$244:$CY$244,0)),"-") -> - | L27: =IFERROR(INDEX($E$268:$CY$293,MATCH($B27,$D$268:$D$293,0),MATCH($A$2,$E$266:$CY$266,0))&" ---> "&INDEX($E$268:$CY$293,MATCH($B27,$D$268:$D$293,0),MATCH($A$1,$E$266:$CY$266,0)),"-") -> -
B28: =IFERROR(__xludf.DUMMYFUNCTION("""COMPUTED_VALUE"""),"Resma Papel Fot. Carta (UN)") -> Resma Papel Fot. Carta (UN) | C28: =IFERROR(INDEX($E$82:$CY$96,MATCH($B28,$D$82:$D$96,0),MATCH($A$2,$E$80:$CY$80,0))&" ---> "&INDEX($E$82:$CY$96,MATCH($B28,$D$82:$D$96,0),MATCH($A$1,$E$80:$CY$80,0)),"-") -> - | D28: =IFERROR(INDEX($E$100:$CY$113,MATCH($B28,$D$100:$D$113,0),MATCH($A$2,$E$98:$CY$98,0))&" ---> "&INDEX($E$100:$CY$113,MATCH($B28,$D$100:$D$113,0),MATCH($A$1,$E$98:$CY$98,0)),"-") -> - | E28: =IFERROR(INDEX($E$117:$CY$130,MATCH($B28,$D$117:$D$130,0),MATCH($A$2,$E$115:$CY$115,0))&" ---> "&INDEX($E$117:$CY$130,MATCH($B28,$D$117:$D$130,0),MATCH($A$1,$E$115:$CY$115,0)),"-") -> - | F28: =IFERROR(INDEX($E$134:$CY$147,MATCH($B28,$D$134:$D$147,0),MATCH($A$2,$E$132:$CY$132,0))&" ---> "&INDEX($E$134:$CY$147,MATCH($B28,$D$134:$D$147,0),MATCH($A$1,$E$132:$CY$132,0)),"-") -> - | G28: =IFERROR(INDEX($E$151:$CY$165,MATCH($B28,$D$151:$D$165,0),MATCH($A$2,$E$149:$CY$149,0))&" ---> "&INDEX($E$151:$CY$165,MATCH($B28,$D$151:$D$165,0),MATCH($A$1,$E$149:$CY$149,0)),"-") -> - | H28: =IFERROR(INDEX($E$169:$CY$182,MATCH($B28,$D$169:$D$182,0),MATCH($A$2,$E$167:$CY$167,0))&" ---> "&INDEX($E$169:$CY$182,MATCH($B28,$D$169:$D$182,0),MATCH($A$1,$E$167:$CY$167,0)),"-") -> - | I28: =IFERROR(INDEX($E$186:$CY$224,MATCH($B28,$D$186:$D$224,0),MATCH($A$2,$E$184:$CY$184,0))&" ---> "&INDEX($E$186:$CY$224,MATCH($B28,$D$186:$D$224,0),MATCH($A$1,$E$184:$CY$184,0)),"-") -> 10 ---> 10 | J28: =IFERROR(INDEX($E$228:$BK$243,MATCH($B28,$D$228:$D$243,0),MATCH($A$2,$E$226:$BK$226,0))&" ---> "&INDEX($E$228:$BK$243,MATCH($B28,$D$228:$D$243,0),MATCH($A$1,$E$226:$BK$226,0)),"-") -> - | K28: =IFERROR(INDEX($E$246:$CY$260,MATCH($B28,$D$246:$D$260,0),MATCH($A$2,$E$244:$CY$244,0))&" ---> "&INDEX($E$246:$CY$260,MATCH($B28,$D$246:$D$260,0),MATCH($A$1,$E$244:$CY$244,0)),"-") -> - | L28: =IFERROR(INDEX($E$268:$CY$293,MATCH($B28,$D$268:$D$293,0),MATCH($A$2,$E$266:$CY$266,0))&" ---> "&INDEX($E$268:$CY$293,MATCH($B28,$D$268:$D$293,0),MATCH($A$1,$E$266:$CY$266,0)),"-") -> -
B29: =IFERROR(__xludf.DUMMYFUNCTION("""COMPUTED_VALUE"""),"Resma Papel Fot. Oficio (UN)") -> Resma Papel Fot. Oficio (UN) | C29: =IFERROR(INDEX($E$82:$CY$96,MATCH($B29,$D$82:$D$96,0),MATCH($A$2,$E$80:$CY$80,0))&" ---> "&INDEX($E$82:$CY$96,MATCH($B29,$D$82:$D$96,0),MATCH($A$1,$E$80:$CY$80,0)),"-") -> - | D29: =IFERROR(INDEX($E$100:$CY$113,MATCH($B29,$D$100:$D$113,0),MATCH($A$2,$E$98:$CY$98,0))&" ---> "&INDEX($E$100:$CY$113,MATCH($B29,$D$100:$D$113,0),MATCH($A$1,$E$98:$CY$98,0)),"-") -> - | E29: =IFERROR(INDEX($E$117:$CY$130,MATCH($B29,$D$117:$D$130,0),MATCH($A$2,$E$115:$CY$115,0))&" ---> "&INDEX($E$117:$CY$130,MATCH($B29,$D$117:$D$130,0),MATCH($A$1,$E$115:$CY$115,0)),"-") -> - | F29: =IFERROR(INDEX($E$134:$CY$147,MATCH($B29,$D$134:$D$147,0),MATCH($A$2,$E$132:$CY$132,0))&" ---> "&INDEX($E$134:$CY$147,MATCH($B29,$D$134:$D$147,0),MATCH($A$1,$E$132:$CY$132,0)),"-") -> - | G29: =IFERROR(INDEX($E$151:$CY$165,MATCH($B29,$D$151:$D$165,0),MATCH($A$2,$E$149:$CY$149,0))&" ---> "&INDEX($E$151:$CY$165,MATCH($B29,$D$151:$D$165,0),MATCH($A$1,$E$149:$CY$149,0)),"-") -> - | H29: =IFERROR(INDEX($E$169:$CY$182,MATCH($B29,$D$169:$D$182,0),MATCH($A$2,$E$167:$CY$167,0))&" ---> "&INDEX($E$169:$CY$182,MATCH($B29,$D$169:$D$182,0),MATCH($A$1,$E$167:$CY$167,0)),"-") -> - | I29: =IFERROR(INDEX($E$186:$CY$224,MATCH($B29,$D$186:$D$224,0),MATCH($A$2,$E$184:$CY$184,0))&" ---> "&INDEX($E$186:$CY$224,MATCH($B29,$D$186:$D$224,0),MATCH($A$1,$E$184:$CY$184,0)),"-") -> 9 ---> 9 | J29: =IFERROR(INDEX($E$228:$BK$243,MATCH($B29,$D$228:$D$243,0),MATCH($A$2,$E$226:$BK$226,0))&" ---> "&INDEX($E$228:$BK$243,MATCH($B29,$D$228:$D$243,0),MATCH($A$1,$E$226:$BK$226,0)),"-") -> - | K29: =IFERROR(INDEX($E$246:$CY$260,MATCH($B29,$D$246:$D$260,0),MATCH($A$2,$E$244:$CY$244,0))&" ---> "&INDEX($E$246:$CY$260,MATCH($B29,$D$246:$D$260,0),MATCH($A$1,$E$244:$CY$244,0)),"-") -> - | L29: =IFERROR(INDEX($E$268:$CY$293,MATCH($B29,$D$268:$D$293,0),MATCH($A$2,$E$266:$CY$266,0))&" ---> "&INDEX($E$268:$CY$293,MATCH($B29,$D$268:$D$293,0),MATCH($A$1,$E$266:$CY$266,0)),"-") -> -
B30: =IFERROR(__xludf.DUMMYFUNCTION("""COMPUTED_VALUE"""),"Revolvedores ") -> Revolvedores | C30: =IFERROR(INDEX($E$82:$CY$96,MATCH($B30,$D$82:$D$96,0),MATCH($A$2,$E$80:$CY$80,0))&" ---> "&INDEX($E$82:$CY$96,MATCH($B30,$D$82:$D$96,0),MATCH($A$1,$E$80:$CY$80,0)),"-") -> - | D30: =IFERROR(INDEX($E$100:$CY$113,MATCH($B30,$D$100:$D$113,0),MATCH($A$2,$E$98:$CY$98,0))&" ---> "&INDEX($E$100:$CY$113,MATCH($B30,$D$100:$D$113,0),MATCH($A$1,$E$98:$CY$98,0)),"-") -> - | E30: =IFERROR(INDEX($E$117:$CY$130,MATCH($B30,$D$117:$D$130,0),MATCH($A$2,$E$115:$CY$115,0))&" ---> "&INDEX($E$117:$CY$130,MATCH($B30,$D$117:$D$130,0),MATCH($A$1,$E$115:$CY$115,0)),"-") -> - | F30: =IFERROR(INDEX($E$134:$CY$147,MATCH($B30,$D$134:$D$147,0),MATCH($A$2,$E$132:$CY$132,0))&" ---> "&INDEX($E$134:$CY$147,MATCH($B30,$D$134:$D$147,0),MATCH($A$1,$E$132:$CY$132,0)),"-") -> - | G30: =IFERROR(INDEX($E$151:$CY$165,MATCH($B30,$D$151:$D$165,0),MATCH($A$2,$E$149:$CY$149,0))&" ---> "&INDEX($E$151:$CY$165,MATCH($B30,$D$151:$D$165,0),MATCH($A$1,$E$149:$CY$149,0)),"-") -> - | H30: =IFERROR(INDEX($E$169:$CY$182,MATCH($B30,$D$169:$D$182,0),MATCH($A$2,$E$167:$CY$167,0))&" ---> "&INDEX($E$169:$CY$182,MATCH($B30,$D$169:$D$182,0),MATCH($A$1,$E$167:$CY$167,0)),"-") -> - | I30: =IFERROR(INDEX($E$186:$CY$224,MATCH($B30,$D$186:$D$224,0),MATCH($A$2,$E$184:$CY$184,0))&" ---> "&INDEX($E$186:$CY$224,MATCH($B30,$D$186:$D$224,0),MATCH($A$1,$E$184:$CY$184,0)),"-") -> 8 ---> 6 | J30: =IFERROR(INDEX($E$228:$BK$243,MATCH($B30,$D$228:$D$243,0),MATCH($A$2,$E$226:$BK$226,0))&" ---> "&INDEX($E$228:$BK$243,MATCH($B30,$D$228:$D$243,0),MATCH($A$1,$E$226:$BK$226,0)),"-") -> - | K30: =IFERROR(INDEX($E$246:$CY$260,MATCH($B30,$D$246:$D$260,0),MATCH($A$2,$E$244:$CY$244,0))&" ---> "&INDEX($E$246:$CY$260,MATCH($B30,$D$246:$D$260,0),MATCH($A$1,$E$244:$CY$244,0)),"-") -> - | L30: =IFERROR(INDEX($E$268:$CY$293,MATCH($B30,$D$268:$D$293,0),MATCH($A$2,$E$266:$CY$266,0))&" ---> "&INDEX($E$268:$CY$293,MATCH($B30,$D$268:$D$293,0),MATCH($A$1,$E$266:$CY$266,0)),"-") -> -
B31: =IFERROR(__xludf.DUMMYFUNCTION("""COMPUTED_VALUE"""),"Sal") -> Sal | C31: =IFERROR(INDEX($E$82:$CY$96,MATCH($B31,$D$82:$D$96,0),MATCH($A$2,$E$80:$CY$80,0))&" ---> "&INDEX($E$82:$CY$96,MATCH($B31,$D$82:$D$96,0),MATCH($A$1,$E$80:$CY$80,0)),"-") -> - | D31: =IFERROR(INDEX($E$100:$CY$113,MATCH($B31,$D$100:$D$113,0),MATCH($A$2,$E$98:$CY$98,0))&" ---> "&INDEX($E$100:$CY$113,MATCH($B31,$D$100:$D$113,0),MATCH($A$1,$E$98:$CY$98,0)),"-") -> - | E31: =IFERROR(INDEX($E$117:$CY$130,MATCH($B31,$D$117:$D$130,0),MATCH($A$2,$E$115:$CY$115,0))&" ---> "&INDEX($E$117:$CY$130,MATCH($B31,$D$117:$D$130,0),MATCH($A$1,$E$115:$CY$115,0)),"-") -> - | F31: =IFERROR(INDEX($E$134:$CY$147,MATCH($B31,$D$134:$D$147,0),MATCH($A$2,$E$132:$CY$132,0))&" ---> "&INDEX($E$134:$CY$147,MATCH($B31,$D$134:$D$147,0),MATCH($A$1,$E$132:$CY$132,0)),"-") -> - | G31: =IFERROR(INDEX($E$151:$CY$165,MATCH($B31,$D$151:$D$165,0),MATCH($A$2,$E$149:$CY$149,0))&" ---> "&INDEX($E$151:$CY$165,MATCH($B31,$D$151:$D$165,0),MATCH($A$1,$E$149:$CY$149,0)),"-") -> - | H31: =IFERROR(INDEX($E$169:$CY$182,MATCH($B31,$D$169:$D$182,0),MATCH($A$2,$E$167:$CY$167,0))&" ---> "&INDEX($E$169:$CY$182,MATCH($B31,$D$169:$D$182,0),MATCH($A$1,$E$167:$CY$167,0)),"-") -> - | I31: =IFERROR(INDEX($E$186:$CY$224,MATCH($B31,$D$186:$D$224,0),MATCH($A$2,$E$184:$CY$184,0))&" ---> "&INDEX($E$186:$CY$224,MATCH($B31,$D$186:$D$224,0),MATCH($A$1,$E$184:$CY$184,0)),"-") -> 1 ---> 1 | J31: =IFERROR(INDEX($E$228:$BK$243,MATCH($B31,$D$228:$D$243,0),MATCH($A$2,$E$226:$BK$226,0))&" ---> "&INDEX($E$228:$BK$243,MATCH($B31,$D$228:$D$243,0),MATCH($A$1,$E$226:$BK$226,0)),"-") -> - | K31: =IFERROR(INDEX($E$246:$CY$260,MATCH($B31,$D$246:$D$260,0),MATCH($A$2,$E$244:$CY$244,0))&" ---> "&INDEX($E$246:$CY$260,MATCH($B31,$D$246:$D$260,0),MATCH($A$1,$E$244:$CY$244,0)),"-") -> - | L31: =IFERROR(INDEX($E$268:$CY$293,MATCH($B31,$D$268:$D$293,0),MATCH($A$2,$E$266:$CY$266,0))&" ---> "&INDEX($E$268:$CY$293,MATCH($B31,$D$268:$D$293,0),MATCH($A$1,$E$266:$CY$266,0)),"-") -> 4 ---> 3
